Workbook

Sheet Table 1_Summary Statistics
A1: Table 1. Summary Statistics for Manufacturing Section by Industry Group: Philippines, 2022
A2: (Preliminary)
A4: 2009 PSIC Code | B4: Industry Description | D4: Number of Establishments | E4: Employment as of 15 November | G4: Total Revenue (in thousand PhP)
E6: Total | F6: Paid Employees
D7: (1) | E7: (2) | F7: (3) | G7: (4)
B9: Manufacturing | D9: 23361 | E9: 1195082 | F9: 1186717 | G9: 7030675449
A11: C101 | B11: Processing and preserving of meat | D11: 276 | E11: 26585 | F11: 26412 | G11: 193923710
A12: C102 | B12: Processing and preserving of fish, crustaceans and mollusks | D12: 244 | E12: 17479 | F12: 17205 | G12: 103106128
A13: C103 | B13: Processing and preserving of fruits and vegetables | D13: 166 | E13: 24843 | F13: 24663 | G13: 149632239
A14: C104 | B14: Manufacture of vegetable and animal oils and fats | D14: 99 | E14: 6695 | F14: 6678 | G14: 205321393
A15: C105 | B15: Manufacture of dairy products | D15: 102 | E15: 11001 | F15: 10907 | G15: 227650879
A16: C106 | B16: Manufacture of grain mill products, starches and starch products | D16: 1233 | E16: 17749 | F16: 15765 | G16: 182820561
A17: C107 | B17: Manufacture of other food products | D17: 7162 | E17: 126181 | F17: 124562 | G17: 469477583
A18: C108 | B18: Manufacture of prepared animal feeds | D18: 191 | E18: 14627 | F18: 14616 | G18: 197078004
A19: C110 | B19: Manufacture of beverages | D19: 2995 | E19: 32821 | F19: 31774 | G19: 384394091
A20: C120 | B20: Manufacture of tobacco products | D20: 21 | E20: 6354 | F20: 6351 | G20: 80218284
A21: C131 | B21: Spinning, weaving and finishing of textiles | D21: 79 | E21: 4793 | F21: 4637 | G21: 7831261
A22: C139 | B22: Manufacture of other textiles | D22: 190 | E22: 10977 | F22: 10873 | G22: 18717565
... A53: C265 | B53: Manufacture of measuring, testing, navigating and control equipment; watches and clocks | D53: 25 | E53: 2965 | F53: 2965 | G53: 4656281
A54: C266 | B54: Manufacture of irradiation, electromedical and electrotherapeutic equipment | D54: s | E54: s | F54: s | G54: s
A55: C267 | B55: Manufacture of optical instruments and photographic equipment | D55: 20 | E55: 6375 | F55: 6367 | G55: 26508470
A56: C271 | B56: Manufacture of electric motors, generators, transformers and electricity distribution and control apparatus | D56: 60 | E56: 8670 | F56: 8668 | G56: 26207907
A57: C272 | B57: Manufacture of batteries and accumulators | D57: 7 | E57: 1930 | F57: 1930 | G57: 19511522
A58: C273 | B58: Manufacture of wiring and wiring devices | D58: 51 | E58: 9313 | F58: 9313 | G58: 48042241
A59: C274 | B59: Manufacture of electric lighting equipment | D59: 35 | E59: 5320 | F59: 5320 | G59: 10793502
A60: C275 | B60: Manufacture of domestic appliances | D60: 38 | E60: 2802 | F60: 2797 | G60: 17731302
A61: C279 | B61: Manufacture of other electrical equipment | D61: 27 | E61: 13588 | F61: 13588 | G61: 27670060
A62: C281 | B62: Manufacture of general purpose machinery | D62: 76 | E62: 13709 | F62: 13709 | G62: 142510011
A63: C282 | B63: Manufacture of special purpose machinery | D63: 115 | E63: 17857 | F63: 17842 | G63: 64906266
A64: C291 | B64: Manufacture of motor vehicles | D64: 39 | E64: 9371 | F64: 9360 | G64: 399685688
A65: C292 | B65: Manufacture of bodies (coachwork) for motor vehicles; manufacture of trailers and semi-trailers | D65: 28 | E65: 1155 | F65: 1140 | G65: 4229795
A66: C293 | B66: Manufacture of parts and accessories for motor vehicles | D66: 157 | E66: 97352 | F66: 97173 | G66: 266002135
A67: C301 | B67: Building of ships and boats | D67: 27 | E67: 4417 | F67: 4416 | G67: 31374070
A68: C302 | B68: Manufacture of railway locomotive and rolling stock | D68: s | E68: s | F68: s | G68: s
A69: C303 | B69: Manufacture of air and spacecraft and related machinery | D69: 5 | E69: 3526 | F69: 3526 | G69: 20444656
A70: C304 | B70: Manufacture of military fighting vehicles | D70: s | E70: s | F70: s | G70: s
A71: C309 | B71: Manufacture of transport equipment, n.e.c. | D71: 76 | E71: 8264 | F71: 8238 | G71: 117834358
A72: C310 | B72: Manufacture of furniture | D72: 753 | E72: 25123 | F72: 24949 | G72: 46397291
A73: C321 | B73: Manufacture of jewelry, bijouterie and related articles | D73: 66 | E73: 1623 | F73: 1622 | G73: 1281780
A74: C322 | B74: Manufacture of musical instruments | D74: 4 | E74: 40 | F74: 38 | G74: 12612
...

Sheet Table 1_Summary Statistics_Cont
A1: Table 1. --Cont.
A3: 2009 PSIC Code | B3: Industry Description | D3: Expense (in thousand PhP) | G3: E-Commerce Sales (in thousand PhP)
D5: Total | E5: Compensation | F5: Other Expense
D6: (5) | E6: (6) | F6: (7) | G6: (8)
A8: C | B8: Manufacturing | D8: 6198826206 | E8: 387456578 | F8: 5811369628 | G8: 2145237
A10: C101 | B10: Processing and preserving of meat | D10: 184326407 | E10: 7534852 | F10: 176791554 | G10: 17
A11: C102 | B11: Processing and preserving of fish, crustaceans and mollusks | D11: 92481758 | E11: 3987648 | F11: 88494109 | G11: 4712
A12: C103 | B12: Processing and preserving of fruits and vegetables | D12: 131841443 | E12: 11498018 | F12: 120343425 | G12: 18004
A13: C104 | B13: Manufacture of vegetable and animal oils and fats | D13: 162361299 | E13: 1675694 | F13: 160685605 | G13: 127
A14: C105 | B14: Manufacture of dairy products | D14: 175559818 | E14: 8491577 | F14: 167068241 | G14: 906734
A15: C106 | B15: Manufacture of grain mill products, starches and starch products | D15: 161096180 | E15: 3416315 | F15: 157679865 | G15: -
A16: C107 | B16: Manufacture of other food products | D16: 420414185 | E16: 31505609 | F16: 388908577 | G16: 135950
A17: C108 | B17: Manufacture of prepared animal feeds | D17: 161975759 | E17: 4025938 | F17: 157949821 | G17: -
A18: C110 | B18: Manufacture of beverages | D18: 325285560 | E18: 15944170 | F18: 309341390 | G18: 3726
A19: C120 | B19: Manufacture of tobacco products | D19: 62697471 | E19: 3419082 | F19: 59278389 | G19: 12962
A20: C131 | B20: Spinning, weaving and finishing of textiles | D20: 6442296 | E20: 946126 | F20: 5496171 | G20: 3474
A21: C139 | B21: Manufacture of other textiles | D21: 16045812 | E21: 2804688 | F21: 13241124 | G21: 8490
A22: C141 | B22: Manufacture of wearing apparel, except fur apparel | D22: 41751925 | E22: 15550051 | F22: 26201874 | G22: 181
A23: C142 | B23: Custom tailoring and dressmaking | D23: 707014 | E23: 221452 | F23: 485562 | G23: -
A24: C143 | B24: Manufacture of knitted and crocheted apparel | D24: 3460619 | E24: 1165364 | F24: 2295255 | G24: -
A25: C151 | B25: Tanning and dressing of leather; manufacture of luggage and handbags | D25: 12219001 | E25: 3527794 | F25: 8691207 | G25: 9955
A26: C152 | B26: Manufacture of footwear | D26: 7371529 | E26: 1736366 | F26: 5635163 | G26: 325
A27: C161 | B27: Sawmilling and planing of wood | D27: 2501551 | E27: 289164 | F27: 2212387 | G27: -
A28: C162 | B28: Manufacture of products of wood, cork, straw and plaiting materials | D28: 61256788 | E28: 2418430 | F28: 58838358 | G28: 30
A29: C170 | B29: Manufacture of paper and paper products | D29: 113552954 | E29: 4376915 | F29: 109176039 | G29: -
A30: C181 | B30: Printing and service activities related to printing | D30: 30870261 | E30: 4432746 | F30: 26437514 | G30: 12221
A31: C182 | B31: Reproduction of recorded media | D31: 3408905 | E31: 92419 | F31: 3316486 | G31: -
A32: C192 | B32: Manufacture of refined petroleum products | D32: 366023040 | E32: 3394085 | F32: 362628955 | G32: -
A33: C199 | B33: Manufacture of other fuel products | D33: 8227329 | E33: 91390 | F33: 8135939 | G33: -
A34: C201 | B34: Manufacture of basic chemicals | D34: 170473920 | E34: 5788057 | F34: 164685863 | G34: 12495
A35: C202 | B35: Manufacture of other chemical products, n.e.c. | D35: 173929161 | E35: 11864579 | F35: 162064582 | G35: 281128
A36: C203 | B36: Manufacture of man-made fibers | D36: 240660 | E36: 25190 | F36: 215470 | G36: -
A37: C210 | B37: Manufacture of pharmaceuticals, medicinal chemical and botanical products | D37: 52858722 | E37: 11872629 | F37: 40986093 | G37: 130
A38: C221 | B38: Manufacture of rubber products | D38: 35471201 | E38: 3659351 | F38: 31811850 | G38: -
A39: C222 | B39: Manufacture of plastics products | D39: 128772726 | E39: 11737338 | F39: 117035388 | G39: 30535
A40: C231 | B40: Manufacture of glass and glass products | D40: 21143686 | E40: 1957769 | F40: 19185917 | G40: -
A41: C239 | B41: Manufacture of non-metallic mineral products, n.e.c. | D41: 282478799 | E41: 12892359 | F41: 269586441 | G41: -
A42: C241 | B42: Manufacture of basic iron and steel | D42: 169860710 | E42: 4550238 | F42: 165310471 | G42: 286683
A43: C242 | B43: Manufacture of basic precious and other non-ferrous metals | D43: 228206426 | E43: 3482916 | F43: 224723510 | G43: -
A44: C243 | B44: Casting of metals | D44: 7173225 | E44: 966801 | F44: 6206424 | G44: -
...

Sheet Table 2_Selected Indicators
A1: Table 2. Selected Indicators for Manufacturing Section by Industry Group: Philippines, 2022
A2: (Preliminary)
A4: 2009 PSIC Code | B4: Industry Description | D4: Average Numbers of Workers per Establishment | E4: Average Annual Compensation per Paid Employee (PhP) | F4: Revenue per Expense Ratio
D7: (1) | E7: (2) | F7: (3)
A9: C | B9: Manufacturing | D9: ='Table 1_Summary Statistics'!E9/'Table 1_Summary Statistics'!D9 -> 51.157142 | E9: ='Table 1_Summary Statistics_Cont'!E8/'Table 1_Summary Statistics'!F9*1000 -> 326494.5 | F9: ='Table 1_Summary Statistics'!G9/'Table 1_Summary Statistics_Cont'!D8 -> 1.1341946
A11: C101 | B11: Processing and preserving of meat | D11: ='Table 1_Summary Statistics'!E11/'Table 1_Summary Statistics'!D11 -> 96.322464 | E11: ='Table 1_Summary Statistics_Cont'!E10/'Table 1_Summary Statistics'!F11*1000 -> 285281.39 | F11: ='Table 1_Summary Statistics'!G11/'Table 1_Summary Statistics_Cont'!D10 -> 1.0520669
A12: C102 | B12: Processing and preserving of fish, crustaceans and mollusks | D12: ='Table 1_Summary Statistics'!E12/'Table 1_Summary Statistics'!D12 -> 71.635246 | E12: ='Table 1_Summary Statistics_Cont'!E11/'Table 1_Summary Statistics'!F12*1000 -> 231772.62 | F12: ='Table 1_Summary Statistics'!G12/'Table 1_Summary Statistics_Cont'!D11 -> 1.1148807
A13: C103 | B13: Processing and preserving of fruits and vegetables | D13: ='Table 1_Summary Statistics'!E13/'Table 1_Summary Statistics'!D13 -> 149.65663 | E13: ='Table 1_Summary Statistics_Cont'!E12/'Table 1_Summary Statistics'!F13*1000 -> 466205.17 | F13: ='Table 1_Summary Statistics'!G13/'Table 1_Summary Statistics_Cont'!D12 -> 1.1349408
A14: C104 | B14: Manufacture of vegetable and animal oils and fats | D14: ='Table 1_Summary Statistics'!E14/'Table 1_Summary Statistics'!D14 -> 67.626263 | E14: ='Table 1_Summary Statistics_Cont'!E13/'Table 1_Summary Statistics'!F14*1000 -> 250927.52 | F14: ='Table 1_Summary Statistics'!G14/'Table 1_Summary Statistics_Cont'!D13 -> 1.2645957
A15: C105 | B15: Manufacture of dairy products | D15: ='Table 1_Summary Statistics'!E15/'Table 1_Summary Statistics'!D15 -> 107.85294 | E15: ='Table 1_Summary Statistics_Cont'!E14/'Table 1_Summary Statistics'!F15*1000 -> 778543.78 | F15: ='Table 1_Summary Statistics'!G15/'Table 1_Summary Statistics_Cont'!D14 -> 1.296714
A16: C106 | B16: Manufacture of grain mill products, starches and starch products | D16: ='Table 1_Summary Statistics'!E16/'Table 1_Summary Statistics'!D16 -> 14.394972 | E16: ='Table 1_Summary Statistics_Cont'!E15/'Table 1_Summary Statistics'!F16*1000 -> 216702.51 | F16: ='Table 1_Summary Statistics'!G16/'Table 1_Summary Statistics_Cont'!D15 -> 1.1348535
A17: C107 | B17: Manufacture of other food products | D17: ='Table 1_Summary Statistics'!E17/'Table 1_Summary Statistics'!D17 -> 17.618123 | E17: ='Table 1_Summary Statistics_Cont'!E16/'Table 1_Summary Statistics'!F17*1000 -> 252931.14 | F17: ='Table 1_Summary Statistics'!G17/'Table 1_Summary Statistics_Cont'!D16 -> 1.1167025
A18: C108 | B18: Manufacture of prepared animal feeds | D18: ='Table 1_Summary Statistics'!E18/'Table 1_Summary Statistics'!D18 -> 76.581152 | E18: ='Table 1_Summary Statistics_Cont'!E17/'Table 1_Summary Statistics'!F18*1000 -> 275447.32 | F18: ='Table 1_Summary Statistics'!G18/'Table 1_Summary Statistics_Cont'!D17 -> 1.216713
A19: C110 | B19: Manufacture of beverages | D19: ='Table 1_Summary Statistics'!E19/'Table 1_Summary Statistics'!D19 -> 10.958598 | E19: ='Table 1_Summary Statistics_Cont'!E18/'Table 1_Summary Statistics'!F19*1000 -> 501799.27 | F19: ='Table 1_Summary Statistics'!G19/'Table 1_Summary Statistics_Cont'!D18 -> 1.1817127
A20: C120 | B20: Manufacture of tobacco products | D20: ='Table 1_Summary Statistics'!E20/'Table 1_Summary Statistics'!D20 -> 302.57143 | E20: ='Table 1_Summary Statistics_Cont'!E19/'Table 1_Summary Statistics'!F20*1000 -> 538353.33 | F20: ='Table 1_Summary Statistics'!G20/'Table 1_Summary Statistics_Cont'!D19 -> 1.2794501
A21: C131 | B21: Spinning, weaving and finishing of textiles | D21: ='Table 1_Summary Statistics'!E21/'Table 1_Summary Statistics'!D21 -> 60.670886 | E21: ='Table 1_Summary Statistics_Cont'!E20/'Table 1_Summary Statistics'!F21*1000 -> 204038.39 | F21: ='Table 1_Summary Statistics'!G21/'Table 1_Summary Statistics_Cont'!D20 -> 1.2156009
... A53: C265 | B53: Manufacture of measuring, testing, navigating and control equipment; watches and clocks | D53: ='Table 1_Summary Statistics'!E53/'Table 1_Summary Statistics'!D53 -> 118.6 | E53: ='Table 1_Summary Statistics_Cont'!E52/'Table 1_Summary Statistics'!F53*1000 -> 416106.24 | F53: ='Table 1_Summary Statistics'!G53/'Table 1_Summary Statistics_Cont'!D52 -> 1.0802394
A54: C266 | B54: Manufacture of irradiation, electromedical and electrotherapeutic equipment | D54: s | E54: s | F54: s
A55: C267 | B55: Manufacture of optical instruments and photographic equipment | D55: ='Table 1_Summary Statistics'!E55/'Table 1_Summary Statistics'!D55 -> 318.75 | E55: ='Table 1_Summary Statistics_Cont'!E54/'Table 1_Summary Statistics'!F55*1000 -> 335069.11 | F55: ='Table 1_Summary Statistics'!G55/'Table 1_Summary Statistics_Cont'!D54 -> 1.0966302
A56: C271 | B56: Manufacture of electric motors, generators, transformers and electricity distribution and control apparatus | D56: ='Table 1_Summary Statistics'!E56/'Table 1_Summary Statistics'!D56 -> 144.5 | E56: ='Table 1_Summary Statistics_Cont'!E55/'Table 1_Summary Statistics'!F56*1000 -> 277779.07 | F56: ='Table 1_Summary Statistics'!G56/'Table 1_Summary Statistics_Cont'!D55 -> 1.2875249
A57: C272 | B57: Manufacture of batteries and accumulators | D57: ='Table 1_Summary Statistics'!E57/'Table 1_Summary Statistics'!D57 -> 275.71429 | E57: ='Table 1_Summary Statistics_Cont'!E56/'Table 1_Summary Statistics'!F57*1000 -> 773851.81 | F57: ='Table 1_Summary Statistics'!G57/'Table 1_Summary Statistics_Cont'!D56 -> 2.6277581
A58: C273 | B58: Manufacture of wiring and wiring devices | D58: ='Table 1_Summary Statistics'!E58/'Table 1_Summary Statistics'!D58 -> 182.60784 | E58: ='Table 1_Summary Statistics_Cont'!E57/'Table 1_Summary Statistics'!F58*1000 -> 267453.34 | F58: ='Table 1_Summary Statistics'!G58/'Table 1_Summary Statistics_Cont'!D57 -> 1.0617225
A59: C274 | B59: Manufacture of electric lighting equipment | D59: ='Table 1_Summary Statistics'!E59/'Table 1_Summary Statistics'!D59 -> 152 | E59: ='Table 1_Summary Statistics_Cont'!E58/'Table 1_Summary Statistics'!F59*1000 -> 216582.52 | F59: ='Table 1_Summary Statistics'!G59/'Table 1_Summary Statistics_Cont'!D58 -> 1.1829971
A60: C275 | B60: Manufacture of domestic appliances | D60: ='Table 1_Summary Statistics'!E60/'Table 1_Summary Statistics'!D60 -> 73.736842 | E60: ='Table 1_Summary Statistics_Cont'!E59/'Table 1_Summary Statistics'!F60*1000 -> 381872.72 | F60: ='Table 1_Summary Statistics'!G60/'Table 1_Summary Statistics_Cont'!D59 -> 1.0703915
A61: C279 | B61: Manufacture of other electrical equipment | D61: ='Table 1_Summary Statistics'!E61/'Table 1_Summary Statistics'!D61 -> 503.25926 | E61: ='Table 1_Summary Statistics_Cont'!E60/'Table 1_Summary Statistics'!F61*1000 -> 303926.18 | F61: ='Table 1_Summary Statistics'!G61/'Table 1_Summary Statistics_Cont'!D60 -> 1.0694451
A62: C281 | B62: Manufacture of general purpose machinery | D62: ='Table 1_Summary Statistics'!E62/'Table 1_Summary Statistics'!D62 -> 180.38158 | E62: ='Table 1_Summary Statistics_Cont'!E61/'Table 1_Summary Statistics'!F62*1000 -> 616648.48 | F62: ='Table 1_Summary Statistics'!G62/'Table 1_Summary Statistics_Cont'!D61 -> 1.1119446
A63: C282 | B63: Manufacture of special purpose machinery | D63: ='Table 1_Summary Statistics'!E63/'Table 1_Summary Statistics'!D63 -> 155.27826 | E63: ='Table 1_Summary Statistics_Cont'!E62/'Table 1_Summary Statistics'!F63*1000 -> 259686.58 | F63: ='Table 1_Summary Statistics'!G63/'Table 1_Summary Statistics_Cont'!D62 -> 1.0761023
A64: C291 | B64: Manufacture of motor vehicles | D64: ='Table 1_Summary Statistics'!E64/'Table 1_Summary Statistics'!D64 -> 240.28205 | E64: ='Table 1_Summary Statistics_Cont'!E63/'Table 1_Summary Statistics'!F64*1000 -> 630498.29 | F64: ='Table 1_Summary Statistics'!G64/'Table 1_Summary Statistics_Cont'!D63 -> 1.0592594
A65: C292 | B65: Manufacture of bodies (coachwork) for motor vehicles; manufacture of trailers and semi-trailers | D65: ='Table 1_Summary Statistics'!E65/'Table 1_Summary Statistics'!D65 -> 41.25 | E65: ='Table 1_Summary Statistics_Cont'!E64/'Table 1_Summary Statistics'!F65*1000 -> 462097.37 | F65: ='Table 1_Summary Statistics'!G65/'Table 1_Summary Statistics_Cont'!D64 -> 1.2695412
A66: C293 | B66: Manufacture of parts and accessories for motor vehicles | D66: ='Table 1_Summary Statistics'!E66/'Table 1_Summary Statistics'!D66 -> 620.07643 | E66: ='Table 1_Summary Statistics_Cont'!E65/'Table 1_Summary Statistics'!F66*1000 -> 292474.06 | F66: ='Table 1_Summary Statistics'!G66/'Table 1_Summary Statistics_Cont'!D65 -> 1.0278191
A67: C301 | B67: Building of ships and boats | D67: ='Table 1_Summary Statistics'!E67/'Table 1_Summary Statistics'!D67 -> 163.59259 | E67: ='Table 1_Summary Statistics_Cont'!E66/'Table 1_Summary Statistics'!F67*1000 -> 696262.91 | F67: ='Table 1_Summary Statistics'!G67/'Table 1_Summary Statistics_Cont'!D66 -> 1.129331
A68: C302 | B68: Manufacture of railway locomotive and rolling stock | D68: s | E68: s | F68: s
A69: C303 | B69: Manufacture of air and spacecraft and related machinery | D69: ='Table 1_Summary Statistics'!E69/'Table 1_Summary Statistics'!D69 -> 705.2 | E69: ='Table 1_Summary Statistics_Cont'!E68/'Table 1_Summary Statistics'!F69*1000 -> 528814.24 | F69: ='Table 1_Summary Statistics'!G69/'Table 1_Summary Statistics_Cont'!D68 -> 1.2732546
A70: C304 | B70: Manufacture of military fighting vehicles | D70: s | E70: s | F70: s
A71: C309 | B71: Manufacture of transport equipment, n.e.c. | D71: ='Table 1_Summary Statistics'!E71/'Table 1_Summary Statistics'!D71 -> 108.73684 | E71: ='Table 1_Summary Statistics_Cont'!E70/'Table 1_Summary Statistics'!F71*1000 -> 388569.56 | F71: ='Table 1_Summary Statistics'!G71/'Table 1_Summary Statistics_Cont'!D70 -> 1.0557494
A72: C310 | B72: Manufacture of furniture | D72: ='Table 1_Summary Statistics'!E72/'Table 1_Summary Statistics'!D72 -> 33.363878 | E72: ='Table 1_Summary Statistics_Cont'!E71/'Table 1_Summary Statistics'!F72*1000 -> 221498.46 | F72: ='Table 1_Summary Statistics'!G72/'Table 1_Summary Statistics_Cont'!D71 -> 1.1068567
A73: C321 | B73: Manufacture of jewelry, bijouterie and related articles | D73: ='Table 1_Summary Statistics'!E73/'Table 1_Summary Statistics'!D73 -> 24.590909 | E73: ='Table 1_Summary Statistics_Cont'!E72/'Table 1_Summary Statistics'!F73*1000 -> 233681.87 | F73: ='Table 1_Summary Statistics'!G73/'Table 1_Summary Statistics_Cont'!D72 -> 1.0781127
A74: C322 | B74: Manufacture of musical instruments | D74: ='Table 1_Summary Statistics'!E74/'Table 1_Summary Statistics'!D74 -> 10 | E74: ='Table 1_Summary Statistics_Cont'!E73/'Table 1_Summary Statistics'!F74*1000 -> 135763.16 | F74: ='Table 1_Summary Statistics'!G74/'Table 1_Summary Statistics_Cont'!D73 -> 1.161219
A75: C323 | B75: Manufacture of sports goods | D75: ='Table 1_Summary Statistics'!E75/'Table 1_Summary Statistics'!D75 -> 212.53333 | E75: ='Table 1_Summary Statistics_Cont'!E74/'Table 1_Summary Statistics'!F75*1000 -> 224154.11 | F75: ='Table 1_Summary Statistics'!G75/'Table 1_Summary Statistics_Cont'!D74 -> 1.2148679
A76: C324 | B76: Manufacture of games and toys | D76: ='Table 1_Summary Statistics'!E76/'Table 1_Summary Statistics'!D76 -> 166.41667 | E76: ='Table 1_Summary Statistics_Cont'!E75/'Table 1_Summary Statistics'!F76*1000 -> 197533.58 | F76: ='Table 1_Summary Statistics'!G76/'Table 1_Summary Statistics_Cont'!D75 -> 1.1972997
...

Sheet Table 3_SummStat Reg
A1: Table 3. Summary Statistics for Manufacturing Section by Region: Philippines, 2022
A2: (Preliminary)
A4: Industry Description | B4: Number of Establishments | C4: Employment as of 15 November | E4: Total Revenue (in thousand PhP)
C6: Total | D6: Paid Employees
B7: (1) | C7: (2) | D7: (3) | E7: (4)
A9: Philippines | B9: 23361 | C9: 1195082 | D9: 1186717 | E9: 7030675449
A11: National Capital Region (NCR) | B11: 4364 | C11: 188768 | D11: 188213 | E11: 950255259
A12: Cordillera Administrative Region (CAR) | B12: 308 | C12: 5996 | D12: 5751 | E12: 212295708
A13: Region I (Ilocos Region) | B13: 1015 | C13: 9553 | D13: 8757 | E13: 108346766
A14: Region II (Cagayan Valley) | B14: 493 | C14: 8920 | D14: 8758 | E14: 22402078
A15: Region III (Central Luzon) | B15: 2634 | C15: 168939 | D15: 168383 | E15: 1190543601
A16: Region IV-A (CALABARZON) | B16: 3948 | C16: 527508 | D16: 526282 | E16: 3168135335
A17: MIMAROPA Region | B17: 371 | C17: 4096 | D17: 3939 | E17: 29240132
A18: Region V (Bicol Region) | B18: 774 | C18: 10666 | D18: 10007 | E18: 69425912
A19: Region VI (Western Visayas) | B19: 1426 | C19: 24470 | D19: 23856 | E19: 101364774
A20: Region VII (Central Visayas) | B20: 2416 | C20: 135030 | D20: 134504 | E20: 385124129
A21: Region VIII (Eastern Visayas) | B21: 1008 | C21: 11391 | D21: 10601 | E21: 167478189
... A27: Bangsamoro Autonomous Region in Muslim Mindanao (BARMM) | B27: 173 | C27: 2085 | D27: 1954 | E27: 5664251

Sheet Table 3_SummStat Reg_Cont
A1: Table 3. --Conc.
A4: Industry Description | B4: Expense (in thousand PhP) | E4: E-Commerce Sales (in thousand PhP)
B6: Total | C6: Compensation | D6: Other Expense
B7: (5) | C7: (6) | D7: (7) | E7: (8)
A9: Philippines | B9: 6198826206 | C9: 387456578 | D9: 5811369628 | E9: 2145237
A11: National Capital Region (NCR) | B11: 863244914 | C11: 68886053 | D11: 794358861 | E11: 1792095
A12: Cordillera Administrative Region (CAR) | B12: 148137572 | C12: 3593090 | D12: 144544482 | E12: 244
A13: Region I (Ilocos Region) | B13: 97378887 | C13: 2871881 | D13: 94507006 | E13: 36298
A14: Region II (Cagayan Valley) | B14: 14964748 | C14: 1008296 | D14: 13956452 | E14: -
A15: Region III (Central Luzon) | B15: 976271724 | C15: 41885744 | D15: 934385980 | E15: 43401
A16: Region IV-A (CALABARZON) | B16: 2898489980 | C16: 194081331 | D16: 2704408649 | E16: 176923
A17: MIMAROPA Region | B17: 23330966 | C17: 644326 | D17: 22686640 | E17: 7709
A18: Region V (Bicol Region) | B18: 50174146 | C18: 1879109 | D18: 48295037 | E18: 413
A19: Region VI (Western Visayas) | B19: 84727325 | C19: 5848362 | D19: 78878963 | E19: 12509
A20: Region VII (Central Visayas) | B20: 355855410 | C20: 38411102 | D20: 317444309 | E20: 39614
A21: Region VIII (Eastern Visayas) | B21: 168322350 | C21: 2597993 | D21: 165724357 | E21: 10
A22: Region IX (Zamboanga Peninsula) | B22: 39934394 | C22: 1620446 | D22: 38313948 | E22: 4712
A23: Region X (Northern Mindanao) | B23: 193279811 | C23: 6521876 | D23: 186757935 | E23: 11900
A24: Region XI (Davao Region) | B24: 162846926 | C24: 7069683 | D24: 155777242 | E24: 18632
A25: Region XII (SOCCSKSARGEN) | B25: 74988100 | C25: 8479458 | D25: 66508642 | E25: 777
A26: Region XIII (Caraga) | B26: 42038349 | C26: 1797263 | D26: 40241086 | E26: -
A27: Bangsamoro Autonomous Region in Muslim Mindanao (BARMM) 1/ | B27: 4840604 | C27: 260565 | D27: 4580038 | E27: -
A29: 1/ The sample coverage for BARMM for 2022 includes Cotabato City and the Eight Area Clusters (63 Barangays previously
A30: from the Province of Cotabato)
A31: Note: - zero value
A32: Details may not add up to total due to rounding and/or statistical disclosure control
A33: Source: Philippine Statistics Authority, 2022 Annual Survey of Philippine Business and Industry (Preliminary Results)

Sheet Table 4_Selected Indicators Reg
A1: Table 4. Selected Indicators for Manufacturing Section by Region: Philippines, 2022
A2: (Preliminary)
A4: Industry Description | B4: Average Numbers of Workers per Establishment | C4: Average Annual Compensation per Paid Employee (PhP) | D4: Revenue per Expense Ratio
B7: (1) | C7: (2) | D7: (3)
A9: Philippines | B9: ='Table 3_SummStat Reg'!C9/'Table 3_SummStat Reg'!B9 -> 51.157142 | C9: ='Table 3_SummStat Reg_Cont'!C9/'Table 3_SummStat Reg'!D9*1000 -> 326494.5 | D9: ='Table 3_SummStat Reg'!E9/'Table 3_SummStat Reg_Cont'!B9 -> 1.1341946
A11: National Capital Region (NCR) | B11: ='Table 3_SummStat Reg'!C11/'Table 3_SummStat Reg'!B11 -> 43.255729 | C11: ='Table 3_SummStat Reg_Cont'!C11/'Table 3_SummStat Reg'!D11*1000 -> 366000.5 | D11: ='Table 3_SummStat Reg'!E11/'Table 3_SummStat Reg_Cont'!B11 -> 1.1007945
A12: Cordillera Administrative Region (CAR) | B12: ='Table 3_SummStat Reg'!C12/'Table 3_SummStat Reg'!B12 -> 19.467532 | C12: ='Table 3_SummStat Reg_Cont'!C12/'Table 3_SummStat Reg'!D12*1000 -> 624776.56 | D12: ='Table 3_SummStat Reg'!E12/'Table 3_SummStat Reg_Cont'!B12 -> 1.4330983
A13: Region I (Ilocos Region) | B13: ='Table 3_SummStat Reg'!C13/'Table 3_SummStat Reg'!B13 -> 9.4118227 | C13: ='Table 3_SummStat Reg_Cont'!C13/'Table 3_SummStat Reg'!D13*1000 -> 327952.61 | D13: ='Table 3_SummStat Reg'!E13/'Table 3_SummStat Reg_Cont'!B13 -> 1.112631
A14: Region II (Cagayan Valley) | B14: ='Table 3_SummStat Reg'!C14/'Table 3_SummStat Reg'!B14 -> 18.093306 | C14: ='Table 3_SummStat Reg_Cont'!C14/'Table 3_SummStat Reg'!D14*1000 -> 115128.57 | D14: ='Table 3_SummStat Reg'!E14/'Table 3_SummStat Reg_Cont'!B14 -> 1.49699
A15: Region III (Central Luzon) | B15: ='Table 3_SummStat Reg'!C15/'Table 3_SummStat Reg'!B15 -> 64.137813 | C15: ='Table 3_SummStat Reg_Cont'!C15/'Table 3_SummStat Reg'!D15*1000 -> 248752.81 | D15: ='Table 3_SummStat Reg'!E15/'Table 3_SummStat Reg_Cont'!B15 -> 1.2194798
A16: Region IV-A (CALABARZON) | B16: ='Table 3_SummStat Reg'!C16/'Table 3_SummStat Reg'!B16 -> 133.61398 | C16: ='Table 3_SummStat Reg_Cont'!C16/'Table 3_SummStat Reg'!D16*1000 -> 368778.2 | D16: ='Table 3_SummStat Reg'!E16/'Table 3_SummStat Reg_Cont'!B16 -> 1.0930296
A17: MIMAROPA Region | B17: ='Table 3_SummStat Reg'!C17/'Table 3_SummStat Reg'!B17 -> 11.040431 | C17: ='Table 3_SummStat Reg_Cont'!C17/'Table 3_SummStat Reg'!D17*1000 -> 163576.03 | D17: ='Table 3_SummStat Reg'!E17/'Table 3_SummStat Reg_Cont'!B17 -> 1.2532757
A18: Region V (Bicol Region) | B18: ='Table 3_SummStat Reg'!C18/'Table 3_SummStat Reg'!B18 -> 13.780362 | C18: ='Table 3_SummStat Reg_Cont'!C18/'Table 3_SummStat Reg'!D18*1000 -> 187779.45 | D18: ='Table 3_SummStat Reg'!E18/'Table 3_SummStat Reg_Cont'!B18 -> 1.3836989
A19: Region VI (Western Visayas) | B19: ='Table 3_SummStat Reg'!C19/'Table 3_SummStat Reg'!B19 -> 17.159888 | C19: ='Table 3_SummStat Reg_Cont'!C19/'Table 3_SummStat Reg'!D19*1000 -> 245152.67 | D19: ='Table 3_SummStat Reg'!E19/'Table 3_SummStat Reg_Cont'!B19 -> 1.1963646
A20: Region VII (Central Visayas) | B20: ='Table 3_SummStat Reg'!C20/'Table 3_SummStat Reg'!B20 -> 55.889901 | C20: ='Table 3_SummStat Reg_Cont'!C20/'Table 3_SummStat Reg'!D20*1000 -> 285575.91 | D20: ='Table 3_SummStat Reg'!E20/'Table 3_SummStat Reg_Cont'!B20 -> 1.0822489
A21: Region VIII (Eastern Visayas) | B21: ='Table 3_SummStat Reg'!C21/'Table 3_SummStat Reg'!B21 -> 11.300595 | C21: ='Table 3_SummStat Reg_Cont'!C21/'Table 3_SummStat Reg'!D21*1000 -> 245070.56 | D21: ='Table 3_SummStat Reg'!E21/'Table 3_SummStat Reg_Cont'!B21 -> 0.99498485
... A27: Bangsamoro Autonomous Region in Muslim Mindanao (BARMM) | B27: ='Table 3_SummStat Reg'!C27/'Table 3_SummStat Reg'!B27 -> 12.052023 | C27: ='Table 3_SummStat Reg_Cont'!C27/'Table 3_SummStat Reg'!D27*1000 -> 133349.54 | D27: ='Table 3_SummStat Reg'!E27/'Table 3_SummStat Reg_Cont'!B27 -> 1.1701538
A29: 1/ The sample coverage for BARMM for 2022 includes Cotabato City and the Eight Area Clusters (63 Barangays previously
A30: from the Province of Cotabato)
A31: Note: - zero value
A32: Details may not add up to total due to rounding and/or statistical disclosure control
A33: Source: Philippine Statistics Authority, 2022 Annual Survey of Philippine Business and Industry (Preliminary Results)
