Workbook

Sheet Bohol
A2: Region | B2: REGION_VII
A3: Province | B3: BOHOL
A4: Number of Districts | B4: 3
A5: Sector | B5: Subsector/ Value Chain | C5: Job Requirement | D5: Tasks | E5: Program | F5: Type of Program (TR, CS, New and Emerging, Diploma Programs) | G5: Provincial Rank (Averaged Across Districts)
H6: D1 | O6: D2 | X6: D3
A7: AGRICULTURE FORESTRY AND FISHERY | B7: CROP PRODUCTION | C7: AGRI CROPS PRODUCER | D7: PRODUCE SEEDS AND FERTILIZER | E7: AGRICULTURAL CROPS PRODUCTION NC II | F7: With TR | G7: HIGH | H7: TRUE | I7: TRUE | J7: FALSE | K7: FALSE | L7: FALSE | M7: TRUE | N7: 1 | O7: HIGH | P7: TRUE | Q7: TRUE | R7: FALSE | S7: FALSE | T7: FALSE | U7: TRUE | V7: 1 | W7: HIGH | X7: TRUE | Y7: TRUE | Z7: FALSE | AA7: FALSE | AB7: FALSE | AC7: TRUE | AD7: 1 | AE7: HIGH
A8: AGRICULTURE FORESTRY AND FISHERY | B8: FOOD PROCESSING | C8: ANIMAL BUTCHERING AND SLAUGHTERING | D8: PREPARE, HANDLE, STUN, SLAUGHTER, INSPECT, PROCES, COLLECT, STORE, DISPOSE AND LABEL MEAT | E8: SLAUGHTERING OPERATIONS (LARGE ANIMAL) NC II | F8: With TR | G8: HIGH | H8: TRUE | I8: TRUE | J8: FALSE | K8: FALSE | L8: TRUE | M8: FALSE | N8: 1.5 | O8: HIGH | P8: FALSE | Q8: FALSE | R8: FALSE | S8: FALSE | T8: FALSE | U8: FALSE | X8: TRUE | Y8: TRUE | Z8: FALSE | AA8: FALSE | AB8: TRUE | AC8: FALSE | AD8: 1.5 | AE8: HIGH
A9: AGRICULTURE FORESTRY AND FISHERY | B9: FISHERY | C9: BANGUS FRY PRODUCTION | D9: COLLECT AND INCUBATE EGG IN HATCHERY | E9: AQUACULTURE (HATCHERY OPERATION) NC II | F9: With TR | G9: HIGH | H9: TRUE | I9: TRUE | J9: FALSE | K9: FALSE | L9: FALSE | M9: TRUE | N9: 1 | O9: HIGH | P9: TRUE | Q9: TRUE | R9: FALSE | S9: FALSE | T9: FALSE | U9: TRUE | V9: 1 | W9: HIGH | X9: TRUE | Y9: TRUE | Z9: FALSE | AA9: FALSE | AB9: FALSE | AC9: TRUE | AD9: 1 | AE9: HIGH
A10: AGRICULTURE FORESTRY AND FISHERY | B10: AGRICULTURE FORESTRY AND FISHERY | C10: BEEKEEPING | D10: MANAGE BEEHIVE | E10: BEEKEEPING LEVEL II | F10: With TR | G10: MEDIUM | H10: FALSE | I10: FALSE | J10: TRUE | K10: FALSE | L10: TRUE | M10: FALSE | N10: 2 | O10: MEDIUM | P10: FALSE | Q10: FALSE | R10: TRUE | S10: FALSE | T10: TRUE | U10: FALSE | V10: 2 | W10: MEDIUM | X10: FALSE | Y10: FALSE | Z10: TRUE | AA10: FALSE | AB10: TRUE | AC10: FALSE | AD10: 2 | AE10: MEDIUM
A11: AGRICULTURE FORESTRY AND FISHERY | B11: FERRO CEMENT TANK | C11: BUILD FERRO CEMENT TANK | D11: DESIGN, PREPARE, FABRICATE, INSTALL, MIX AND MAINTAIN FERRO CEMENT CONSTRUCTION | E11: NONE | F11: New and Emerging | G11: HIGH | H11: TRUE | I11: TRUE | J11: FALSE | K11: FALSE | L11: FALSE | M11: TRUE | N11: 1 | O11: HIGH | P11: TRUE | Q11: TRUE | R11: FALSE | S11: FALSE | T11: FALSE | U11: TRUE | V11: 1 | W11: HIGH | X11: TRUE | Y11: TRUE | Z11: FALSE | AA11: FALSE | AB11: FALSE | AC11: TRUE | AD11: 1 | AE11: HIGH
A12: AGRICULTURE FORESTRY AND FISHERY | B12: CROP PRODUCTION | C12: CACAO PROCESSING | D12: PROCESS CACAO PRODUCTS AND BY PRODUCTS | E12: CACAO PRODUCTION LEVEL II | F12: With TR | G12: MEDIUM | H12: FALSE | I12: FALSE | J12: TRUE | K12: FALSE | L12: TRUE | M12: FALSE | N12: 2 | O12: MEDIUM | P12: FALSE | Q12: FALSE | R12: FALSE | S12: FALSE | T12: FALSE | U12: FALSE | X12: FALSE | Y12: FALSE | Z12: TRUE | AA12: FALSE | AB12: TRUE | AC12: FALSE | AD12: 2 | AE12: MEDIUM
A13: AGRICULTURE FORESTRY AND FISHERY | B13: ANIMAL HUSBANDRY AND LIVESTOCK PRODUCTION | C13: CHICKEN LAYER GROWER | D13: BROOD, HOUSE, FEED, MANAGE CHICKEN LAYER | E13: ANIMAL PRODUCTION (POULTRY-CHICKEN) NC II | F13: With TR | G13: HIGH | H13: TRUE | I13: TRUE | J13: FALSE | K13: FALSE | L13: FALSE | M13: TRUE | N13: 1 | O13: HIGH | P13: TRUE | Q13: TRUE | R13: FALSE | S13: FALSE | T13: FALSE | U13: TRUE | V13: 1 | W13: HIGH | X13: TRUE | Y13: TRUE | Z13: FALSE | AA13: FALSE | AB13: FALSE | AC13: TRUE | AD13: 1 | AE13: HIGH
A14: AGRICULTURE FORESTRY AND FISHERY | B14: ANIMAL HUSBANDRY AND LIVESTOCK PRODUCTION | C14: EGG PRODUCER | D14: COLLECT AND HANDLE EGG | E14: ANIMAL PRODUCTION (POULTRY-CHICKEN) NC II | F14: With TR | G14: HIGH | H14: TRUE | I14: TRUE | J14: FALSE | K14: FALSE | L14: FALSE | M14: TRUE | N14: 1 | O14: HIGH | P14: TRUE | Q14: TRUE | R14: FALSE | S14: FALSE | T14: FALSE | U14: TRUE | V14: 1 | W14: HIGH | X14: TRUE | Y14: TRUE | Z14: FALSE | AA14: FALSE | AB14: FALSE | AC14: TRUE | AD14: 1 | AE14: HIGH
A15: AGRICULTURE FORESTRY AND FISHERY | B15: CROP PRODUCTION | C15: FARM MACHINERIES OPERATIONS | D15: OPEARATE FARM MACHINERIES | E15: AGRICULTURAL MACHINERY OPERATION NC II | F15: With TR | G15: HIGH | H15: TRUE | I15: TRUE | J15: FALSE | K15: FALSE | L15: FALSE | M15: TRUE | N15: 1 | O15: HIGH | P15: TRUE | Q15: TRUE | R15: FALSE | S15: FALSE | T15: FALSE | U15: TRUE | V15: 1 | W15: HIGH | X15: TRUE | Y15: TRUE | Z15: FALSE | AA15: FALSE | AB15: FALSE | AC15: TRUE | AD15: 1 | AE15: HIGH
A16: AGRICULTURE FORESTRY AND FISHERY | B16: CROP PRODUCTION | C16: FARM MANAGEMENT & TECHNOLOGICAL AWARENESS | D16: TRAIN IN FARM MACHINERY | E16: AGRICULTURAL MACHINERY OPERATION NC II | F16: With TR | G16: MEDIUM | H16: TRUE | I16: FALSE | J16: TRUE | K16: FALSE | L16: TRUE | M16: FALSE | N16: 2 | O16: MEDIUM | P16: TRUE | Q16: FALSE | R16: TRUE | S16: FALSE | T16: TRUE | U16: FALSE | V16: 2 | W16: MEDIUM | X16: TRUE | Y16: FALSE | Z16: TRUE | AA16: FALSE | AB16: TRUE | AC16: FALSE | AD16: 2 | AE16: MEDIUM
A17: AGRICULTURE FORESTRY AND FISHERY | B17: CROP PRODUCTION | C17: FARM MECHANICS & OPERATORS | D17: REPAIR FARM EQUIPMENT | E17: NONE | F17: New and Emerging | G17: HIGH | H17: FALSE | I17: FALSE | J17: FALSE | K17: FALSE | L17: FALSE | M17: FALSE | P17: TRUE | Q17: TRUE | R17: FALSE | S17: FALSE | T17: TRUE | U17: FALSE | V17: 1.5 | W17: HIGH | X17: TRUE | Y17: TRUE | Z17: FALSE | AA17: FALSE | AB17: TRUE | AC17: FALSE | AD17: 1.5 | AE17: HIGH
A18: AGRICULTURE FORESTRY AND FISHERY | B18: FISHERIES | C18: FRESHWATER FISH GROWER | D18: COLLECT AND INCUBATE EGG IN HATCHERY | E18: AQUACULTURE (HATCHERY OPERATION) NC II | F18: With TR | G18: LOW | H18: FALSE | I18: FALSE | J18: TRUE | K18: TRUE | L18: FALSE | M18: FALSE | N18: 2.5 | O18: LOW | P18: FALSE | Q18: FALSE | R18: TRUE | S18: TRUE | T18: FALSE | U18: FALSE | V18: 2.5 | W18: LOW | X18: FALSE | Y18: FALSE | Z18: TRUE | AA18: TRUE | AB18: FALSE | AC18: FALSE | AD18: 2.5 | AE18: LOW
A19: AGRICULTURE FORESTRY AND FISHERY | B19: CROP PRODUCTION | C19: FRUITS, COCONUT TREES, UBI & CACAO PRODUCTION & PROCESSING | D19: UBI PRODUCTION AND PROCESSING | E19: NONE | F19: New and Emerging | G19: HIGH | H19: TRUE | I19: TRUE | J19: FALSE | K19: FALSE | L19: TRUE | M19: FALSE | N19: 1.5 | O19: HIGH | P19: TRUE | Q19: TRUE | R19: FALSE | S19: FALSE | T19: TRUE | U19: FALSE | V19: 1.5 | W19: HIGH | X19: TRUE | Y19: TRUE | Z19: FALSE | AA19: FALSE | AB19: TRUE | AC19: FALSE | AD19: 1.5 | AE19: HIGH
A20: AGRICULTURE FORESTRY AND FISHERY | B20: CROP PRODUCTION | C20: HEAVY EQUIPMENT OPERATOR (BACKHOE, GRADER) | D20: OPERATE BACKHOE AND GRADER FOR DIGGING WATER RESERVOIR | E20: HEAVY EQUIPMENT OPERATION (BACKHOE LOADER) NC II | F20: With TR | G20: HIGH | H20: TRUE | I20: TRUE | J20: FALSE | K20: FALSE | L20: FALSE | M20: TRUE | N20: 1 | O20: HIGH | P20: TRUE | Q20: TRUE | R20: FALSE | S20: FALSE | T20: FALSE | U20: TRUE | V20: 1 | W20: HIGH | X20: TRUE | Y20: TRUE | Z20: FALSE | AA20: FALSE | AB20: FALSE | AC20: TRUE | AD20: 1 | AE20: HIGH
A21: AGRICULTURE FORESTRY AND FISHERY | B21: CROP PRODUCTION | C21: HIGH /ORGANIC QUALITY SEEDS GROWER | D21: PRODUCE ORGANIC VEGETABLE SEEDS | E21: NONE | F21: New and Emerging | G21: HIGH | H21: TRUE | I21: TRUE | J21: FALSE | K21: FALSE | L21: FALSE | M21: TRUE | N21: 1 | O21: HIGH | P21: TRUE | Q21: TRUE | R21: FALSE | S21: FALSE | T21: FALSE | U21: TRUE | V21: 1 | W21: HIGH | X21: TRUE | Y21: TRUE | Z21: FALSE | AA21: FALSE | AB21: FALSE | AC21: TRUE | AD21: 1 | AE21: HIGH
A22: AGRICULTURE FORESTRY AND FISHERY | B22: CROP PRODUCTION | C22: HIGH QUALITY INBREED RICE GROWER | D22: RICE PRODUCTION SEED CERTIFICATION AND FARM MECHANIZATION | E22: NONE | F22: New and Emerging | G22: MEDIUM | H22: TRUE | I22: FALSE | J22: TRUE | K22: FALSE | L22: TRUE | M22: FALSE | N22: 2 | O22: MEDIUM | P22: FALSE | Q22: FALSE | R22: TRUE | S22: FALSE | T22: TRUE | U22: FALSE | V22: 2 | W22: MEDIUM | X22: FALSE | Y22: FALSE | Z22: TRUE | AA22: FALSE | AB22: TRUE | AC22: FALSE | AD22: 2 | AE22: MEDIUM
A23: AGRICULTURE FORESTRY AND FISHERY | B23: CROP PRODUCTION | C23: INTERCROPPING TECHNICIAN | D23: IDENTIFY COMPATIBLE CROPS WITH COCONUT | E23: NONE | F23: New and Emerging | G23: MEDIUM | H23: TRUE | I23: FALSE | J23: TRUE | K23: FALSE | L23: TRUE | M23: FALSE | N23: 2 | O23: MEDIUM | P23: FALSE | Q23: FALSE | R23: TRUE | S23: FALSE | T23: TRUE | U23: FALSE | V23: 2 | W23: MEDIUM | X23: FALSE | Y23: FALSE | Z23: TRUE | AA23: FALSE | AB23: TRUE | AC23: FALSE | AD23: 2 | AE23: MEDIUM
A24: AGRICULTURE FORESTRY AND FISHERY | B24: CROP PRODUCTION | C24: INTERGRATED COCONUT AND CASH CROPS PRODUCTION AND PROCESSING (BY PRODUCTS LIKE SHELL,DUST, COIR) | D24: PRODUCE COCONUT and PROCESS COCONUT PRDUCTS AND BY PRODUCTS | E24: COCONUT PRODUCTION LEVEL II | F24: With CS | G24: HIGH | H24: TRUE | I24: TRUE | J24: FALSE | K24: FALSE | L24: TRUE | M24: FALSE | N24: 1.5 | O24: HIGH | P24: TRUE | Q24: TRUE | R24: FALSE | S24: FALSE | T24: TRUE | U24: FALSE | V24: 1.5 | W24: HIGH | X24: TRUE | Y24: TRUE | Z24: FALSE | AA24: FALSE | AB24: TRUE | AC24: FALSE | AD24: 1.5 | AE24: HIGH
A25: AGRICULTURE FORESTRY AND FISHERY | B25: HORTICULTURE | C25: LANDSCAPE PLANTS (ORNAMENTAL AND CUT FLOWER) CULTURE, CARE AND MAINTENANCE | D25: PROPAGATE, PLANT CARE, MAINTAIN, LANDSCAPE AND MANAGE ORNAMENTAL PLANTS | E25: LANDSCAPE INSTALLATION AND MAINTENANCE (SOFTSCAPE) NC II | F25: With TR | G25: HIGH | H25: TRUE | I25: TRUE | J25: FALSE | K25: FALSE | L25: TRUE | M25: FALSE | N25: 1.5 | O25: HIGH | P25: TRUE | Q25: TRUE | R25: FALSE | S25: FALSE | T25: TRUE | U25: FALSE | V25: 1.5 | W25: HIGH | X25: TRUE | Y25: TRUE | Z25: FALSE | AA25: FALSE | AB25: TRUE | AC25: FALSE | AD25: 1.5 | AE25: HIGH
A26: AGRICULTURE FORESTRY AND FISHERY | B26: CROP PRODUCTION | C26: MAKE ORGANIC FERTILIZER & CONCOCTION | D26: PRODUCE ORGANIC FERTILIZER, SEEDS, RICE | E26: ORGANIC AGRICULTURE PRODUCTION NC II | F26: With TR | G26: HIGH | H26: TRUE | I26: TRUE | J26: FALSE | K26: FALSE | L26: FALSE | M26: TRUE | N26: 1 | O26: HIGH | P26: TRUE | Q26: TRUE | R26: FALSE | S26: FALSE | T26: FALSE | U26: TRUE | V26: 1 | W26: HIGH | X26: TRUE | Y26: TRUE | Z26: FALSE | AA26: FALSE | AB26: FALSE | AC26: TRUE | AD26: 1 | AE26: HIGH
A27: AGRICULTURE FORESTRY AND FISHERY | B27: CROP PRODUCTION | C27: MEDICINAL TEA PRODUCTION AND PROCESSING (TURMERIC,SALABAT,MORINGA,ETC.) | D27: PRODUCE AND PROCESS MEDICINAL PLANTS | E27: NONE | F27: New and Emerging | G27: HIGH | H27: TRUE | I27: TRUE | J27: FALSE | K27: FALSE | L27: FALSE | M27: TRUE | N27: 1 | O27: HIGH | P27: TRUE | Q27: TRUE | R27: FALSE | S27: FALSE | T27: FALSE | U27: TRUE | V27: 1 | W27: HIGH | X27: TRUE | Y27: TRUE | Z27: FALSE | AA27: FALSE | AB27: FALSE | AC27: TRUE | AD27: 1 | AE27: HIGH
A28: AGRICULTURE FORESTRY AND FISHERY | B28: AGRICULTURE | C28: REPAIR OF FARM MECHANICAL EQUIPMENT | D28: REPAIR FARM EQUIPMENT | E28: NONE | F28: New and Emerging | G28: HIGH | H28: TRUE | I28: TRUE | J28: FALSE | K28: FALSE | L28: FALSE | M28: TRUE | N28: 1 | O28: HIGH | P28: TRUE | Q28: TRUE | R28: FALSE | S28: FALSE | T28: FALSE | U28: TRUE | V28: 1 | W28: HIGH | X28: TRUE | Y28: TRUE | Z28: FALSE | AA28: FALSE | AB28: FALSE | AC28: TRUE | AD28: 1 | AE28: HIGH
A29: AGRICULTURE FORESTRY AND FISHERY | B29: CROP PRODUCTION | C29: RICE MACHINES OPERATORS | D29: OPERATE RICE MACHINERIES | E29: RICE MACHINERY OPERATIONS NC II | F29: With TR | G29: HIGH | H29: FALSE | I29: TRUE | J29: FALSE | K29: FALSE | L29: TRUE | M29: FALSE | N29: 1.5 | O29: HIGH | P29: FALSE | Q29: TRUE | R29: FALSE | S29: FALSE | T29: TRUE | U29: FALSE | V29: 1.5 | W29: HIGH | X29: FALSE | Y29: TRUE | Z29: FALSE | AA29: FALSE | AB29: TRUE | AC29: FALSE | AD29: 1.5 | AE29: HIGH
... A89: INFORMATION AND COMMUNICATION TECHNOLOGY | B89: CONTACT CENTER AND BPO | C89: CALL CENTER AGENTS | D89: ASSESS AND RESOLVE CLIENT CONCERN | E89: CONTACT CENTER SERVICES NC II | F89: With TR | G89: HIGH | H89: TRUE | I89: TRUE | J89: FALSE | K89: FALSE | L89: FALSE | M89: TRUE | N89: 1 | O89: HIGH | P89: TRUE | Q89: TRUE | R89: FALSE | S89: FALSE | T89: FALSE | U89: TRUE | V89: 1 | W89: HIGH | X89: TRUE | Y89: TRUE | Z89: FALSE | AA89: FALSE | AB89: FALSE | AC89: TRUE | AD89: 1 | AE89: HIGH
A90: INFORMATION AND COMMUNICATION TECHNOLOGY | B90: INFORMATION TECHNOLOGY SERVICES | C90: COMPUTER LITERATE AND PROFICIENT TO WINDOWS OS, APPLE OS, X, MS OFFICE AND GOOGLE APPLICATION | D90: PERFORM OFFICE APPLICATION SOFTWARES | E90: COMPUTER SYSTEMS SERVICING NC II | F90: With TR | G90: MEDIUM | H90: FALSE | I90: FALSE | J90: FALSE | K90: FALSE | L90: FALSE | M90: FALSE | P90: TRUE | Q90: TRUE | R90: FALSE | S90: TRUE | T90: FALSE | U90: FALSE | V90: 2 | W90: MEDIUM | X90: TRUE | Y90: TRUE | Z90: FALSE | AA90: TRUE | AB90: FALSE | AC90: FALSE | AD90: 2 | AE90: MEDIUM
A91: INFORMATION AND COMMUNICATION TECHNOLOGY | B91: CONTACT CENTER AND BPO | C91: CUSTOMER SERVICE REPRESENTATIVE | D91: ASSESS AND RESOLVE CUSTOMER CONCERN | E91: CONTACT CENTER SERVICES NC II | F91: With TR | G91: HIGH | H91: TRUE | I91: TRUE | J91: FALSE | K91: FALSE | L91: FALSE | M91: TRUE | N91: 1 | O91: HIGH | P91: TRUE | Q91: TRUE | R91: FALSE | S91: FALSE | T91: FALSE | U91: TRUE | V91: 1 | W91: HIGH | X91: TRUE | Y91: TRUE | Z91: FALSE | AA91: FALSE | AB91: FALSE | AC91: TRUE | AD91: 1 | AE91: HIGH
A92: INFORMATION AND COMMUNICATION TECHNOLOGY | B92: INFORMATION TECHNOLOGY SERVICES | C92: CYBER SECURITY | D92: MANAGE AND SECURE CYBERSPACE | E92: CYBER RISK ASSESSMENT LEVEL III | F92: With TR | G92: HIGH | H92: FALSE | I92: FALSE | J92: FALSE | K92: FALSE | L92: FALSE | M92: FALSE | P92: TRUE | Q92: TRUE | R92: FALSE | S92: FALSE | T92: FALSE | U92: TRUE | V92: 1 | W92: HIGH | X92: FALSE | Y92: FALSE | Z92: FALSE | AA92: FALSE | AB92: FALSE | AC92: FALSE
A93: INFORMATION AND COMMUNICATION TECHNOLOGY | B93: E-COMMERCE | C93: DATA ANALYST | D93: ANALYZE DATA HISTORICALS TO PROVIDE FORECAST | E93: DATA ANALYTICS LEVEL III | F93: With TR | G93: HIGH | H93: TRUE | I93: TRUE | J93: FALSE | K93: FALSE | L93: FALSE | M93: TRUE | N93: 1 | O93: HIGH | P93: TRUE | Q93: TRUE | R93: FALSE | S93: FALSE | T93: FALSE | U93: TRUE | V93: 1 | W93: HIGH | X93: TRUE | Y93: TRUE | Z93: FALSE | AA93: FALSE | AB93: FALSE | AC93: TRUE | AD93: 1 | AE93: HIGH
A94: INFORMATION AND COMMUNICATION TECHNOLOGY | B94: MULTIMEDIA SERVICES | C94: GRAPHIC DESIGNERS | D94: CREATE AND DESIGN GRAPHICS | E94: VISUAL GRAPHIC DESIGN NC III | F94: With TR | G94: HIGH | H94: TRUE | I94: TRUE | J94: FALSE | K94: FALSE | L94: FALSE | M94: TRUE | N94: 1 | O94: HIGH | P94: TRUE | Q94: TRUE | R94: FALSE | S94: FALSE | T94: FALSE | U94: TRUE | V94: 1 | W94: HIGH | X94: TRUE | Y94: TRUE | Z94: FALSE | AA94: FALSE | AB94: FALSE | AC94: TRUE | AD94: 1 | AE94: HIGH
A95: INFORMATION AND COMMUNICATION TECHNOLOGY | B95: INFORMATION TECHNOLOGY SERVICES | C95: HARDWARE DEPLOYMENT | D95: INSTALLATION OF ICT INFRASTRUCTURE | E95: COMPUTER SYSTEMS SERVICING NC II | F95: With TR | G95: HIGH | H95: FALSE | I95: FALSE | J95: FALSE | K95: FALSE | L95: FALSE | M95: FALSE | P95: TRUE | Q95: TRUE | R95: FALSE | S95: FALSE | T95: TRUE | U95: FALSE | V95: 1.5 | W95: HIGH | X95: FALSE | Y95: FALSE | Z95: FALSE | AA95: FALSE | AB95: FALSE | AC95: FALSE
A96: INFORMATION AND COMMUNICATION TECHNOLOGY | B96: INFORMATION TECHNOLOGY SERVICES | C96: IT SKILLED INDIVIDUAL | D96: PROVIDE ICT SERVICES | E96: COMPUTER SYSTEMS SERVICING NC II | F96: With TR | G96: HIGH | H96: TRUE | I96: TRUE | J96: FALSE | K96: FALSE | L96: FALSE | M96: TRUE | N96: 1 | O96: HIGH | P96: TRUE | Q96: TRUE | R96: FALSE | S96: FALSE | T96: FALSE | U96: TRUE | V96: 1 | W96: HIGH | X96: TRUE | Y96: TRUE | Z96: FALSE | AA96: FALSE | AB96: FALSE | AC96: TRUE | AD96: 1 | AE96: HIGH
A97: INFORMATION AND COMMUNICATION TECHNOLOGY | B97: MULTIMEDIA SERVICES | C97: MASTER OF PHOTOSHOP | D97: CREATE AND DESIGN GRAPHICS | E97: VISUAL GRAPHIC DESIGN NC III | F97: With TR | G97: HIGH | H97: FALSE | I97: FALSE | J97: FALSE | K97: FALSE | L97: FALSE | M97: FALSE | P97: TRUE | Q97: TRUE | R97: FALSE | S97: FALSE | T97: TRUE | U97: FALSE | V97: 1.5 | W97: HIGH | X97: FALSE | Y97: FALSE | Z97: FALSE | AA97: FALSE | AB97: FALSE | AC97: FALSE
A98: INFORMATION AND COMMUNICATION TECHNOLOGY | B98: INFORMATION TECHNOLOGY SERVICES | C98: NETWORK ENGINEER AND FIBER OPTIC SPECIALIST | D98: MANAGE AND INSTALL PREMISES/OUTSIDE PLANT COPPER OR FIBER NETWORKS | E98: TELECOM OSP INSTALLATION (FIBER OPTIC CABLE) NC II | F98: With TR | G98: MEDIUM | H98: FALSE | I98: FALSE | J98: FALSE | K98: FALSE | L98: FALSE | M98: FALSE | P98: TRUE | Q98: TRUE | R98: FALSE | S98: TRUE | T98: FALSE | U98: FALSE | V98: 2 | W98: MEDIUM | X98: TRUE | Y98: TRUE | Z98: FALSE | AA98: TRUE | AB98: FALSE | AC98: FALSE | AD98: 2 | AE98: MEDIUM
A99: INFORMATION AND COMMUNICATION TECHNOLOGY | B99: INFORMATION TECHNOLOGY SERVICES | C99: SENIOR DRUPAL DEVELOPER | D99: CONCEPTUALIZE, DESIGN, DEPLOY AND MONITOR WEBSITE | E99: WEB DEVELOPMENT NC III | F99: With TR | G99: MEDIUM | H99: TRUE | I99: TRUE | J99: FALSE | K99: TRUE | L99: FALSE | M99: FALSE | N99: 2 | O99: MEDIUM | P99: TRUE | Q99: TRUE | R99: FALSE | S99: TRUE | T99: FALSE | U99: FALSE | V99: 2 | W99: MEDIUM | X99: TRUE | Y99: TRUE | Z99: FALSE | AA99: TRUE | AB99: FALSE | AC99: FALSE | AD99: 2 | AE99: MEDIUM
A100: INFORMATION AND COMMUNICATION TECHNOLOGY | B100: INFORMATION TECHNOLOGY SERVICES | C100: SENIOR SWIFT DEVELOPER | D100: CONCEPTUALIZE, DESIGN, DEPLOY AND MONITOR APPLICATIONS (EITHER WEB, DESKTOP OR MOBILE) | E100: WEB DEVELOPMENT NC III | F100: With TR | G100: HIGH | H100: TRUE | I100: TRUE | J100: FALSE | K100: FALSE | L100: FALSE | M100: TRUE | N100: 1 | O100: HIGH | P100: TRUE | Q100: TRUE | R100: FALSE | S100: FALSE | T100: FALSE | U100: TRUE | V100: 1 | W100: HIGH | X100: TRUE | Y100: TRUE | Z100: FALSE | AA100: FALSE | AB100: FALSE | AC100: TRUE | AD100: 1 | AE100: HIGH
...

Sheet BoholFinal
A1: Region | B1: REGION_VII
A2: Province | B2: BOHOL
A3: Number of Districts | B3: 3
A4: Sector | B4: Subsector/ Value Chain | C4: Job Requirement | D4: Tasks | E4: Program | F4: Type of Program (TR, CS, New and Emerging, Diploma Programs) | G4: Provincial Rank (Averaged Across Districts)
A6: DISTRICTS | I6: D1 | O6: D2 | W6: D3
A7: AGRICULTURE FORESTRY AND FISHERY | B7: CROP PRODUCTION | C7: AGRI CROPS PRODUCER | D7: PRODUCE SEEDS AND FERTILIZER | E7: AGRICULTURAL CROPS PRODUCTION NC II | F7: With TR | G7: HIGH | H7: 1 | I7: =IF(Bohol!H7=TRUE,"✓","") -> ✓ | J7: =IF(Bohol!I7=TRUE,"✓","") -> ✓ | K7: =IF(Bohol!J7=TRUE,"✓","") | L7: =IF(Bohol!K7=TRUE,"✓","") | M7: =IF(Bohol!L7=TRUE,"✓","") | N7: =IF(Bohol!M7=TRUE,"✓","") -> ✓ | O7: HIGH | P7: =IF(Bohol!P7=TRUE,"✓","") -> ✓ | Q7: =IF(Bohol!Q7=TRUE,"✓","") -> ✓ | R7: =IF(Bohol!R7=TRUE,"✓","") | S7: =IF(Bohol!S7=TRUE,"✓","") | T7: =IF(Bohol!T7=TRUE,"✓","") | U7: =IF(Bohol!U7=TRUE,"✓","") -> ✓ | V7: 1 | W7: HIGH | X7: =IF(Bohol!X7=TRUE,"✓","") -> ✓ | Y7: =IF(Bohol!Y7=TRUE,"✓","") -> ✓ | Z7: =IF(Bohol!Z7=TRUE,"✓","") | AA7: =IF(Bohol!AA7=TRUE,"✓","") | AB7: =IF(Bohol!AB7=TRUE,"✓","") | AC7: 1 | AD7: HIGH
A8: AGRICULTURE FORESTRY AND FISHERY | B8: FOOD PROCESSING | C8: ANIMAL BUTCHERING AND SLAUGHTERING | D8: PREPARE, HANDLE, STUN, SLAUGHTER, INSPECT, PROCES, COLLECT, STORE, DISPOSE AND LABEL MEAT | E8: SLAUGHTERING OPERATIONS (LARGE ANIMAL) NC II | F8: With TR | G8: HIGH | H8: 1.5 | I8: =IF(Bohol!H8=TRUE,"✓","") -> ✓ | J8: =IF(Bohol!I8=TRUE,"✓","") -> ✓ | K8: =IF(Bohol!J8=TRUE,"✓","") | L8: =IF(Bohol!K8=TRUE,"✓","") | M8: =IF(Bohol!L8=TRUE,"✓","") -> ✓ | N8: =IF(Bohol!M8=TRUE,"✓","") | O8: HIGH | P8: =IF(Bohol!P8=TRUE,"✓","") | Q8: =IF(Bohol!Q8=TRUE,"✓","") | R8: =IF(Bohol!R8=TRUE,"✓","") | S8: =IF(Bohol!S8=TRUE,"✓","") | T8: =IF(Bohol!T8=TRUE,"✓","") | U8: =IF(Bohol!U8=TRUE,"✓","") | X8: =IF(Bohol!X8=TRUE,"✓","") -> ✓ | Y8: =IF(Bohol!Y8=TRUE,"✓","") -> ✓ | Z8: =IF(Bohol!Z8=TRUE,"✓","") | AA8: =IF(Bohol!AA8=TRUE,"✓","") | AB8: =IF(Bohol!AB8=TRUE,"✓","") -> ✓ | AC8: 1.5 | AD8: HIGH
A9: AGRICULTURE FORESTRY AND FISHERY | B9: FISHERY | C9: BANGUS FRY PRODUCTION | D9: COLLECT AND INCUBATE EGG IN HATCHERY | E9: AQUACULTURE (HATCHERY OPERATION) NC II | F9: With TR | G9: HIGH | H9: 1 | I9: =IF(Bohol!H9=TRUE,"✓","") -> ✓ | J9: =IF(Bohol!I9=TRUE,"✓","") -> ✓ | K9: =IF(Bohol!J9=TRUE,"✓","") | L9: =IF(Bohol!K9=TRUE,"✓","") | M9: =IF(Bohol!L9=TRUE,"✓","") | N9: =IF(Bohol!M9=TRUE,"✓","") -> ✓ | O9: HIGH | P9: =IF(Bohol!P9=TRUE,"✓","") -> ✓ | Q9: =IF(Bohol!Q9=TRUE,"✓","") -> ✓ | R9: =IF(Bohol!R9=TRUE,"✓","") | S9: =IF(Bohol!S9=TRUE,"✓","") | T9: =IF(Bohol!T9=TRUE,"✓","") | U9: =IF(Bohol!U9=TRUE,"✓","") -> ✓ | V9: 1 | W9: HIGH | X9: =IF(Bohol!X9=TRUE,"✓","") -> ✓ | Y9: =IF(Bohol!Y9=TRUE,"✓","") -> ✓ | Z9: =IF(Bohol!Z9=TRUE,"✓","") | AA9: =IF(Bohol!AA9=TRUE,"✓","") | AB9: =IF(Bohol!AB9=TRUE,"✓","") | AC9: 1 | AD9: HIGH
A10: AGRICULTURE FORESTRY AND FISHERY | B10: AGRICULTURE FORESTRY AND FISHERY | C10: BEEKEEPING | D10: MANAGE BEEHIVE | E10: BEEKEEPING LEVEL II | F10: With TR | G10: MEDIUM | H10: 2 | I10: =IF(Bohol!H10=TRUE,"✓","") | J10: =IF(Bohol!I10=TRUE,"✓","") | K10: =IF(Bohol!J10=TRUE,"✓","") -> ✓ | L10: =IF(Bohol!K10=TRUE,"✓","") | M10: =IF(Bohol!L10=TRUE,"✓","") -> ✓ | N10: =IF(Bohol!M10=TRUE,"✓","") | O10: MEDIUM | P10: =IF(Bohol!P10=TRUE,"✓","") | Q10: =IF(Bohol!Q10=TRUE,"✓","") | R10: =IF(Bohol!R10=TRUE,"✓","") -> ✓ | S10: =IF(Bohol!S10=TRUE,"✓","") | T10: =IF(Bohol!T10=TRUE,"✓","") -> ✓ | U10: =IF(Bohol!U10=TRUE,"✓","") | V10: 2 | W10: MEDIUM | X10: =IF(Bohol!X10=TRUE,"✓","") | Y10: =IF(Bohol!Y10=TRUE,"✓","") | Z10: =IF(Bohol!Z10=TRUE,"✓","") -> ✓ | AA10: =IF(Bohol!AA10=TRUE,"✓","") | AB10: =IF(Bohol!AB10=TRUE,"✓","") -> ✓ | AC10: 2 | AD10: MEDIUM
A11: AGRICULTURE FORESTRY AND FISHERY | B11: FERRO CEMENT TANK | C11: BUILD FERRO CEMENT TANK | D11: DESIGN, PREPARE, FABRICATE, INSTALL, MIX AND MAINTAIN FERRO CEMENT CONSTRUCTION | E11: NONE | F11: New and Emerging | G11: HIGH | H11: 1 | I11: =IF(Bohol!H11=TRUE,"✓","") -> ✓ | J11: =IF(Bohol!I11=TRUE,"✓","") -> ✓ | K11: =IF(Bohol!J11=TRUE,"✓","") | L11: =IF(Bohol!K11=TRUE,"✓","") | M11: =IF(Bohol!L11=TRUE,"✓","") | N11: =IF(Bohol!M11=TRUE,"✓","") -> ✓ | O11: HIGH | P11: =IF(Bohol!P11=TRUE,"✓","") -> ✓ | Q11: =IF(Bohol!Q11=TRUE,"✓","") -> ✓ | R11: =IF(Bohol!R11=TRUE,"✓","") | S11: =IF(Bohol!S11=TRUE,"✓","") | T11: =IF(Bohol!T11=TRUE,"✓","") | U11: =IF(Bohol!U11=TRUE,"✓","") -> ✓ | V11: 1 | W11: HIGH | X11: =IF(Bohol!X11=TRUE,"✓","") -> ✓ | Y11: =IF(Bohol!Y11=TRUE,"✓","") -> ✓ | Z11: =IF(Bohol!Z11=TRUE,"✓","") | AA11: =IF(Bohol!AA11=TRUE,"✓","") | AB11: =IF(Bohol!AB11=TRUE,"✓","") | AC11: 1 | AD11: HIGH
A12: AGRICULTURE FORESTRY AND FISHERY | B12: CROP PRODUCTION | C12: CACAO PROCESSING | D12: PROCESS CACAO PRODUCTS AND BY PRODUCTS | E12: CACAO PRODUCTION LEVEL II | F12: With TR | G12: MEDIUM | H12: 2 | I12: =IF(Bohol!H12=TRUE,"✓","") | J12: =IF(Bohol!I12=TRUE,"✓","") | K12: =IF(Bohol!J12=TRUE,"✓","") -> ✓ | L12: =IF(Bohol!K12=TRUE,"✓","") | M12: =IF(Bohol!L12=TRUE,"✓","") -> ✓ | N12: =IF(Bohol!M12=TRUE,"✓","") | O12: MEDIUM | P12: =IF(Bohol!P12=TRUE,"✓","") | Q12: =IF(Bohol!Q12=TRUE,"✓","") | R12: =IF(Bohol!R12=TRUE,"✓","") | S12: =IF(Bohol!S12=TRUE,"✓","") | T12: =IF(Bohol!T12=TRUE,"✓","") | U12: =IF(Bohol!U12=TRUE,"✓","") | X12: =IF(Bohol!X12=TRUE,"✓","") | Y12: =IF(Bohol!Y12=TRUE,"✓","") | Z12: =IF(Bohol!Z12=TRUE,"✓","") -> ✓ | AA12: =IF(Bohol!AA12=TRUE,"✓","") | AB12: =IF(Bohol!AB12=TRUE,"✓","") -> ✓ | AC12: 2 | AD12: MEDIUM
A13: AGRICULTURE FORESTRY AND FISHERY | B13: ANIMAL HUSBANDRY AND LIVESTOCK PRODUCTION | C13: CHICKEN LAYER GROWER | D13: BROOD, HOUSE, FEED, MANAGE CHICKEN LAYER | E13: ANIMAL PRODUCTION (POULTRY-CHICKEN) NC II | F13: With TR | G13: HIGH | H13: 1 | I13: =IF(Bohol!H13=TRUE,"✓","") -> ✓ | J13: =IF(Bohol!I13=TRUE,"✓","") -> ✓ | K13: =IF(Bohol!J13=TRUE,"✓","") | L13: =IF(Bohol!K13=TRUE,"✓","") | M13: =IF(Bohol!L13=TRUE,"✓","") | N13: =IF(Bohol!M13=TRUE,"✓","") -> ✓ | O13: HIGH | P13: =IF(Bohol!P13=TRUE,"✓","") -> ✓ | Q13: =IF(Bohol!Q13=TRUE,"✓","") -> ✓ | R13: =IF(Bohol!R13=TRUE,"✓","") | S13: =IF(Bohol!S13=TRUE,"✓","") | T13: =IF(Bohol!T13=TRUE,"✓","") | U13: =IF(Bohol!U13=TRUE,"✓","") -> ✓ | V13: 1 | W13: HIGH | X13: =IF(Bohol!X13=TRUE,"✓","") -> ✓ | Y13: =IF(Bohol!Y13=TRUE,"✓","") -> ✓ | Z13: =IF(Bohol!Z13=TRUE,"✓","") | AA13: =IF(Bohol!AA13=TRUE,"✓","") | AB13: =IF(Bohol!AB13=TRUE,"✓","") | AC13: 1 | AD13: HIGH
A14: AGRICULTURE FORESTRY AND FISHERY | B14: ANIMAL HUSBANDRY AND LIVESTOCK PRODUCTION | C14: EGG PRODUCER | D14: COLLECT AND HANDLE EGG | E14: ANIMAL PRODUCTION (POULTRY-CHICKEN) NC II | F14: With TR | G14: HIGH | H14: 1 | I14: =IF(Bohol!H14=TRUE,"✓","") -> ✓ | J14: =IF(Bohol!I14=TRUE,"✓","") -> ✓ | K14: =IF(Bohol!J14=TRUE,"✓","") | L14: =IF(Bohol!K14=TRUE,"✓","") | M14: =IF(Bohol!L14=TRUE,"✓","") | N14: =IF(Bohol!M14=TRUE,"✓","") -> ✓ | O14: HIGH | P14: =IF(Bohol!P14=TRUE,"✓","") -> ✓ | Q14: =IF(Bohol!Q14=TRUE,"✓","") -> ✓ | R14: =IF(Bohol!R14=TRUE,"✓","") | S14: =IF(Bohol!S14=TRUE,"✓","") | T14: =IF(Bohol!T14=TRUE,"✓","") | U14: =IF(Bohol!U14=TRUE,"✓","") -> ✓ | V14: 1 | W14: HIGH | X14: =IF(Bohol!X14=TRUE,"✓","") -> ✓ | Y14: =IF(Bohol!Y14=TRUE,"✓","") -> ✓ | Z14: =IF(Bohol!Z14=TRUE,"✓","") | AA14: =IF(Bohol!AA14=TRUE,"✓","") | AB14: =IF(Bohol!AB14=TRUE,"✓","") | AC14: 1 | AD14: HIGH
A15: AGRICULTURE FORESTRY AND FISHERY | B15: CROP PRODUCTION | C15: FARM MACHINERIES OPERATIONS | D15: OPEARATE FARM MACHINERIES | E15: AGRICULTURAL MACHINERY OPERATION NC II | F15: With TR | G15: HIGH | H15: 1 | I15: =IF(Bohol!H15=TRUE,"✓","") -> ✓ | J15: =IF(Bohol!I15=TRUE,"✓","") -> ✓ | K15: =IF(Bohol!J15=TRUE,"✓","") | L15: =IF(Bohol!K15=TRUE,"✓","") | M15: =IF(Bohol!L15=TRUE,"✓","") | N15: =IF(Bohol!M15=TRUE,"✓","") -> ✓ | O15: HIGH | P15: =IF(Bohol!P15=TRUE,"✓","") -> ✓ | Q15: =IF(Bohol!Q15=TRUE,"✓","") -> ✓ | R15: =IF(Bohol!R15=TRUE,"✓","") | S15: =IF(Bohol!S15=TRUE,"✓","") | T15: =IF(Bohol!T15=TRUE,"✓","") | U15: =IF(Bohol!U15=TRUE,"✓","") -> ✓ | V15: 1 | W15: HIGH | X15: =IF(Bohol!X15=TRUE,"✓","") -> ✓ | Y15: =IF(Bohol!Y15=TRUE,"✓","") -> ✓ | Z15: =IF(Bohol!Z15=TRUE,"✓","") | AA15: =IF(Bohol!AA15=TRUE,"✓","") | AB15: =IF(Bohol!AB15=TRUE,"✓","") | AC15: 1 | AD15: HIGH
A16: AGRICULTURE FORESTRY AND FISHERY | B16: CROP PRODUCTION | C16: FARM MANAGEMENT & TECHNOLOGICAL AWARENESS | D16: TRAIN IN FARM MACHINERY | E16: AGRICULTURAL MACHINERY OPERATION NC II | F16: With TR | G16: MEDIUM | H16: 2 | I16: =IF(Bohol!H16=TRUE,"✓","") -> ✓ | J16: =IF(Bohol!I16=TRUE,"✓","") | K16: =IF(Bohol!J16=TRUE,"✓","") -> ✓ | L16: =IF(Bohol!K16=TRUE,"✓","") | M16: =IF(Bohol!L16=TRUE,"✓","") -> ✓ | N16: =IF(Bohol!M16=TRUE,"✓","") | O16: MEDIUM | P16: =IF(Bohol!P16=TRUE,"✓","") -> ✓ | Q16: =IF(Bohol!Q16=TRUE,"✓","") | R16: =IF(Bohol!R16=TRUE,"✓","") -> ✓ | S16: =IF(Bohol!S16=TRUE,"✓","") | T16: =IF(Bohol!T16=TRUE,"✓","") -> ✓ | U16: =IF(Bohol!U16=TRUE,"✓","") | V16: 2 | W16: MEDIUM | X16: =IF(Bohol!X16=TRUE,"✓","") -> ✓ | Y16: =IF(Bohol!Y16=TRUE,"✓","") | Z16: =IF(Bohol!Z16=TRUE,"✓","") -> ✓ | AA16: =IF(Bohol!AA16=TRUE,"✓","") | AB16: =IF(Bohol!AB16=TRUE,"✓","") -> ✓ | AC16: 2 | AD16: MEDIUM
A17: AGRICULTURE FORESTRY AND FISHERY | B17: CROP PRODUCTION | C17: FARM MECHANICS & OPERATORS | D17: REPAIR FARM EQUIPMENT | E17: NONE | F17: New and Emerging | G17: HIGH | I17: =IF(Bohol!H17=TRUE,"✓","") | J17: =IF(Bohol!I17=TRUE,"✓","") | K17: =IF(Bohol!J17=TRUE,"✓","") | L17: =IF(Bohol!K17=TRUE,"✓","") | M17: =IF(Bohol!L17=TRUE,"✓","") | N17: =IF(Bohol!M17=TRUE,"✓","") | P17: =IF(Bohol!P17=TRUE,"✓","") -> ✓ | Q17: =IF(Bohol!Q17=TRUE,"✓","") -> ✓ | R17: =IF(Bohol!R17=TRUE,"✓","") | S17: =IF(Bohol!S17=TRUE,"✓","") | T17: =IF(Bohol!T17=TRUE,"✓","") -> ✓ | U17: =IF(Bohol!U17=TRUE,"✓","") | V17: 1.5 | W17: HIGH | X17: =IF(Bohol!X17=TRUE,"✓","") -> ✓ | Y17: =IF(Bohol!Y17=TRUE,"✓","") -> ✓ | Z17: =IF(Bohol!Z17=TRUE,"✓","") | AA17: =IF(Bohol!AA17=TRUE,"✓","") | AB17: =IF(Bohol!AB17=TRUE,"✓","") -> ✓ | AC17: 1.5 | AD17: HIGH
A18: AGRICULTURE FORESTRY AND FISHERY | B18: FISHERIES | C18: FRESHWATER FISH GROWER | D18: COLLECT AND INCUBATE EGG IN HATCHERY | E18: AQUACULTURE (HATCHERY OPERATION) NC II | F18: With TR | G18: LOW | H18: 2.5 | I18: =IF(Bohol!H18=TRUE,"✓","") | J18: =IF(Bohol!I18=TRUE,"✓","") | K18: =IF(Bohol!J18=TRUE,"✓","") -> ✓ | L18: =IF(Bohol!K18=TRUE,"✓","") -> ✓ | M18: =IF(Bohol!L18=TRUE,"✓","") | N18: =IF(Bohol!M18=TRUE,"✓","") | O18: LOW | P18: =IF(Bohol!P18=TRUE,"✓","") | Q18: =IF(Bohol!Q18=TRUE,"✓","") | R18: =IF(Bohol!R18=TRUE,"✓","") -> ✓ | S18: =IF(Bohol!S18=TRUE,"✓","") -> ✓ | T18: =IF(Bohol!T18=TRUE,"✓","") | U18: =IF(Bohol!U18=TRUE,"✓","") | V18: 2.5 | W18: LOW | X18: =IF(Bohol!X18=TRUE,"✓","") | Y18: =IF(Bohol!Y18=TRUE,"✓","") | Z18: =IF(Bohol!Z18=TRUE,"✓","") -> ✓ | AA18: =IF(Bohol!AA18=TRUE,"✓","") -> ✓ | AB18: =IF(Bohol!AB18=TRUE,"✓","") | AC18: 2.5 | AD18: LOW
A19: AGRICULTURE FORESTRY AND FISHERY | B19: CROP PRODUCTION | C19: FRUITS, COCONUT TREES, UBI & CACAO PRODUCTION & PROCESSING | D19: UBI PRODUCTION AND PROCESSING | E19: NONE | F19: New and Emerging | G19: HIGH | H19: 1.5 | I19: =IF(Bohol!H19=TRUE,"✓","") -> ✓ | J19: =IF(Bohol!I19=TRUE,"✓","") -> ✓ | K19: =IF(Bohol!J19=TRUE,"✓","") | L19: =IF(Bohol!K19=TRUE,"✓","") | M19: =IF(Bohol!L19=TRUE,"✓","") -> ✓ | N19: =IF(Bohol!M19=TRUE,"✓","") | O19: HIGH | P19: =IF(Bohol!P19=TRUE,"✓","") -> ✓ | Q19: =IF(Bohol!Q19=TRUE,"✓","") -> ✓ | R19: =IF(Bohol!R19=TRUE,"✓","") | S19: =IF(Bohol!S19=TRUE,"✓","") | T19: =IF(Bohol!T19=TRUE,"✓","") -> ✓ | U19: =IF(Bohol!U19=TRUE,"✓","") | V19: 1.5 | W19: HIGH | X19: =IF(Bohol!X19=TRUE,"✓","") -> ✓ | Y19: =IF(Bohol!Y19=TRUE,"✓","") -> ✓ | Z19: =IF(Bohol!Z19=TRUE,"✓","") | AA19: =IF(Bohol!AA19=TRUE,"✓","") | AB19: =IF(Bohol!AB19=TRUE,"✓","") -> ✓ | AC19: 1.5 | AD19: HIGH
A20: AGRICULTURE FORESTRY AND FISHERY | B20: CROP PRODUCTION | C20: HEAVY EQUIPMENT OPERATOR (BACKHOE, GRADER) | D20: OPERATE BACKHOE AND GRADER FOR DIGGING WATER RESERVOIR | E20: HEAVY EQUIPMENT OPERATION (BACKHOE LOADER) NC II | F20: With TR | G20: HIGH | H20: 1 | I20: =IF(Bohol!H20=TRUE,"✓","") -> ✓ | J20: =IF(Bohol!I20=TRUE,"✓","") -> ✓ | K20: =IF(Bohol!J20=TRUE,"✓","") | L20: =IF(Bohol!K20=TRUE,"✓","") | M20: =IF(Bohol!L20=TRUE,"✓","") | N20: =IF(Bohol!M20=TRUE,"✓","") -> ✓ | O20: HIGH | P20: =IF(Bohol!P20=TRUE,"✓","") -> ✓ | Q20: =IF(Bohol!Q20=TRUE,"✓","") -> ✓ | R20: =IF(Bohol!R20=TRUE,"✓","") | S20: =IF(Bohol!S20=TRUE,"✓","") | T20: =IF(Bohol!T20=TRUE,"✓","") | U20: =IF(Bohol!U20=TRUE,"✓","") -> ✓ | V20: 1 | W20: HIGH | X20: =IF(Bohol!X20=TRUE,"✓","") -> ✓ | Y20: =IF(Bohol!Y20=TRUE,"✓","") -> ✓ | Z20: =IF(Bohol!Z20=TRUE,"✓","") | AA20: =IF(Bohol!AA20=TRUE,"✓","") | AB20: =IF(Bohol!AB20=TRUE,"✓","") | AC20: 1 | AD20: HIGH
A21: AGRICULTURE FORESTRY AND FISHERY | B21: CROP PRODUCTION | C21: HIGH /ORGANIC QUALITY SEEDS GROWER | D21: PRODUCE ORGANIC VEGETABLE SEEDS | E21: NONE | F21: New and Emerging | G21: HIGH | H21: 1 | I21: =IF(Bohol!H21=TRUE,"✓","") -> ✓ | J21: =IF(Bohol!I21=TRUE,"✓","") -> ✓ | K21: =IF(Bohol!J21=TRUE,"✓","") | L21: =IF(Bohol!K21=TRUE,"✓","") | M21: =IF(Bohol!L21=TRUE,"✓","") | N21: =IF(Bohol!M21=TRUE,"✓","") -> ✓ | O21: HIGH | P21: =IF(Bohol!P21=TRUE,"✓","") -> ✓ | Q21: =IF(Bohol!Q21=TRUE,"✓","") -> ✓ | R21: =IF(Bohol!R21=TRUE,"✓","") | S21: =IF(Bohol!S21=TRUE,"✓","") | T21: =IF(Bohol!T21=TRUE,"✓","") | U21: =IF(Bohol!U21=TRUE,"✓","") -> ✓ | V21: 1 | W21: HIGH | X21: =IF(Bohol!X21=TRUE,"✓","") -> ✓ | Y21: =IF(Bohol!Y21=TRUE,"✓","") -> ✓ | Z21: =IF(Bohol!Z21=TRUE,"✓","") | AA21: =IF(Bohol!AA21=TRUE,"✓","") | AB21: =IF(Bohol!AB21=TRUE,"✓","") | AC21: 1 | AD21: HIGH
A22: AGRICULTURE FORESTRY AND FISHERY | B22: CROP PRODUCTION | C22: HIGH QUALITY INBREED RICE GROWER | D22: RICE PRODUCTION SEED CERTIFICATION AND FARM MECHANIZATION | E22: NONE | F22: New and Emerging | G22: MEDIUM | H22: 2 | I22: =IF(Bohol!H22=TRUE,"✓","") -> ✓ | J22: =IF(Bohol!I22=TRUE,"✓","") | K22: =IF(Bohol!J22=TRUE,"✓","") -> ✓ | L22: =IF(Bohol!K22=TRUE,"✓","") | M22: =IF(Bohol!L22=TRUE,"✓","") -> ✓ | N22: =IF(Bohol!M22=TRUE,"✓","") | O22: MEDIUM | P22: =IF(Bohol!P22=TRUE,"✓","") | Q22: =IF(Bohol!Q22=TRUE,"✓","") | R22: =IF(Bohol!R22=TRUE,"✓","") -> ✓ | S22: =IF(Bohol!S22=TRUE,"✓","") | T22: =IF(Bohol!T22=TRUE,"✓","") -> ✓ | U22: =IF(Bohol!U22=TRUE,"✓","") | V22: 2 | W22: MEDIUM | X22: =IF(Bohol!X22=TRUE,"✓","") | Y22: =IF(Bohol!Y22=TRUE,"✓","") | Z22: =IF(Bohol!Z22=TRUE,"✓","") -> ✓ | AA22: =IF(Bohol!AA22=TRUE,"✓","") | AB22: =IF(Bohol!AB22=TRUE,"✓","") -> ✓ | AC22: 2 | AD22: MEDIUM
A23: AGRICULTURE FORESTRY AND FISHERY | B23: CROP PRODUCTION | C23: INTERCROPPING TECHNICIAN | D23: IDENTIFY COMPATIBLE CROPS WITH COCONUT | E23: NONE | F23: New and Emerging | G23: MEDIUM | H23: 2 | I23: =IF(Bohol!H23=TRUE,"✓","") -> ✓ | J23: =IF(Bohol!I23=TRUE,"✓","") | K23: =IF(Bohol!J23=TRUE,"✓","") -> ✓ | L23: =IF(Bohol!K23=TRUE,"✓","") | M23: =IF(Bohol!L23=TRUE,"✓","") -> ✓ | N23: =IF(Bohol!M23=TRUE,"✓","") | O23: MEDIUM | P23: =IF(Bohol!P23=TRUE,"✓","") | Q23: =IF(Bohol!Q23=TRUE,"✓","") | R23: =IF(Bohol!R23=TRUE,"✓","") -> ✓ | S23: =IF(Bohol!S23=TRUE,"✓","") | T23: =IF(Bohol!T23=TRUE,"✓","") -> ✓ | U23: =IF(Bohol!U23=TRUE,"✓","") | V23: 2 | W23: MEDIUM | X23: =IF(Bohol!X23=TRUE,"✓","") | Y23: =IF(Bohol!Y23=TRUE,"✓","") | Z23: =IF(Bohol!Z23=TRUE,"✓","") -> ✓ | AA23: =IF(Bohol!AA23=TRUE,"✓","") | AB23: =IF(Bohol!AB23=TRUE,"✓","") -> ✓ | AC23: 2 | AD23: MEDIUM
A24: AGRICULTURE FORESTRY AND FISHERY | B24: CROP PRODUCTION | C24: INTERGRATED COCONUT AND CASH CROPS PRODUCTION AND PROCESSING (BY PRODUCTS LIKE SHELL,DUST, COIR) | D24: PRODUCE COCONUT and PROCESS COCONUT PRDUCTS AND BY PRODUCTS | E24: COCONUT PRODUCTION LEVEL II | F24: With CS | G24: HIGH | H24: 1.5 | I24: =IF(Bohol!H24=TRUE,"✓","") -> ✓ | J24: =IF(Bohol!I24=TRUE,"✓","") -> ✓ | K24: =IF(Bohol!J24=TRUE,"✓","") | L24: =IF(Bohol!K24=TRUE,"✓","") | M24: =IF(Bohol!L24=TRUE,"✓","") -> ✓ | N24: =IF(Bohol!M24=TRUE,"✓","") | O24: HIGH | P24: =IF(Bohol!P24=TRUE,"✓","") -> ✓ | Q24: =IF(Bohol!Q24=TRUE,"✓","") -> ✓ | R24: =IF(Bohol!R24=TRUE,"✓","") | S24: =IF(Bohol!S24=TRUE,"✓","") | T24: =IF(Bohol!T24=TRUE,"✓","") -> ✓ | U24: =IF(Bohol!U24=TRUE,"✓","") | V24: 1.5 | W24: HIGH | X24: =IF(Bohol!X24=TRUE,"✓","") -> ✓ | Y24: =IF(Bohol!Y24=TRUE,"✓","") -> ✓ | Z24: =IF(Bohol!Z24=TRUE,"✓","") | AA24: =IF(Bohol!AA24=TRUE,"✓","") | AB24: =IF(Bohol!AB24=TRUE,"✓","") -> ✓ | AC24: 1.5 | AD24: HIGH
A25: AGRICULTURE FORESTRY AND FISHERY | B25: HORTICULTURE | C25: LANDSCAPE PLANTS (ORNAMENTAL AND CUT FLOWER) CULTURE, CARE AND MAINTENANCE | D25: PROPAGATE, PLANT CARE, MAINTAIN, LANDSCAPE AND MANAGE ORNAMENTAL PLANTS | E25: LANDSCAPE INSTALLATION AND MAINTENANCE (SOFTSCAPE) NC II | F25: With TR | G25: HIGH | H25: 1.5 | I25: =IF(Bohol!H25=TRUE,"✓","") -> ✓ | J25: =IF(Bohol!I25=TRUE,"✓","") -> ✓ | K25: =IF(Bohol!J25=TRUE,"✓","") | L25: =IF(Bohol!K25=TRUE,"✓","") | M25: =IF(Bohol!L25=TRUE,"✓","") -> ✓ | N25: =IF(Bohol!M25=TRUE,"✓","") | O25: HIGH | P25: =IF(Bohol!P25=TRUE,"✓","") -> ✓ | Q25: =IF(Bohol!Q25=TRUE,"✓","") -> ✓ | R25: =IF(Bohol!R25=TRUE,"✓","") | S25: =IF(Bohol!S25=TRUE,"✓","") | T25: =IF(Bohol!T25=TRUE,"✓","") -> ✓ | U25: =IF(Bohol!U25=TRUE,"✓","") | V25: 1.5 | W25: HIGH | X25: =IF(Bohol!X25=TRUE,"✓","") -> ✓ | Y25: =IF(Bohol!Y25=TRUE,"✓","") -> ✓ | Z25: =IF(Bohol!Z25=TRUE,"✓","") | AA25: =IF(Bohol!AA25=TRUE,"✓","") | AB25: =IF(Bohol!AB25=TRUE,"✓","") -> ✓ | AC25: 1.5 | AD25: HIGH
A26: AGRICULTURE FORESTRY AND FISHERY | B26: CROP PRODUCTION | C26: MAKE ORGANIC FERTILIZER & CONCOCTION | D26: PRODUCE ORGANIC FERTILIZER, SEEDS, RICE | E26: ORGANIC AGRICULTURE PRODUCTION NC II | F26: With TR | G26: HIGH | H26: 1 | I26: =IF(Bohol!H26=TRUE,"✓","") -> ✓ | J26: =IF(Bohol!I26=TRUE,"✓","") -> ✓ | K26: =IF(Bohol!J26=TRUE,"✓","") | L26: =IF(Bohol!K26=TRUE,"✓","") | M26: =IF(Bohol!L26=TRUE,"✓","") | N26: =IF(Bohol!M26=TRUE,"✓","") -> ✓ | O26: HIGH | P26: =IF(Bohol!P26=TRUE,"✓","") -> ✓ | Q26: =IF(Bohol!Q26=TRUE,"✓","") -> ✓ | R26: =IF(Bohol!R26=TRUE,"✓","") | S26: =IF(Bohol!S26=TRUE,"✓","") | T26: =IF(Bohol!T26=TRUE,"✓","") | U26: =IF(Bohol!U26=TRUE,"✓","") -> ✓ | V26: 1 | W26: HIGH | X26: =IF(Bohol!X26=TRUE,"✓","") -> ✓ | Y26: =IF(Bohol!Y26=TRUE,"✓","") -> ✓ | Z26: =IF(Bohol!Z26=TRUE,"✓","") | AA26: =IF(Bohol!AA26=TRUE,"✓","") | AB26: =IF(Bohol!AB26=TRUE,"✓","") | AC26: 1 | AD26: HIGH
A27: AGRICULTURE FORESTRY AND FISHERY | B27: CROP PRODUCTION | C27: MEDICINAL TEA PRODUCTION AND PROCESSING (TURMERIC,SALABAT,MORINGA,ETC.) | D27: PRODUCE AND PROCESS MEDICINAL PLANTS | E27: NONE | F27: New and Emerging | G27: HIGH | H27: 1 | I27: =IF(Bohol!H27=TRUE,"✓","") -> ✓ | J27: =IF(Bohol!I27=TRUE,"✓","") -> ✓ | K27: =IF(Bohol!J27=TRUE,"✓","") | L27: =IF(Bohol!K27=TRUE,"✓","") | M27: =IF(Bohol!L27=TRUE,"✓","") | N27: =IF(Bohol!M27=TRUE,"✓","") -> ✓ | O27: HIGH | P27: =IF(Bohol!P27=TRUE,"✓","") -> ✓ | Q27: =IF(Bohol!Q27=TRUE,"✓","") -> ✓ | R27: =IF(Bohol!R27=TRUE,"✓","") | S27: =IF(Bohol!S27=TRUE,"✓","") | T27: =IF(Bohol!T27=TRUE,"✓","") | U27: =IF(Bohol!U27=TRUE,"✓","") -> ✓ | V27: 1 | W27: HIGH | X27: =IF(Bohol!X27=TRUE,"✓","") -> ✓ | Y27: =IF(Bohol!Y27=TRUE,"✓","") -> ✓ | Z27: =IF(Bohol!Z27=TRUE,"✓","") | AA27: =IF(Bohol!AA27=TRUE,"✓","") | AB27: =IF(Bohol!AB27=TRUE,"✓","") | AC27: 1 | AD27: HIGH
A28: AGRICULTURE FORESTRY AND FISHERY | B28: AGRICULTURE | C28: REPAIR OF FARM MECHANICAL EQUIPMENT | D28: REPAIR FARM EQUIPMENT | E28: NONE | F28: New and Emerging | G28: HIGH | H28: 1 | I28: =IF(Bohol!H28=TRUE,"✓","") -> ✓ | J28: =IF(Bohol!I28=TRUE,"✓","") -> ✓ | K28: =IF(Bohol!J28=TRUE,"✓","") | L28: =IF(Bohol!K28=TRUE,"✓","") | M28: =IF(Bohol!L28=TRUE,"✓","") | N28: =IF(Bohol!M28=TRUE,"✓","") -> ✓ | O28: HIGH | P28: =IF(Bohol!P28=TRUE,"✓","") -> ✓ | Q28: =IF(Bohol!Q28=TRUE,"✓","") -> ✓ | R28: =IF(Bohol!R28=TRUE,"✓","") | S28: =IF(Bohol!S28=TRUE,"✓","") | T28: =IF(Bohol!T28=TRUE,"✓","") | U28: =IF(Bohol!U28=TRUE,"✓","") -> ✓ | V28: 1 | W28: HIGH | X28: =IF(Bohol!X28=TRUE,"✓","") -> ✓ | Y28: =IF(Bohol!Y28=TRUE,"✓","") -> ✓ | Z28: =IF(Bohol!Z28=TRUE,"✓","") | AA28: =IF(Bohol!AA28=TRUE,"✓","") | AB28: =IF(Bohol!AB28=TRUE,"✓","") | AC28: 1 | AD28: HIGH
A29: AGRICULTURE FORESTRY AND FISHERY | B29: CROP PRODUCTION | C29: RICE MACHINES OPERATORS | D29: OPERATE RICE MACHINERIES | E29: RICE MACHINERY OPERATIONS NC II | F29: With TR | G29: HIGH | H29: 1.5 | I29: =IF(Bohol!H29=TRUE,"✓","") | J29: =IF(Bohol!I29=TRUE,"✓","") -> ✓ | K29: =IF(Bohol!J29=TRUE,"✓","") | L29: =IF(Bohol!K29=TRUE,"✓","") | M29: =IF(Bohol!L29=TRUE,"✓","") -> ✓ | N29: =IF(Bohol!M29=TRUE,"✓","") | O29: HIGH | P29: =IF(Bohol!P29=TRUE,"✓","") | Q29: =IF(Bohol!Q29=TRUE,"✓","") -> ✓ | R29: =IF(Bohol!R29=TRUE,"✓","") | S29: =IF(Bohol!S29=TRUE,"✓","") | T29: =IF(Bohol!T29=TRUE,"✓","") -> ✓ | U29: =IF(Bohol!U29=TRUE,"✓","") | V29: 1.5 | W29: HIGH | X29: =IF(Bohol!X29=TRUE,"✓","") | Y29: =IF(Bohol!Y29=TRUE,"✓","") -> ✓ | Z29: =IF(Bohol!Z29=TRUE,"✓","") | AA29: =IF(Bohol!AA29=TRUE,"✓","") | AB29: =IF(Bohol!AB29=TRUE,"✓","") -> ✓ | AC29: 1.5 | AD29: HIGH
... A89: INFORMATION AND COMMUNICATION TECHNOLOGY | B89: CONTACT CENTER AND BPO | C89: CALL CENTER AGENTS | D89: ASSESS AND RESOLVE CLIENT CONCERN | E89: CONTACT CENTER SERVICES NC II | F89: With TR | G89: HIGH | H89: 1 | I89: =IF(Bohol!H89=TRUE,"✓","") -> ✓ | J89: =IF(Bohol!I89=TRUE,"✓","") -> ✓ | K89: =IF(Bohol!J89=TRUE,"✓","") | L89: =IF(Bohol!K89=TRUE,"✓","") | M89: =IF(Bohol!L89=TRUE,"✓","") | N89: =IF(Bohol!M89=TRUE,"✓","") -> ✓ | O89: HIGH | P89: =IF(Bohol!P89=TRUE,"✓","") -> ✓ | Q89: =IF(Bohol!Q89=TRUE,"✓","") -> ✓ | R89: =IF(Bohol!R89=TRUE,"✓","") | S89: =IF(Bohol!S89=TRUE,"✓","") | T89: =IF(Bohol!T89=TRUE,"✓","") | U89: =IF(Bohol!U89=TRUE,"✓","") -> ✓ | V89: 1 | W89: HIGH | X89: =IF(Bohol!X89=TRUE,"✓","") -> ✓ | Y89: =IF(Bohol!Y89=TRUE,"✓","") -> ✓ | Z89: =IF(Bohol!Z89=TRUE,"✓","") | AA89: =IF(Bohol!AA89=TRUE,"✓","") | AB89: =IF(Bohol!AB89=TRUE,"✓","") | AC89: 1 | AD89: HIGH
A90: INFORMATION AND COMMUNICATION TECHNOLOGY | B90: INFORMATION TECHNOLOGY SERVICES | C90: COMPUTER LITERATE AND PROFICIENT TO WINDOWS OS, APPLE OS, X, MS OFFICE AND GOOGLE APPLICATION | D90: PERFORM OFFICE APPLICATION SOFTWARES | E90: COMPUTER SYSTEMS SERVICING NC II | F90: With TR | G90: MEDIUM | I90: =IF(Bohol!H90=TRUE,"✓","") | J90: =IF(Bohol!I90=TRUE,"✓","") | K90: =IF(Bohol!J90=TRUE,"✓","") | L90: =IF(Bohol!K90=TRUE,"✓","") | M90: =IF(Bohol!L90=TRUE,"✓","") | N90: =IF(Bohol!M90=TRUE,"✓","") | P90: =IF(Bohol!P90=TRUE,"✓","") -> ✓ | Q90: =IF(Bohol!Q90=TRUE,"✓","") -> ✓ | R90: =IF(Bohol!R90=TRUE,"✓","") | S90: =IF(Bohol!S90=TRUE,"✓","") -> ✓ | T90: =IF(Bohol!T90=TRUE,"✓","") | U90: =IF(Bohol!U90=TRUE,"✓","") | V90: 2 | W90: MEDIUM | X90: =IF(Bohol!X90=TRUE,"✓","") -> ✓ | Y90: =IF(Bohol!Y90=TRUE,"✓","") -> ✓ | Z90: =IF(Bohol!Z90=TRUE,"✓","") | AA90: =IF(Bohol!AA90=TRUE,"✓","") -> ✓ | AB90: =IF(Bohol!AB90=TRUE,"✓","") | AC90: 2 | AD90: MEDIUM
A91: INFORMATION AND COMMUNICATION TECHNOLOGY | B91: CONTACT CENTER AND BPO | C91: CUSTOMER SERVICE REPRESENTATIVE | D91: ASSESS AND RESOLVE CUSTOMER CONCERN | E91: CONTACT CENTER SERVICES NC II | F91: With TR | G91: HIGH | H91: 1 | I91: =IF(Bohol!H91=TRUE,"✓","") -> ✓ | J91: =IF(Bohol!I91=TRUE,"✓","") -> ✓ | K91: =IF(Bohol!J91=TRUE,"✓","") | L91: =IF(Bohol!K91=TRUE,"✓","") | M91: =IF(Bohol!L91=TRUE,"✓","") | N91: =IF(Bohol!M91=TRUE,"✓","") -> ✓ | O91: HIGH | P91: =IF(Bohol!P91=TRUE,"✓","") -> ✓ | Q91: =IF(Bohol!Q91=TRUE,"✓","") -> ✓ | R91: =IF(Bohol!R91=TRUE,"✓","") | S91: =IF(Bohol!S91=TRUE,"✓","") | T91: =IF(Bohol!T91=TRUE,"✓","") | U91: =IF(Bohol!U91=TRUE,"✓","") -> ✓ | V91: 1 | W91: HIGH | X91: =IF(Bohol!X91=TRUE,"✓","") -> ✓ | Y91: =IF(Bohol!Y91=TRUE,"✓","") -> ✓ | Z91: =IF(Bohol!Z91=TRUE,"✓","") | AA91: =IF(Bohol!AA91=TRUE,"✓","") | AB91: =IF(Bohol!AB91=TRUE,"✓","") | AC91: 1 | AD91: HIGH
A92: INFORMATION AND COMMUNICATION TECHNOLOGY | B92: INFORMATION TECHNOLOGY SERVICES | C92: CYBER SECURITY | D92: MANAGE AND SECURE CYBERSPACE | E92: CYBER RISK ASSESSMENT LEVEL III | F92: With TR | G92: HIGH | I92: =IF(Bohol!H92=TRUE,"✓","") | J92: =IF(Bohol!I92=TRUE,"✓","") | K92: =IF(Bohol!J92=TRUE,"✓","") | L92: =IF(Bohol!K92=TRUE,"✓","") | M92: =IF(Bohol!L92=TRUE,"✓","") | N92: =IF(Bohol!M92=TRUE,"✓","") | P92: =IF(Bohol!P92=TRUE,"✓","") -> ✓ | Q92: =IF(Bohol!Q92=TRUE,"✓","") -> ✓ | R92: =IF(Bohol!R92=TRUE,"✓","") | S92: =IF(Bohol!S92=TRUE,"✓","") | T92: =IF(Bohol!T92=TRUE,"✓","") | U92: =IF(Bohol!U92=TRUE,"✓","") -> ✓ | V92: 1 | W92: HIGH | X92: =IF(Bohol!X92=TRUE,"✓","") | Y92: =IF(Bohol!Y92=TRUE,"✓","") | Z92: =IF(Bohol!Z92=TRUE,"✓","") | AA92: =IF(Bohol!AA92=TRUE,"✓","") | AB92: =IF(Bohol!AB92=TRUE,"✓","")
A93: INFORMATION AND COMMUNICATION TECHNOLOGY | B93: E-COMMERCE | C93: DATA ANALYST | D93: ANALYZE DATA HISTORICALS TO PROVIDE FORECAST | E93: DATA ANALYTICS LEVEL III | F93: With TR | G93: HIGH | H93: 1 | I93: =IF(Bohol!H93=TRUE,"✓","") -> ✓ | J93: =IF(Bohol!I93=TRUE,"✓","") -> ✓ | K93: =IF(Bohol!J93=TRUE,"✓","") | L93: =IF(Bohol!K93=TRUE,"✓","") | M93: =IF(Bohol!L93=TRUE,"✓","") | N93: =IF(Bohol!M93=TRUE,"✓","") -> ✓ | O93: HIGH | P93: =IF(Bohol!P93=TRUE,"✓","") -> ✓ | Q93: =IF(Bohol!Q93=TRUE,"✓","") -> ✓ | R93: =IF(Bohol!R93=TRUE,"✓","") | S93: =IF(Bohol!S93=TRUE,"✓","") | T93: =IF(Bohol!T93=TRUE,"✓","") | U93: =IF(Bohol!U93=TRUE,"✓","") -> ✓ | V93: 1 | W93: HIGH | X93: =IF(Bohol!X93=TRUE,"✓","") -> ✓ | Y93: =IF(Bohol!Y93=TRUE,"✓","") -> ✓ | Z93: =IF(Bohol!Z93=TRUE,"✓","") | AA93: =IF(Bohol!AA93=TRUE,"✓","") | AB93: =IF(Bohol!AB93=TRUE,"✓","") | AC93: 1 | AD93: HIGH
A94: INFORMATION AND COMMUNICATION TECHNOLOGY | B94: MULTIMEDIA SERVICES | C94: GRAPHIC DESIGNERS | D94: CREATE AND DESIGN GRAPHICS | E94: VISUAL GRAPHIC DESIGN NC III | F94: With TR | G94: HIGH | H94: 1 | I94: =IF(Bohol!H94=TRUE,"✓","") -> ✓ | J94: =IF(Bohol!I94=TRUE,"✓","") -> ✓ | K94: =IF(Bohol!J94=TRUE,"✓","") | L94: =IF(Bohol!K94=TRUE,"✓","") | M94: =IF(Bohol!L94=TRUE,"✓","") | N94: =IF(Bohol!M94=TRUE,"✓","") -> ✓ | O94: HIGH | P94: =IF(Bohol!P94=TRUE,"✓","") -> ✓ | Q94: =IF(Bohol!Q94=TRUE,"✓","") -> ✓ | R94: =IF(Bohol!R94=TRUE,"✓","") | S94: =IF(Bohol!S94=TRUE,"✓","") | T94: =IF(Bohol!T94=TRUE,"✓","") | U94: =IF(Bohol!U94=TRUE,"✓","") -> ✓ | V94: 1 | W94: HIGH | X94: =IF(Bohol!X94=TRUE,"✓","") -> ✓ | Y94: =IF(Bohol!Y94=TRUE,"✓","") -> ✓ | Z94: =IF(Bohol!Z94=TRUE,"✓","") | AA94: =IF(Bohol!AA94=TRUE,"✓","") | AB94: =IF(Bohol!AB94=TRUE,"✓","") | AC94: 1 | AD94: HIGH
A95: INFORMATION AND COMMUNICATION TECHNOLOGY | B95: INFORMATION TECHNOLOGY SERVICES | C95: HARDWARE DEPLOYMENT | D95: INSTALLATION OF ICT INFRASTRUCTURE | E95: COMPUTER SYSTEMS SERVICING NC II | F95: With TR | G95: HIGH | I95: =IF(Bohol!H95=TRUE,"✓","") | J95: =IF(Bohol!I95=TRUE,"✓","") | K95: =IF(Bohol!J95=TRUE,"✓","") | L95: =IF(Bohol!K95=TRUE,"✓","") | M95: =IF(Bohol!L95=TRUE,"✓","") | N95: =IF(Bohol!M95=TRUE,"✓","") | P95: =IF(Bohol!P95=TRUE,"✓","") -> ✓ | Q95: =IF(Bohol!Q95=TRUE,"✓","") -> ✓ | R95: =IF(Bohol!R95=TRUE,"✓","") | S95: =IF(Bohol!S95=TRUE,"✓","") | T95: =IF(Bohol!T95=TRUE,"✓","") -> ✓ | U95: =IF(Bohol!U95=TRUE,"✓","") | V95: 1.5 | W95: HIGH | X95: =IF(Bohol!X95=TRUE,"✓","") | Y95: =IF(Bohol!Y95=TRUE,"✓","") | Z95: =IF(Bohol!Z95=TRUE,"✓","") | AA95: =IF(Bohol!AA95=TRUE,"✓","") | AB95: =IF(Bohol!AB95=TRUE,"✓","")
A96: INFORMATION AND COMMUNICATION TECHNOLOGY | B96: INFORMATION TECHNOLOGY SERVICES | C96: IT SKILLED INDIVIDUAL | D96: PROVIDE ICT SERVICES | E96: COMPUTER SYSTEMS SERVICING NC II | F96: With TR | G96: HIGH | H96: 1 | I96: =IF(Bohol!H96=TRUE,"✓","") -> ✓ | J96: =IF(Bohol!I96=TRUE,"✓","") -> ✓ | K96: =IF(Bohol!J96=TRUE,"✓","") | L96: =IF(Bohol!K96=TRUE,"✓","") | M96: =IF(Bohol!L96=TRUE,"✓","") | N96: =IF(Bohol!M96=TRUE,"✓","") -> ✓ | O96: HIGH | P96: =IF(Bohol!P96=TRUE,"✓","") -> ✓ | Q96: =IF(Bohol!Q96=TRUE,"✓","") -> ✓ | R96: =IF(Bohol!R96=TRUE,"✓","") | S96: =IF(Bohol!S96=TRUE,"✓","") | T96: =IF(Bohol!T96=TRUE,"✓","") | U96: =IF(Bohol!U96=TRUE,"✓","") -> ✓ | V96: 1 | W96: HIGH | X96: =IF(Bohol!X96=TRUE,"✓","") -> ✓ | Y96: =IF(Bohol!Y96=TRUE,"✓","") -> ✓ | Z96: =IF(Bohol!Z96=TRUE,"✓","") | AA96: =IF(Bohol!AA96=TRUE,"✓","") | AB96: =IF(Bohol!AB96=TRUE,"✓","") | AC96: 1 | AD96: HIGH
A97: INFORMATION AND COMMUNICATION TECHNOLOGY | B97: MULTIMEDIA SERVICES | C97: MASTER OF PHOTOSHOP | D97: CREATE AND DESIGN GRAPHICS | E97: VISUAL GRAPHIC DESIGN NC III | F97: With TR | G97: HIGH | I97: =IF(Bohol!H97=TRUE,"✓","") | J97: =IF(Bohol!I97=TRUE,"✓","") | K97: =IF(Bohol!J97=TRUE,"✓","") | L97: =IF(Bohol!K97=TRUE,"✓","") | M97: =IF(Bohol!L97=TRUE,"✓","") | N97: =IF(Bohol!M97=TRUE,"✓","") | P97: =IF(Bohol!P97=TRUE,"✓","") -> ✓ | Q97: =IF(Bohol!Q97=TRUE,"✓","") -> ✓ | R97: =IF(Bohol!R97=TRUE,"✓","") | S97: =IF(Bohol!S97=TRUE,"✓","") | T97: =IF(Bohol!T97=TRUE,"✓","") -> ✓ | U97: =IF(Bohol!U97=TRUE,"✓","") | V97: 1.5 | W97: HIGH | X97: =IF(Bohol!X97=TRUE,"✓","") | Y97: =IF(Bohol!Y97=TRUE,"✓","") | Z97: =IF(Bohol!Z97=TRUE,"✓","") | AA97: =IF(Bohol!AA97=TRUE,"✓","") | AB97: =IF(Bohol!AB97=TRUE,"✓","")
A98: INFORMATION AND COMMUNICATION TECHNOLOGY | B98: INFORMATION TECHNOLOGY SERVICES | C98: NETWORK ENGINEER AND FIBER OPTIC SPECIALIST | D98: MANAGE AND INSTALL PREMISES/OUTSIDE PLANT COPPER OR FIBER NETWORKS | E98: TELECOM OSP INSTALLATION (FIBER OPTIC CABLE) NC II | F98: With TR | G98: MEDIUM | I98: =IF(Bohol!H98=TRUE,"✓","") | J98: =IF(Bohol!I98=TRUE,"✓","") | K98: =IF(Bohol!J98=TRUE,"✓","") | L98: =IF(Bohol!K98=TRUE,"✓","") | M98: =IF(Bohol!L98=TRUE,"✓","") | N98: =IF(Bohol!M98=TRUE,"✓","") | P98: =IF(Bohol!P98=TRUE,"✓","") -> ✓ | Q98: =IF(Bohol!Q98=TRUE,"✓","") -> ✓ | R98: =IF(Bohol!R98=TRUE,"✓","") | S98: =IF(Bohol!S98=TRUE,"✓","") -> ✓ | T98: =IF(Bohol!T98=TRUE,"✓","") | U98: =IF(Bohol!U98=TRUE,"✓","") | V98: 2 | W98: MEDIUM | X98: =IF(Bohol!X98=TRUE,"✓","") -> ✓ | Y98: =IF(Bohol!Y98=TRUE,"✓","") -> ✓ | Z98: =IF(Bohol!Z98=TRUE,"✓","") | AA98: =IF(Bohol!AA98=TRUE,"✓","") -> ✓ | AB98: =IF(Bohol!AB98=TRUE,"✓","") | AC98: 2 | AD98: MEDIUM
A99: INFORMATION AND COMMUNICATION TECHNOLOGY | B99: INFORMATION TECHNOLOGY SERVICES | C99: SENIOR DRUPAL DEVELOPER | D99: CONCEPTUALIZE, DESIGN, DEPLOY AND MONITOR WEBSITE | E99: WEB DEVELOPMENT NC III | F99: With TR | G99: MEDIUM | H99: 2 | I99: =IF(Bohol!H99=TRUE,"✓","") -> ✓ | J99: =IF(Bohol!I99=TRUE,"✓","") -> ✓ | K99: =IF(Bohol!J99=TRUE,"✓","") | L99: =IF(Bohol!K99=TRUE,"✓","") -> ✓ | M99: =IF(Bohol!L99=TRUE,"✓","") | N99: =IF(Bohol!M99=TRUE,"✓","") | O99: MEDIUM | P99: =IF(Bohol!P99=TRUE,"✓","") -> ✓ | Q99: =IF(Bohol!Q99=TRUE,"✓","") -> ✓ | R99: =IF(Bohol!R99=TRUE,"✓","") | S99: =IF(Bohol!S99=TRUE,"✓","") -> ✓ | T99: =IF(Bohol!T99=TRUE,"✓","") | U99: =IF(Bohol!U99=TRUE,"✓","") | V99: 2 | W99: MEDIUM | X99: =IF(Bohol!X99=TRUE,"✓","") -> ✓ | Y99: =IF(Bohol!Y99=TRUE,"✓","") -> ✓ | Z99: =IF(Bohol!Z99=TRUE,"✓","") | AA99: =IF(Bohol!AA99=TRUE,"✓","") -> ✓ | AB99: =IF(Bohol!AB99=TRUE,"✓","") | AC99: 2 | AD99: MEDIUM
A100: INFORMATION AND COMMUNICATION TECHNOLOGY | B100: INFORMATION TECHNOLOGY SERVICES | C100: SENIOR SWIFT DEVELOPER | D100: CONCEPTUALIZE, DESIGN, DEPLOY AND MONITOR APPLICATIONS (EITHER WEB, DESKTOP OR MOBILE) | E100: WEB DEVELOPMENT NC III | F100: With TR | G100: HIGH | H100: 1 | I100: =IF(Bohol!H100=TRUE,"✓","") -> ✓ | J100: =IF(Bohol!I100=TRUE,"✓","") -> ✓ | K100: =IF(Bohol!J100=TRUE,"✓","") | L100: =IF(Bohol!K100=TRUE,"✓","") | M100: =IF(Bohol!L100=TRUE,"✓","") | N100: =IF(Bohol!M100=TRUE,"✓","") -> ✓ | O100: HIGH | P100: =IF(Bohol!P100=TRUE,"✓","") -> ✓ | Q100: =IF(Bohol!Q100=TRUE,"✓","") -> ✓ | R100: =IF(Bohol!R100=TRUE,"✓","") | S100: =IF(Bohol!S100=TRUE,"✓","") | T100: =IF(Bohol!T100=TRUE,"✓","") | U100: =IF(Bohol!U100=TRUE,"✓","") -> ✓ | V100: 1 | W100: HIGH | X100: =IF(Bohol!X100=TRUE,"✓","") -> ✓ | Y100: =IF(Bohol!Y100=TRUE,"✓","") -> ✓ | Z100: =IF(Bohol!Z100=TRUE,"✓","") | AA100: =IF(Bohol!AA100=TRUE,"✓","") | AB100: =IF(Bohol!AB100=TRUE,"✓","") | AC100: 1 | AD100: HIGH
...

Sheet Cebu
A1: Region | B1: REGION_VII
A2: Province | B2: CEBU
A3: Number of Districts | B3: 11
A4: Sector | B4: Subsector/ Value Chain | C4: Job Requirement | D4: Tasks | E4: Program | F4: Type of Program (TR, CS, New and Emerging, Diploma Programs) | G4: Provincial Rank (Averaged Across Districts)
H5: D1 | P5: D2 | AA5: D3 | AL5: D4 | AW5: D5 | BG5: D6 | BS5: D7 | CD5: D8 | CO5: D9 | CZ5: D10 | DK5: D11
A6: AGRICULTURE FORESTRY AND FISHERY | B6: CROP PRODUCTION | C6: BAMBOO FARM WORKER | D6: PLANT BAMBOO SEEDLINGS PERFORM MAINTENANCE OF BAMBOO FARM GENERAL FARM SUPPORT | E6: BAMBOO PRODUCTION NC II | F6: With TR | G6: HIGH | H6: FALSE | I6: FALSE | J6: FALSE | K6: FALSE | L6: FALSE | M6: FALSE | P6: FALSE | S6: FALSE | T6: FALSE | U6: FALSE | V6: FALSE | W6: FALSE | X6: FALSE | AA6: FALSE | AD6: FALSE | AE6: FALSE | AF6: FALSE | AG6: FALSE | AH6: FALSE | AI6: FALSE | AL6: FALSE | AO6: FALSE | AP6: FALSE | AQ6: FALSE | AR6: FALSE | AS6: FALSE | AT6: FALSE | AW6: FALSE | AZ6: TRUE | BA6: TRUE | BB6: TRUE | BC6: FALSE | BD6: FALSE | BE6: TRUE | BF6: 1.25 | BG6: HIGH | BH6: TRUE | BI6: REGION_VII|CEBU|Cebu, District 3|AGRICULTURE FORESTRY AND FISHERY|AGRICULTURAL SERVICES|BAMBOO GROWER||BAMBOO PRODUCTION NC II||With TR|HIGH | BK6: FALSE | BL6: FALSE | BM6: FALSE | BN6: FALSE | BO6: FALSE | BP6: FALSE | BS6: FALSE | BV6: FALSE | BW6: FALSE | BX6: FALSE | BY6: FALSE | BZ6: FALSE | CA6: FALSE | CD6: FALSE | CG6: FALSE | CH6: FALSE | CI6: FALSE | CJ6: FALSE | CK6: FALSE | CL6: FALSE | CO6: FALSE | CR6: FALSE | CS6: FALSE | CT6: FALSE | CU6: FALSE | CV6: FALSE | CW6: FALSE | CZ6: FALSE | DC6: FALSE | DD6: FALSE | DE6: FALSE | DF6: FALSE | DG6: FALSE | DH6: FALSE | DK6: FALSE | DN6: FALSE | DO6: FALSE | DP6: FALSE | DQ6: FALSE | DR6: FALSE | DS6: FALSE
A7: AGRICULTURE FORESTRY AND FISHERY | B7: AGRICULTURAL SERVICES | C7: BAMBOO GROWER | D7: PERFORM NURSERY OPERATION COLLECT PROPAGULES BAMBOO CULTIVIATION CARE AND MAINTAIN HARVESTING | E7: BAMBOO PRODUCTION NC II | F7: With TR | G7: HIGH | H7: TRUE | I7: TRUE | J7: TRUE | K7: FALSE | L7: FALSE | M7: TRUE | N7: 1.25 | O7: HIGH | P7: TRUE | Q7: REGION_VII|CEBU|Cebu City, District 1|AGRICULTURE FORESTRY AND FISHERY|AGRICULTURAL SERVICES|CACAO FARM TECHNCIAN||CACAO PRODUCTION LEVEL II||With CS|HIGH | S7: FALSE | T7: FALSE | U7: FALSE | V7: FALSE | W7: FALSE | X7: FALSE | AA7: FALSE | AD7: FALSE | AE7: FALSE | AF7: FALSE | AG7: FALSE | AH7: FALSE | AI7: FALSE | AL7: FALSE | AO7: FALSE | AP7: FALSE | AQ7: FALSE | AR7: FALSE | AS7: FALSE | AT7: FALSE | AW7: FALSE | AZ7: FALSE | BA7: FALSE | BB7: FALSE | BC7: FALSE | BD7: FALSE | BE7: FALSE | BH7: FALSE | BK7: FALSE | BL7: FALSE | BM7: FALSE | BN7: FALSE | BO7: FALSE | BP7: FALSE | BS7: FALSE | BV7: FALSE | BW7: FALSE | BX7: FALSE | BY7: FALSE | BZ7: FALSE | CA7: FALSE | CD7: FALSE | CG7: FALSE | CH7: FALSE | CI7: FALSE | CJ7: FALSE | CK7: FALSE | CL7: FALSE | CO7: FALSE | CR7: FALSE | CS7: FALSE | CT7: FALSE | CU7: FALSE | CV7: FALSE | CW7: FALSE | CZ7: FALSE | DC7: FALSE | DD7: FALSE | DE7: FALSE | DF7: FALSE | DG7: FALSE | DH7: FALSE | DK7: FALSE | DN7: FALSE | DO7: FALSE | DP7: FALSE | DQ7: FALSE | DR7: FALSE | DS7: FALSE
A8: AGRICULTURE FORESTRY AND FISHERY | B8: AGRICULTURAL SERVICES | C8: CACAO FARM TECHNCIAN | D8: NURSERY OPERATION & MANAGEMENT LAND PREPRATION PLANTING AND SEEDLINGS PLANT CARE & MAINTENANCE HARVEST / POST HARVEST ACTIVITIES | E8: CACAO PRODUCTION LEVEL II | F8: With CS | G8: HIGH | H8: TRUE | I8: TRUE | J8: TRUE | K8: FALSE | L8: FALSE | M8: TRUE | N8: 1.25 | O8: HIGH | P8: TRUE | Q8: REGION_VII|CEBU|Cebu City, District 1|AGRICULTURE FORESTRY AND FISHERY|AGRICULTURAL SERVICES|COCONUT FARM TECHNICIAN||COCONUT PRODUCTION LEVEL II||With CS|HIGH | S8: FALSE | T8: FALSE | U8: FALSE | V8: FALSE | W8: FALSE | X8: FALSE | AA8: FALSE | AD8: FALSE | AE8: FALSE | AF8: FALSE | AG8: FALSE | AH8: FALSE | AI8: FALSE | AL8: FALSE | AO8: FALSE | AP8: FALSE | AQ8: FALSE | AR8: FALSE | AS8: FALSE | AT8: FALSE | AW8: FALSE | AZ8: FALSE | BA8: FALSE | BB8: FALSE | BC8: FALSE | BD8: FALSE | BE8: FALSE | BH8: FALSE | BK8: FALSE | BL8: FALSE | BM8: FALSE | BN8: FALSE | BO8: FALSE | BP8: FALSE | BS8: FALSE | BV8: FALSE | BW8: FALSE | BX8: FALSE | BY8: FALSE | BZ8: FALSE | CA8: FALSE | CD8: FALSE | CG8: FALSE | CH8: FALSE | CI8: FALSE | CJ8: FALSE | CK8: FALSE | CL8: FALSE | CO8: FALSE | CR8: FALSE | CS8: FALSE | CT8: FALSE | CU8: FALSE | CV8: FALSE | CW8: FALSE | CZ8: FALSE | DC8: FALSE | DD8: FALSE | DE8: FALSE | DF8: FALSE | DG8: FALSE | DH8: FALSE | DK8: FALSE | DN8: FALSE | DO8: FALSE | DP8: FALSE | DQ8: FALSE | DR8: FALSE | DS8: FALSE
A9: AGRICULTURE FORESTRY AND FISHERY | B9: AGRICULTURAL SERVICES | C9: COCONUT FARM TECHNICIAN | D9: NURSERY DEVELOPMENT & MANAGEMENT LAND PREPARATION PLANT COCO SEEDLINGS PLANT CARE & MAINTENANCE HARVEST & POST HARVEST ACTIVITIES | E9: COCONUT PRODUCTION LEVEL II | F9: With CS | G9: HIGH | H9: TRUE | I9: TRUE | J9: TRUE | K9: TRUE | L9: FALSE | M9: FALSE | N9: 2.25 | O9: LOW | P9: TRUE | Q9: REGION_VII|CEBU|Cebu City, District 1|AGRICULTURE FORESTRY AND FISHERY|ANIMAL PRODUCTION|DAIRY RAISER||ANIMAL PRODUCTION (RUMINANTS) NC II||With TR|LOW | S9: TRUE | T9: TRUE | U9: TRUE | V9: TRUE | W9: FALSE | X9: FALSE | Y9: 2.25 | Z9: LOW | AA9: TRUE | AB9: REGION_VII|CEBU|Cebu City, District 2|AGRICULTURE FORESTRY AND FISHERY|ANIMAL PRODUCTION|DAIRY RAISER||ANIMAL PRODUCTION (RUMINANTS) NC II||With TR|LOW | AD9: TRUE | AE9: TRUE | AF9: TRUE | AG9: TRUE | AH9: FALSE | AI9: FALSE | AJ9: 2.25 | AK9: LOW | AL9: TRUE | AM9: REGION_VII|CEBU|Cebu, District 1|AGRICULTURE FORESTRY AND FISHERY|ANIMAL PRODUCTION|DAIRY RAISER||ANIMAL PRODUCTION (RUMINANTS) NC II||With TR|LOW | AO9: TRUE | AP9: TRUE | AQ9: TRUE | AR9: TRUE | AS9: FALSE | AT9: FALSE | AU9: 2.25 | AV9: LOW | AW9: TRUE | AX9: REGION_VII|CEBU|Cebu, District 2|AGRICULTURE FORESTRY AND FISHERY|ANIMAL PRODUCTION|DAIRY RAISER||ANIMAL PRODUCTION (RUMINANTS) NC II||With TR|LOW | AZ9: TRUE | BA9: TRUE | BB9: TRUE | BC9: FALSE | BD9: FALSE | BE9: TRUE | BF9: 1.25 | BG9: HIGH | BH9: TRUE | BI9: REGION_VII|CEBU|Cebu, District 3|AGRICULTURE FORESTRY AND FISHERY|ANIMAL PRODUCTION|DAIRY RAISER||ANIMAL PRODUCTION (RUMINANTS) NC II||With TR|HIGH | BK9: TRUE | BL9: TRUE | BM9: TRUE | BN9: TRUE | BO9: FALSE | BP9: FALSE | BQ9: 2.25 | BR9: LOW | BS9: TRUE | BT9: REGION_VII|CEBU|Cebu, District 4|AGRICULTURE FORESTRY AND FISHERY|ANIMAL PRODUCTION|DAIRY RAISER||ANIMAL PRODUCTION (RUMINANTS) NC II||With TR|LOW | BV9: TRUE | BW9: TRUE | BX9: TRUE | BY9: TRUE | BZ9: FALSE | CA9: FALSE | CB9: 2.25 | CC9: LOW | CD9: TRUE | CE9: REGION_VII|CEBU|Cebu, District 5|AGRICULTURE FORESTRY AND FISHERY|ANIMAL PRODUCTION|DAIRY RAISER||ANIMAL PRODUCTION (RUMINANTS) NC II||With TR|LOW | CG9: TRUE | CH9: TRUE | CI9: TRUE | CJ9: TRUE | CK9: FALSE | CL9: FALSE | CM9: 2.25 | CN9: LOW | CO9: TRUE | CP9: REGION_VII|CEBU|Cebu, District 6|AGRICULTURE FORESTRY AND FISHERY|ANIMAL PRODUCTION|DAIRY RAISER||ANIMAL PRODUCTION (RUMINANTS) NC II||With TR|LOW | CR9: TRUE | CS9: TRUE | CT9: TRUE | CU9: TRUE | CV9: FALSE | CW9: FALSE | CX9: 2.25 | CY9: LOW | CZ9: TRUE | DA9: REGION_VII|CEBU|Cebu, District 7|AGRICULTURE FORESTRY AND FISHERY|ANIMAL PRODUCTION|DAIRY RAISER||ANIMAL PRODUCTION (RUMINANTS) NC II||With TR|LOW | DC9: TRUE | DD9: TRUE | DE9: TRUE | DF9: TRUE | DG9: FALSE | DH9: FALSE | DI9: 2.25 | DJ9: LOW | DK9: TRUE | DL9: REGION_VII|CEBU|Lapu-Lapu City, Lone District|AGRICULTURE FORESTRY AND FISHERY|ANIMAL PRODUCTION|DAIRY RAISER||ANIMAL PRODUCTION (RUMINANTS) NC II||With TR|LOW | DN9: TRUE | DO9: TRUE | DP9: TRUE | DQ9: TRUE | DR9: FALSE | DS9: FALSE | DT9: 2.25 | DU9: LOW
