Workbook

Sheet Read Me
A1: TVET Landscape EDA & Leads: NCR & Region IV-A (CALABARZON)
A2: Source: NCR4A_TVET.xlsx (TESDA registry extract). JF + Angela
A5: WHAT THIS DATASET IS
A6: Grain | B6: One row = institution x city x qualification x role (training and/or assessment).
A7: Roles | B7: Is_Development=1: delivers training (drives Enrolled, Graduates). Is_Assessment=1: accredited assessment venue (drives Assessed, Certified). A row can be both.
A8: Coverage | B8: 2 regions, 1,085 unique institutions, 155 qualifications, 3,327 records after cleaning.
A10: DATA CLEANING APPLIED
A11: Duplicates removed | B11: 738 exact full-row duplicates dropped (mostly assessment rows double-listed in the export). 4,065 raw rows -> 3,327 clean.
A12: Construction flag | B12: Built-environment trades flagged: SMAW/GMAW/GTAW/FCAW welding, Electrical Installation, Masonry, Carpentry, Plumbing, Tile Setting, Heavy Equipment Operation, Scaffolding, Pipefitting, Reinforcing Steel, Rigging, Formwork. Automotive painting excluded (vehicle, not building).
A14: HOW CENTRES ARE RANKED
A15: Primary metric | B15: Enrolled = training throughput (scale of the teaching business).
A16: Quality signals | B16: Grad Rate = Graduates / Enrolled. Cert Rate = Certified / Assessed. Both can exceed 100% because a cohort graduating/certifying this period may have enrolled earlier, and assessment includes walk-in RPL candidates.
A18: KEY TAKEAWAYS
A19: 1 | B19: The market splits into two businesses: training (Enrolled/Graduates) and assessment/certification (Assessed/Certified). Many high-volume players are assessment-heavy, which is more asset-light.
A20: 2 | B20: NCR leaders skew to BPO-adjacent and service trades (call center, computer servicing, caregiving, food). 4A leaders skew to manufacturing-linked and trade skills.
A21: 3 | B21: Construction trades = 15.8% of all training enrolment, but certification volume (72.5k) far exceeds training enrolment (30.6k): the trades assessment/RPL business is larger than the training business.
A22: 4 | B22: Welding (SMAW I+II) and Electrical Installation are the deepest construction pools by both demand and number of providers (130+ centres each), i.e. competitive. Heavy Equipment, Scaffolding and Plumbing are thinner provider markets with high certification pull.

Sheet Top Centers - NCR
A1: Top TVET Centers for NCR | C1: Filter
A2: 546 institutions. Ranked by training Enrolled. Rates shown as formulas (recompute live). | C2: =>3 Quals | E2: =>100 graduates | H2: =>5 trainers
A4: Rank | B4: Institution | C4: Quals | D4: Enrolled | E4: Graduates | F4: Assessed | G4: Certified | H4: Trainers | I4: Grad Rate | J4: Cert Rate | K4: 1 | L4: Primary Research Notes (JF Inputs) | M4: Updated FB in the Past Year | N4: Congratulate their Graduates of the Current Year? | O4: Updated Google Maps | P4: Responded to Student Inquiry? | Q4: Website? | R4: Website Link | S4: Decision | T4: First Name | U4: Last Name | V4: Title | W4: Email of Contact | X4: Has a LMS | Y4: When is next course starting | Z4: How much is it? | AA4: Can I get scholarship? | AB4: How do I apply? | AC4: 2 | AD4: Phone number contact | AE4: Email Contact | AF4: 3 | AG4: Number of Yes | AH4: Number of Institutions that have At Least 3 Yes
A5: 1 | B5: PHILIPPINE CALL CENTER INSTITUTE INC. | C5: 3 | D5: 2741 | E5: 3191 | F5: 0 | G5: 0 | H5: 20 | I5: =IF(D5=0,"-",E5/D5) -> 1.1641737 | J5: =IF(F5=0,"-",G5/F5) -> - | K5: 1 | L5: Facebook page, last update 2024. Called both numbers, no response. | M5: No | N5: No | O5: No | P5: No | Q5: No | AG5: {=SUMPRODUCT(--(M5:Q5="YES"))} -> 0 | AH5: =COUNTIF($AG$5:AG5, ">=3") -> 0
A6: 2 | B6: TESDA Women's Center | C6: 18 | D6: 2422 | E6: 2491 | F6: 0 | G6: 0 | H6: 25 | I6: =IF(D6=0,"-",E6/D6) -> 1.0284889 | J6: =IF(F6=0,"-",G6/F6) -> - | K6: 1 | L6: Has a webpage and Facebook page. | M6: Yes | N6: Yes | O6: Yes | P6: Yes | Q6: Yes | R6: https://twc.tesda.gov.ph/ | S6: Yes | T6: Gerrelen | U6: Balbin | V6: Senior TESD Specialist, Unit Head (Training Management Unit) | W6: gdbalbin@tesda.gov.ph | X6: Yes | Y6: N/A | Z6: N/A | AA6: N/A | AB6: N/A | AD6: (02) 8817-2650 / (02) 8817-2651 | AE6: twc@tesda.gov.ph | AG6: {=SUMPRODUCT(--(M6:Q6="YES"))} -> 5 | AH6: =COUNTIF($AG$5:AG6, ">=3") -> 1
A7: 3 | B7: UNITED INTERNATIONAL MARITIME TRAINING AND ASSESSMENT CENTER INC. | C7: 7 | D7: 2126 | E7: 325 | F7: 5627 | G7: 5549 | H7: 16 | I7: =IF(D7=0,"-",E7/D7) -> 0.15286924 | J7: =IF(F7=0,"-",G7/F7) -> 0.98613826 | K7: 1 | L7: Facebook has student photos, but the phone number given does not work. They have a website. There, the number does work. Wala pong bread and pastry. No TESDA scholarship. Ships NC III for 27 days for 1495 USD. They ask for Form 137, 138,and Transcript of Records. Pwede mag apply ng online. Sales@unpc.com.ph. | M7: No | N7: No | O7: Yes | P7: Yes | Q7: Yes | R7: https://www.umtc.com.ph/ | S7: Yes | Y7: None (Waiting for full batch) | Z7: 1495 USD | AA7: No (No TESDA scholarship currently) | AB7: Online (Email the Requirements) | AG7: {=SUMPRODUCT(--(M7:Q7="YES"))} -> 3 | AH7: =COUNTIF($AG$5:AG7, ">=3") -> 2
A8: 4 | B8: CARENET HEALTHCARE INSTITUTE INC. | C8: 3 | D8: 2114 | E8: 2193 | F8: 1221 | G8: 1205 | H8: 19 | I8: =IF(D8=0,"-",E8/D8) -> 1.0373699 | J8: =IF(F8=0,"-",G8/F8) -> 0.98689599 | K8: 1 | L8: Facebook page is actually an account, not a page. | M8: No | N8: No | O8: Yes | P8: No | Q8: No | AG8: {=SUMPRODUCT(--(M8:Q8="YES"))} -> 1 | AH8: =COUNTIF($AG$5:AG8, ">=3") -> 2
A9: 5 | B9: TECHVOC SKILLS INC. | C9: 4 | D9: 2028 | E9: 1917 | F9: 817 | G9: 812 | H9: 12 | I9: =IF(D9=0,"-",E9/D9) -> 0.94526627 | J9: =IF(F9=0,"-",G9/F9) -> 0.99388005 | K9: 1 | L9: They have a message channel that just posts whenver there is a new opening or program. They responded very quickly when I messaged them on Facebook. They even have a Tiktok with 2000 followers. | M9: Yes | N9: Yes | O9: Yes | P9: Yes | Q9: No | S9: Yes | T9: Melody | U9: Cruz | V9: School Head | Y9: N/A | Z9: N/A | AA9: N/A | AB9: N/A | AD9: N/A | AE9: techvoc_skills.incorporated@yahoo.com | AG9: {=SUMPRODUCT(--(M9:Q9="YES"))} -> 4 | AH9: =COUNTIF($AG$5:AG9, ">=3") -> 3
A10: 6 | B10: PHILIPPINE SCHOOL FOR TECHNOLOGY DEVELOPMENT AND INNOVATION INC. | C10: 12 | D10: 1831 | E10: 1972 | F10: 1666 | G10: 1658 | H10: 9 | I10: =IF(D10=0,"-",E10/D10) -> 1.0770071 | J10: =IF(F10=0,"-",G10/F10) -> 0.99519808 | K10: 1 | L10: Facebook was updated last April 14. No phone number and email is provided. | M10: Yes | N10: Yes | O10: Yes | P10: No | Q10: No | AG10: {=SUMPRODUCT(--(M10:Q10="YES"))} -> 3 | AH10: =COUNTIF($AG$5:AG10, ">=3") -> 4
A11: 7 | B11: UNO CAREGIVER AND DOMESTIC MNGT TRAINING, INC. | C11: 13 | D11: 1722 | E11: 1703 | F11: 1978 | G11: 1935 | H11: 27 | I11: =IF(D11=0,"-",E11/D11) -> 0.98896632 | J11: =IF(F11=0,"-",G11/F11) -> 0.97826087 | L11: They have a Tiktok. I tried calling them thrice. They never picked up. For the Caregiving NC II, there is no tentative. Php 26,000 in installment basis. Merong TESDA scholarship pero walang starting date. Drop by. | M11: Yes | N11: Yes | O11: Yes | P11: Yes | Q11: No | S11: Yes | Y11: None (Pending TESDA funding) | Z11: Php 26,000 | AA11: Yes (Waitlist) | AB11: Onsite (Walk-in application) | AD11: (02) 8687 6250 | AE11: uno.training88@gmail.com | AG11: {=SUMPRODUCT(--(M11:Q11="YES"))} -> 4 | AH11: =COUNTIF($AG$5:AG11, ">=3") -> 5
A12: 8 | B12: PSAA INTERNATIONAL ACADEMY INC. | C12: 16 | D12: 1476 | E12: 1169 | F12: 3929 | G12: 3894 | H12: 20 | I12: =IF(D12=0,"-",E12/D12) -> 0.79200542 | J12: =IF(F12=0,"-",G12/F12) -> 0.99109188 | K12: 1 | L12: Has a Facebook page but webpage does not work anymore. Called, no response. | M12: Yes | N12: Yes | O12: Yes | P12: Yes | Q12: Yes | R12: https://psaamanilatvet.com/ | S12: Yes | T12: Riza | U12: Sorima-Matias | V12: Training Director | W12: N/A | Y12: N/A | Z12: N/A | AA12: N/A | AB12: N/A | AD12: 0920 859 3752 | AE12: psaamanila@hotmail.com | AG12: {=SUMPRODUCT(--(M12:Q12="YES"))} -> 5 | AH12: =COUNTIF($AG$5:AG12, ">=3") -> 6
A13: 9 | B13: POWER LINK CENTER FOR ADVANCED TECHNICAL SKILLS DEVELOPMENT INC. | C13: 5 | D13: 1468 | E13: 1214 | F13: 0 | G13: 0 | H13: 19 | I13: =IF(D13=0,"-",E13/D13) -> 0.82697548 | J13: =IF(F13=0,"-",G13/F13) -> - | K13: 1 | L13: Facebook page was updated last June 19. There is Barista, Cookery. They offer scholarships and the such, but there is no voucher right now. They need 15 to 20 candidates. It is unsure when it will start. Fill up an application. Voucher for the scholarship. | M13: Yes | N13: No | O13: Yes | P13: Yes | Q13: Yes | R13: https://powerlink3.wixsite.com/powerlinkgroup | S13: 3rd Priority | Y13: None (Waiting for full batch) | Z13: None (Pending TESDA funding) | AA13: Yes (Waitlist) | AB13: Onsite (Walk-in application) | AD13: 0969 306 4698 | AE13: powerlink0615@gmail.com | AG13: {=SUMPRODUCT(--(M13:Q13="YES"))} -> 4 | AH13: =COUNTIF($AG$5:AG13, ">=3") -> 7
A14: 11 | B14: MAGSAYSAY CENTER FOR HOSPITALITY AND CULINARY ARTS, INC. | C14: 4 | D14: 1384 | E14: 1675 | F14: 0 | G14: 0 | H14: 15 | I14: =IF(D14=0,"-",E14/D14) -> 1.2102601 | J14: =IF(F14=0,"-",G14/F14) -> - | K14: 1 | L14: Already a partner, no need to review | M14: Yes | N14: Yes | O14: Yes | P14: Yes | Q14: No | S14: N/A | Y14: N/A | Z14: N/A | AA14: N/A | AB14: N/A | AG14: {=SUMPRODUCT(--(M14:Q14="YES"))} -> 4 | AH14: =COUNTIF($AG$5:AG14, ">=3") -> 8
A15: 12 | B15: RMC EAGLES TRAINING AND ASSESSMENT CENTER INC. | C15: 3 | D15: 1377 | E15: 1318 | F15: 1012 | G15: 1010 | H15: 6 | I15: =IF(D15=0,"-",E15/D15) -> 0.95715323 | J15: =IF(F15=0,"-",G15/F15) -> 0.99802372 | L15: Facebook page was updated last June 11. There is registration link in the recent Facebook post to register. They are waiting for the notice to proceed from TESDA so that they can start orientation. For the regular, there is no assessment for the cyber threat monitoring NC I. For the regular, it is 16 days. The price was not said to me, and when they said to look at the registration form, it doesn't even say the price either. | M15: Yes | N15: Yes | O15: Yes | P15: Yes | Q15: No | Y15: None (Pending TESDA funding) | Z15: None (For scheduling) | AA15: Yes (Waitlist) | AB15: FB (Use registration link) | AD15: 0905 418 0148 | AE15: rmceagles3@gmail.com | AG15: {=SUMPRODUCT(--(M15:Q15="YES"))} -> 4 | AH15: =COUNTIF($AG$5:AG15, ">=3") -> 9
A16: 13 | B16: ASIANTOUCH INTERNATIONAL TRAINING INSTITUTE, INC. | C16: 5 | D16: 1369 | E16: 1006 | F16: 1294 | G16: 1289 | H16: 12 | I16: =IF(D16=0,"-",E16/D16) -> 0.73484295 | J16: =IF(F16=0,"-",G16/F16) -> 0.99613601 | K16: 1 | L16: Facebook page was last updated in 2025, but the phone number does not work. | M16: No | N16: No | O16: Yes | P16: No | Q16: No | AG16: {=SUMPRODUCT(--(M16:Q16="YES"))} -> 1 | AH16: =COUNTIF($AG$5:AG16, ">=3") -> 9
A17: 14 | B17: NATIONAL INSTITUTE FOR TECHNICAL AND VOCATIONAL CAREERS, INC. | C17: 3 | D17: 1311 | E17: 1374 | F17: 0 | G17: 0 | H17: 11 | I17: =IF(D17=0,"-",E17/D17) -> 1.0480549 | J17: =IF(F17=0,"-",G17/F17) -> - | K17: 1 | L17: Facebook was updated last 2019, and the phone numbers given do not work. | M17: No | N17: No | O17: No | P17: No | Q17: No | AG17: {=SUMPRODUCT(--(M17:Q17="YES"))} -> 0 | AH17: =COUNTIF($AG$5:AG17, ">=3") -> 9
A18: 16 | B18: PHILIPPINE ACADEMY FOR TECHNICAL AND VOCATIONAL SKILLS, INC. | C18: 4 | D18: 1231 | E18: 1026 | F18: 0 | G18: 0 | H18: 13 | I18: =IF(D18=0,"-",E18/D18) -> 0.83346872 | J18: =IF(F18=0,"-",G18/F18) -> - | K18: 1 | L18: Their landline number is not even updated. | M18: No | N18: No | O18: Yes | P18: No | Q18: No | AG18: {=SUMPRODUCT(--(M18:Q18="YES"))} -> 1 | AH18: =COUNTIF($AG$5:AG18, ">=3") -> 9
A19: 17 | B19: CAPT. WILIJADO P. ABUID FOUNDATION, INC. | C19: 4 | D19: 1227 | E19: 345 | F19: 4261 | G19: 4254 | H19: 6 | I19: =IF(D19=0,"-",E19/D19) -> 0.28117359 | J19: =IF(F19=0,"-",G19/F19) -> 0.99835719 | K19: 1 | AG19: {=SUMPRODUCT(--(M19:Q19="YES"))} -> 0 | AH19: =COUNTIF($AG$5:AG19, ">=3") -> 9
A20: 19 | B20: B AND B ACADEMY FOR SKILLS TRAINING AND ASSESSMENT INC. | C20: 7 | D20: 1178 | E20: 1446 | F20: 1372 | G20: 1334 | H20: 9 | I20: =IF(D20=0,"-",E20/D20) -> 1.2275042 | J20: =IF(F20=0,"-",G20/F20) -> 0.97230321 | K20: 1 | L20: Facebook was updated last June 23. | M20: Yes | N20: Yes | O20: Yes | P20: No | Q20: No | AD20: 0956 432 9868 | AE20: bbacademypasig@gmail.com | AG20: {=SUMPRODUCT(--(M20:Q20="YES"))} -> 3 | AH20: =COUNTIF($AG$5:AG20, ">=3") -> 10
A21: 21 | B21: MILESTONE TECHNOLOGICAL INSTITUTE, INC. | C21: 5 | D21: 1089 | E21: 970 | F21: 0 | G21: 0 | H21: 14 | I21: =IF(D21=0,"-",E21/D21) -> 0.89072544 | J21: =IF(F21=0,"-",G21/F21) -> - | K21: 1 | L21: They have a wordpress. However, when I asked on the Java programming course, they said that it's not currently available since there are currently no scholarships. | M21: Yes | N21: Yes | O21: Yes | P21: Yes | Q21: Yes | R21: https://mtivalenzuela.wordpress.com/?fbclid=IwY2xjawS79edleHRuA2FlbQIxMABicmlkETF5V0pSQ3Y2RzltTzJOcnVnc3J0YwZhcHBfaWQQMjIyMDM5MTc4ODIwMDg5MgABHt0O_Y9j0jQTXKv1oxd1Fu3dQssYM3hmiiWsYsvMSxal3hLrXq4TLgvaa0DH_aem_LJ0TYP3wfSv9mKSm77KLSQ | S21: Yes | X21: Yes | Y21: None (Pending TESDA funding) | Z21: None (Pending TESDA funding) | AA21: No (No TESDA scholarship currently) | AB21: Online (WordPress site for inquiries) | AD21: (02) 8553-8078 | AE21: mti.developer.ph@gmail.com | AG21: {=SUMPRODUCT(--(M21:Q21="YES"))} -> 5 | AH21: =COUNTIF($AG$5:AG21, ">=3") -> 11
A22: 22 | B22: REGIONAL TRAINING CENTER - NCR | C22: 12 | D22: 1059 | E22: 1438 | F22: 1405 | G22: 1346 | H22: 12 | I22: =IF(D22=0,"-",E22/D22) -> 1.3578848 | J22: =IF(F22=0,"-",G22/F22) -> 0.95800712 | K22: 1 | L22: The regional training center does not have its own Facebook page for developmental acitivites. It is combined with the main Facebook page. However, their website does tell on how to apply. | M22: Yes | N22: No | O22: Yes | P22: Yes | Q22: Yes | R22: https://rtcncr.com/ | S22: Yes | T22: Jerry | U22: Taroy | V22: Supervising TESD Specialist, Head – Training, Research, Assessment and Extension Unit (TREAU) | Y22: N/A | Z22: N/A | AA22: N/A | AB22: N/A | AD22: 0968 852 8204 | AE22: rtcncr@tesda.gov.ph | AG22: {=SUMPRODUCT(--(M22:Q22="YES"))} -> 4 | AH22: =COUNTIF($AG$5:AG22, ">=3") -> 12
A23: 23 | B23: QTEK TRAINING AND ASSESSMENT CENTER INC. | C23: 5 | D23: 1048 | E23: 906 | F23: 492 | G23: 487 | H23: 11 | I23: =IF(D23=0,"-",E23/D23) -> 0.86450382 | J23: =IF(F23=0,"-",G23/F23) -> 0.9898374 | K23: 1 | L23: Facebook was updated last July 3. They accepted my call, but they ended it when I asked about scholarships. | M23: Yes | N23: Yes | O23: Yes | P23: Yes | Q23: Yes | R23: http://www.qtekcenter.com/site/page/content | S23: 3rd Priority (For the courses, it is difficult to work with construction) | Y23: N/A | Z23: N/A | AA23: N/A | AB23: N/A | AD23: 0917 300 5827 | AE23: mcobinayug@qtekcenter.com | AG23: {=SUMPRODUCT(--(M23:Q23="YES"))} -> 5 | AH23: =COUNTIF($AG$5:AG23, ">=3") -> 13
A24: 25 | B24: MECHATRONICS TECHNOLOGIES CORP. | C24: 9 | D24: 992 | E24: 957 | F24: 1187 | G24: 1149 | H24: 11 | I24: =IF(D24=0,"-",E24/D24) -> 0.96471774 | J24: =IF(F24=0,"-",G24/F24) -> 0.96798652 | K24: 1 | L24: Facebook was updated last June 25. They also have a website. The landline number does not work, but the phone number does. | M24: Yes | N24: Yes | O24: Yes | P24: Yes | Q24: Yes | R24: https://www.mechatronicstechnologiescorp.com/?fbclid=IwY2xjawS7-FRleHRuA2FlbQIxMABicmlkETF5V0pSQ3Y2RzltTzJOcnVnc3J0YwZhcHBfaWQQMjIyMDM5MTc4ODIwMDg5MgABHgOEcKonPcyX34lk0-T79l9To5TiXmsiLxDTW94WhhoSFaJ87Uav6eHa-KJj_aem_4cikKUbg9_O5qQenqa8UCg | S24: Yes | T24: Xerxes Gamaliel | U24: Itao | V24: Managing Director | W24: N/A | X24: No | Y24: N/A | Z24: N/A | AA24: N/A | AB24: N/A | AD24: 0975 293 7418 | AE24: mechatronicstechnologiescorp@yahoo.com | AG24: {=SUMPRODUCT(--(M24:Q24="YES"))} -> 5 | AH24: =COUNTIF($AG$5:AG24, ">=3") -> 14
A25: 26 | B25: DON BOSCO YOUTH CENTER-TONDO INC. | C25: 9 | D25: 991 | E25: 1117 | F25: 0 | G25: 0 | H25: 11 | I25: =IF(D25=0,"-",E25/D25) -> 1.1271443 | J25: =IF(F25=0,"-",G25/F25) -> - | K25: 1 | L25: Facebook was updated last June 30. They also have a nice website. | M25: Yes | N25: Yes | O25: Yes | P25: No | Q25: Yes | R25: https://www.donboscoyouthcenter.online/ | S25: N/A | AD25: 0949 103 8045 | AE25: donboscoyouthcentertvet@gmail.com | AG25: {=SUMPRODUCT(--(M25:Q25="YES"))} -> 4 | AH25: =COUNTIF($AG$5:AG25, ">=3") -> 15
A26: 27 | B26: SOCIO INTER SKILLS TRAINING ACADEMY (SISTA) INC. | C26: 4 | D26: 988 | E26: 841 | F26: 802 | G26: 801 | H26: 7 | I26: =IF(D26=0,"-",E26/D26) -> 0.85121457 | J26: =IF(F26=0,"-",G26/F26) -> 0.99875312 | K26: 1 | L26: Facebook page was updated last July 2. | M26: Yes | N26: Yes | O26: Yes | P26: No | Q26: Yes | R26: https://www.sista.com.ph/ | S26: Yes | AD26: 0962 246 4473 | AE26: sociointerskills@gmail.com | AG26: {=SUMPRODUCT(--(M26:Q26="YES"))} -> 4 | AH26: =COUNTIF($AG$5:AG26, ">=3") -> 16
A27: 28 | B27: Top Choice Training Institute and Assessment Center | C27: 3 | D27: 963 | E27: 897 | F27: 0 | G27: 0 | H27: 10 | I27: =IF(D27=0,"-",E27/D27) -> 0.93146417 | J27: =IF(F27=0,"-",G27/F27) -> - | K27: 1 | L27: Facebook was updated lasy July 3. The website provided did not work. For the phone call, they were very insightful because they even said on how to actually register. They asked also for my name and said that I can register in the center or message more in WhatsApp. | M27: Yes | N27: No | O27: Yes | P27: Yes | Q27: No | Y27: N/A | Z27: N/A | AA27: N/A | AB27: Onsite / WhatsApp (Register at center or message for assistance) | AD27: 0918 927 1980 | AE27: topchoicetraining24@gmail.com | AG27: {=SUMPRODUCT(--(M27:Q27="YES"))} -> 3 | AH27: =COUNTIF($AG$5:AG27, ">=3") -> 17
A28: 29 | B28: BOWLINE TRAINING & ASSESSMENT CENTER, INC. | C28: 3 | D28: 900 | E28: 731 | F28: 0 | G28: 0 | H28: 6 | I28: =IF(D28=0,"-",E28/D28) -> 0.81222222 | J28: =IF(F28=0,"-",G28/F28) -> - | K28: 1 | AG28: {=SUMPRODUCT(--(M28:Q28="YES"))} -> 0 | AH28: =COUNTIF($AG$5:AG28, ">=3") -> 17
A29: 30 | B29: ARAYA SKILLS DEVELOPMENT INSTITUTE, CORP. | C29: 3 | D29: 900 | E29: 668 | F29: 0 | G29: 0 | H29: 6 | I29: =IF(D29=0,"-",E29/D29) -> 0.74222222 | J29: =IF(F29=0,"-",G29/F29) -> - | K29: 1 | AG29: {=SUMPRODUCT(--(M29:Q29="YES"))} -> 0 | AH29: =COUNTIF($AG$5:AG29, ">=3") -> 17
A30: 31 | B30: Quezon City Lingkod Bayan Skills Development Center | C30: 6 | D30: 882 | E30: 868 | F30: 0 | G30: 0 | H30: 10 | I30: =IF(D30=0,"-",E30/D30) -> 0.98412698 | J30: =IF(F30=0,"-",G30/F30) -> - | K30: 1 | L30: Their Facebook is not even the first result. It's called Tesda Ncr Qclbsdc, so it's just a lost list of acronyms huhuhuhu. Also, calling is not an option. They prefer if you just go there. As a commenter said, "Mas mabilis ang transaction sa QC Lingkod Bayan Center kung personal kayo pupunta sa office nila" | M30: No | N30: No | O30: Yes | P30: No | Q30: No | AG30: {=SUMPRODUCT(--(M30:Q30="YES"))} -> 1 | AH30: =COUNTIF($AG$5:AG30, ">=3") -> 17
A31: 32 | B31: HORIZONS INSTITUTE OF TECHNOLOGY CORPORATION | C31: 8 | D31: 859 | E31: 895 | F31: 1770 | G31: 1756 | H31: 7 | I31: =IF(D31=0,"-",E31/D31) -> 1.0419092 | J31: =IF(F31=0,"-",G31/F31) -> 0.9920904 | K31: 1 | L31: Facebook page was updated last July 7. They did not accept my call. | M31: Yes | N31: Yes | O31: Yes | P31: No | Q31: No | AD31: 0968 776 0024 | AE31: hitacc.am@gmail.com | AG31: {=SUMPRODUCT(--(M31:Q31="YES"))} -> 3 | AH31: =COUNTIF($AG$5:AG31, ">=3") -> 18
A32: 34 | B32: SLDM COLLEGES OF QUEZON CITY, INC. | C32: 5 | D32: 833 | E32: 844 | F32: 0 | G32: 0 | H32: 8 | I32: =IF(D32=0,"-",E32/D32) -> 1.0132053 | J32: =IF(F32=0,"-",G32/F32) -> - | K32: 1 | L32: Facebook was last updated June 30. They actually had to transfer me. To register, we would have to go to Facebook of the training and assessment center of lakewood school of alabang. There would be a link that gives the registration link and they would give me a list of requirements. Aside of the list requirements, certificate of indigency (no need for medical since this is replacement of the medical). | M32: Yes | N32: Yes | O32: Yes | P32: No | Q32: No | AD32: 0967 375 4257 | AE32: sldmcollegesofqc2014@gmail.com | AG32: {=SUMPRODUCT(--(M32:Q32="YES"))} -> 3 | AH32: =COUNTIF($AG$5:AG32, ">=3") -> 19
A33: 35 | B33: RIGHT FOCUS TRAINING CENTER, INC. | C33: 6 | D33: 821 | E33: 764 | F33: 547 | G33: 543 | H33: 8 | I33: =IF(D33=0,"-",E33/D33) -> 0.93057247 | J33: =IF(F33=0,"-",G33/F33) -> 0.99268739 | K33: 1 | L33: Facebook was last updated June 25. They also have an Instagram where they posted last June 11. | M33: Yes | N33: Yes | O33: Yes | P33: No | Q33: Yes | R33: https://www.rightfocustrainingcenter.com/ | S33: Yes | AD33: 0981 792 9222 | AE33: rftc.socmed@gmail.com | AG33: {=SUMPRODUCT(--(M33:Q33="YES"))} -> 4 | AH33: =COUNTIF($AG$5:AG33, ">=3") -> 20
A34: 36 | B34: MUNTIPARLASTAPAT DISTRICT TRAINING AND ASSESSMENT CENTER | C34: 6 | D34: 812 | E34: 1035 | F34: 1018 | G34: 976 | H34: 10 | I34: =IF(D34=0,"-",E34/D34) -> 1.2746305 | J34: =IF(F34=0,"-",G34/F34) -> 0.95874263 | K34: 1 | L34: Facebook was updated last July 2. The district training center does not have their own website, and the phone numbers given do not work. Still, I will just include a phone number for completion's sake. However, they do have a Forms to register: https://docs.google.com/forms/d/e/1FAIpQLSezk8jlUcjy0xn-x7dg1agnQHsxHzhmO0TqGaZCNuBZKQXvew/viewform | M34: Yes | N34: No | O34: Yes | P34: No | Q34: No | AD34: 0917 845 8926 | AE34: mdtac@tesda.gov.ph | AG34: {=SUMPRODUCT(--(M34:Q34="YES"))} -> 2 | AH34: =COUNTIF($AG$5:AG34, ">=3") -> 20
A35: 37 | B35: TESDA-NAVOTAAS TRAINING INSTITUTE | C35: 11 | D35: 811 | E35: 983 | F35: 791 | G35: 782 | H35: 10 | I35: =IF(D35=0,"-",E35/D35) -> 1.2120838 | J35: =IF(F35=0,"-",G35/F35) -> 0.988622 | K35: 1 | L35: Facebook was updated last May. The district's landline does not work, but I'll include it anyways. They do have a Forms: https://forms.gle/gpkjhHgY3i8MGiLy8 | M35: Yes | N35: No | O35: Yes | P35: No | Q35: No | AD35: (02) 8292-2183 | AE35: tnti@tesda.gov.ph | AG35: {=SUMPRODUCT(--(M35:Q35="YES"))} -> 2 | AH35: =COUNTIF($AG$5:AG35, ">=3") -> 20
A36: 38 | B36: TRIDENT-ASSESSMENT AND TECHNICAL TRAINING CENTER INC. | C36: 6 | D36: 788 | E36: 695 | F36: 2801 | G36: 2801 | H36: 5 | I36: =IF(D36=0,"-",E36/D36) -> 0.8819797 | J36: =IF(F36=0,"-",G36/F36) -> 1 | K36: 1 | AG36: {=SUMPRODUCT(--(M36:Q36="YES"))} -> 0 | AH36: =COUNTIF($AG$5:AG36, ">=3") -> 20
A37: 39 | B37: APLUS TECHNICAL AND VOCATIONAL SCHOOL INC. | C37: 3 | D37: 777 | E37: 727 | F37: 0 | G37: 0 | H37: 9 | I37: =IF(D37=0,"-",E37/D37) -> 0.93564994 | J37: =IF(F37=0,"-",G37/F37) -> - | K37: 1 | L37: Facebook was updated last May 14, but the post was just 'Amen!🧚‍♂️' When I called the phone number, they said that I should just go to the actual location for more questions. They did not want to answer on how to register on the phone. | M37: Yes | N37: No | O37: Yes | P37: Yes | Q37: No | Y37: N/A | Z37: N/A | AA37: N/A | AB37: Onsite (Walk-in application) | AD37: 0915 800 1270 | AE37: N/A | AG37: {=SUMPRODUCT(--(M37:Q37="YES"))} -> 3 | AH37: =COUNTIF($AG$5:AG37, ">=3") -> 21
A38: 42 | B38: GATEWAYS INSTITUTE OF SCIENCE & TECHNOLOGY, INC. (Mandaluyong) | C38: 4 | D38: 761 | E38: 719 | F38: 0 | G38: 0 | H38: 6 | I38: =IF(D38=0,"-",E38/D38) -> 0.94480946 | J38: =IF(F38=0,"-",G38/F38) -> - | K38: 1 | AG38: {=SUMPRODUCT(--(M38:Q38="YES"))} -> 0 | AH38: =COUNTIF($AG$5:AG38, ">=3") -> 21
A39: 43 | B39: APHRODITE TRAINING AND ASSESSMENT CENTER INC. | C39: 3 | D39: 757 | E39: 661 | F39: 204 | G39: 204 | H39: 6 | I39: =IF(D39=0,"-",E39/D39) -> 0.87318362 | J39: =IF(F39=0,"-",G39/F39) -> 1 | K39: 1 | AG39: {=SUMPRODUCT(--(M39:Q39="YES"))} -> 0 | AH39: =COUNTIF($AG$5:AG39, ">=3") -> 21
A40: 44 | B40: HEADSTART TRAINING CENTER CORP. | C40: 4 | D40: 751 | E40: 251 | F40: 214 | G40: 214 | H40: 9 | I40: =IF(D40=0,"-",E40/D40) -> 0.33422104 | J40: =IF(F40=0,"-",G40/F40) -> 1 | K40: 1 | L40: Facebook was last updated June 23. The number provided could not be completed at dial. | M40: Yes | N40: Yes | O40: Yes | P40: No | Q40: No | AD40: 0968 447 1790 | AE40: headstartcenter1@gmail.com | AG40: {=SUMPRODUCT(--(M40:Q40="YES"))} -> 3 | AH40: =COUNTIF($AG$5:AG40, ">=3") -> 22
A41: 48 | B41: ACADEMY ASIA SCHOOL OF TECHNOLOGY AND THE ARTS, INC. | C41: 6 | D41: 720 | E41: 644 | F41: 0 | G41: 0 | H41: 7 | I41: =IF(D41=0,"-",E41/D41) -> 0.89444444 | J41: =IF(F41=0,"-",G41/F41) -> - | K41: 1 | L41: Facebook page was updated last June 25. No TESDA courses right now. But there is a registration link in the Facebook page. We can register there so that once TESDA gives scholarship. Instead, they suggested to just enroll regularly. With tuition, they will just be assessed. The tuition will be of the Professional Certificate of Culinary Art (where it leads to the Cookery NC II) is of four months with the duration ours of 270 hours with 300 hours of OJT from 8 AM to 5 PM thrice a week. Afterwards, there is a program inclusion with local partnerships para maging OJT. For the payment, there is two options of cash payment with Php 65,000 with 10% discount. The second option is monthly payment of an initial payment of Php 25,000 (monthly of Php 10,000). | M41: Yes | N41: Yes | O41: Yes | P41: Yes | Q41: Yes | R41: http://academyasia.ph/ | S41: Yes | T41: N/A | U41: N/A | V41: N/A | W41: N/A | Y41: None (Pending TESDA funding) | Z41: ₱65,000 (Training; Professional Certificate in Culinary Art → Cookery NC II) | AA41: Yes (Waitlist) | AB41: Online (Register via FB link for updates or enroll regularly) | AD41: 0917 882 2742 | AE41: academy.asia@gmail.com | AG41: {=SUMPRODUCT(--(M41:Q41="YES"))} -> 5 | AH41: =COUNTIF($AG$5:AG41, ">=3") -> 23
...

Sheet Top Centers - 4A
A1: Top TVET Centres: 4A | C1: Filter
A2: Top TVET Centers for 4A
A3: 543 institutions. Ranked by training Enrolled. Rates shown as formulas (recompute live). | C3: =>3 Quals | E3: =>100 graduates | H3: =>5 trainers
A5: Rank | B5: Institution | C5: Quals | D5: Enrolled | E5: Graduates | F5: Assessed | G5: Certified | H5: Trainers | I5: Grad Rate | J5: Cert Rate | K5: 1 | L5: Primary Research Notes (JF Inputs) | M5: Updated FB in the Past Year | N5: Congratulate their Graduates of the Current Year? | O5: Updated Google Maps | P5: Responded to Student Inquiry? | Q5: Website? | R5: Website Link | S5: Decision | T5: 2 | U5: When is next course starting | V5: How much is it? | W5: Can I get scholarship? | X5: How do I apply? | Y5: 3 | Z5: Phone number contact | AA5: Email Contact | AB5: 4 | AC5: Number of Yes | AD5: Number of Institutions that have At Least 3 Yes
A6: 451 | B6: JACOBO Z. GONZALES MEMORIAL SCHOOL OF ARTS AND TRADES | C6: 38 | D6: 0 | E6: 0 | F6: 5399 | G6: 5191 | H6: 0 | I6: =IF(D6=0,"-",E6/D6) -> - | J6: =IF(F6=0,"-",G6/F6) -> 0.96147435 | K6: 1
A7: 463 | B7: REGIONAL TRAINING CENTER-CALABARZON | C7: 30 | D7: 0 | E7: 0 | F7: 3190 | G7: 2723 | H7: 0 | I7: =IF(D7=0,"-",E7/D7) -> - | J7: =IF(F7=0,"-",G7/F7) -> 0.85360502 | K7: 1 | AG7: =COUNTIF(P7:P21, "YES") -> 5
A8: 462 | B8: QUEZON NATIONAL AGRICULTURAL SCHOOL | C8: 20 | D8: 0 | E8: 0 | F8: 2670 | G8: 2703 | H8: 0 | I8: =IF(D8=0,"-",E8/D8) -> - | J8: =IF(F8=0,"-",G8/F8) -> 1.0123596 | K8: 1
A9: 3 | B9: ADAO LEARNING INSTITUTE INC. | C9: 5 | D9: 2146 | E9: 1945 | F9: 1403 | G9: 1363 | H9: 24 | I9: =IF(D9=0,"-",E9/D9) -> 0.90633737 | J9: =IF(F9=0,"-",G9/F9) -> 0.97148967 | L9: Scholarship available is Carpenter available on July 20 and 30. NCs for assessment can vary, but training is all scholarship provided. | M9: Yes | N9: Yes | O9: Yes | P9: Yes | Q9: No | S9: 2nd Priority | T9: 2 | U9: July 20 and 30 | V9: N/A | W9: Yes | X9: N/A | Z9: 0916 397 7290 | AA9: adaolearninginstituteinc@gmail.com | AC9: {=SUMPRODUCT(--(M9:Q9="YES"))} -> 4 | AD9: =COUNTIF($AC$7:AC9, ">=3") -> 1
A10: 2 | B10: THE BIG FIVE TRAINING AND ASSESSMENT CENTER INC. | C10: 5 | D10: 2170 | E10: 1695 | F10: 1548 | G10: 1733 | H10: 14 | I10: =IF(D10=0,"-",E10/D10) -> 0.78110599 | J10: =IF(F10=0,"-",G10/F10) -> 1.119509 | L10: As of right now, there is no scholarship given by TESDA, but there is regular training (with a training fee of Php 10_000). To enroll, we need to go to the office physically. To be able to start, they need to be fully booked, so as of right now, we just need to wait. Facebook was updated last June 30. | M10: Yes | N10: Yes | O10: Yes | P10: Yes | Q10: No | S10: 2nd Priority | T10: 2 | U10: None (Waiting for full batch) | V10: Php 10,000 (Regular training) | W10: No (No TESDA scholarship currently) | X10: Onsite (Waitlist until class is full) | Z10: 0908 655 2653 | AA10: thebigfivetraining2018@gmail.com | AC10: {=SUMPRODUCT(--(M10:Q10="YES"))} -> 4 | AD10: =COUNTIF($AC$7:AC10, ">=3") -> 2
A11: 11 | B11: Colegio de Santo Cristo De Burgos Corporation | C11: 5 | D11: 1107 | E11: 1187 | F11: 0 | G11: 0 | H11: 11 | I11: =IF(D11=0,"-",E11/D11) -> 1.0722674 | J11: =IF(F11=0,"-",G11/F11) -> - | L11: Facebook page was updated last June 23. | M11: Yes | N11: Yes | O11: Yes | P11: No | Q11: Yes | R11: https://cdscdb.edu.ph/ | S11: Yes | T11: 2 | Z11: 0917 538 1515 | AA11: colegiodesantocristodeburgos@gmail.com | AC11: {=SUMPRODUCT(--(M11:Q11="YES"))} -> 4 | AD11: =COUNTIF($AC$7:AC11, ">=3") -> 3
A12: 411 | B12: LYCEUM OF THE PHILIPPINES UNIVERSITY - BATANGAS, INC. | C12: 14 | D12: 0 | E12: 0 | F12: 2650 | G12: 2626 | H12: 0 | I12: =IF(D12=0,"-",E12/D12) -> - | J12: =IF(F12=0,"-",G12/F12) -> 0.9909434 | K12: 1
A13: 524 | B13: CSTC COLLEGE OF SCIENCES, TECHNOLOGY AND COMMUNICATIONS, INC. | C13: 14 | D13: 0 | E13: 0 | F13: 2709 | G13: 2694 | H13: 0 | I13: =IF(D13=0,"-",E13/D13) -> - | J13: =IF(F13=0,"-",G13/F13) -> 0.9944629 | K13: 1
A14: 16 | B14: RENAISSANCE SCHOOL OF SCIENCE AND TECHNOLOGY INC | C14: 11 | D14: 842 | E14: 1182 | F14: 0 | G14: 0 | H14: 17 | I14: =IF(D14=0,"-",E14/D14) -> 1.4038005 | J14: =IF(F14=0,"-",G14/F14) -> - | L14: Facebook page was updated last July 1. The phone number does not work. | M14: Yes | N14: Yes | O14: Yes | P14: No | Q14: Yes | R14: https://learnatrsst.org/home.php | S14: 2nd Priority | T14: 2 | Z14: 0919 084 0826 | AA14: renaissance.oic@gmail.com | AC14: {=SUMPRODUCT(--(M14:Q14="YES"))} -> 4 | AD14: =COUNTIF($AC$7:AC14, ">=3") -> 4
A15: 402 | B15: UNIVERSITY OF BATANGAS, INC. | C15: 12 | D15: 0 | E15: 0 | F15: 561 | G15: 560 | H15: 0 | I15: =IF(D15=0,"-",E15/D15) -> - | J15: =IF(F15=0,"-",G15/F15) -> 0.99821747 | K15: 1
A16: 7 | B16: AUTOZONE DRIVING SCHOOLINC. | C16: 5 | D16: 1237 | E16: 1141 | F16: 0 | G16: 0 | H16: 10 | I16: =IF(D16=0,"-",E16/D16) -> 0.92239289 | J16: =IF(F16=0,"-",G16/F16) -> - | L16: The Facebook page was last updated on July 2, 2026. The institution also has a webpage; however, upon accessing it, it was flagged as not secure. It should be noted that there are two versions of the site, “Autozone” and “Autozone TESDA,” but the latter appears to be outdated. For the Pedro branch, there are currently no available scholarship slots. However, SMAW NC I training remains open in this branch. To apply or inquire, applicants are advised to search for “Autozone TESDA” and coordinate through their official channels. For Driving NC II, the institution is currently accepting applicants for a waitlist. They require applicants to indicate whether they already have a student permit or driver’s license. According to the staff, there is already a long lineup with multiple batches scheduled. Under the scholarship program, training is free. For private enrollment, the cost is Php 5,500 per trainee, with an additional Php 1,034 for assessment. To apply for the scholarship, applicants must visit the site in person and bring a valid license and a 1×1 photo. Additional requirements will be requested once the training schedule is confirmed. For private training, a minimum of ten students is required to open a class. | M16: Yes | N16: No | O16: Yes | P16: Yes | Q16: Yes | R16: https://autozone.driving.com.ph/ | S16: No | T16: 2 | U16: None (Waiting for full batch) | V16: Php 5,500 + Php 1,034 assessment (Regular Training) | W16: Limited (No slots for Pedro branch; free if available) | X16: Onsite (Walk-in; waitlist for Driving NC II) | Z16: 028 400 2430 | AA16: autozone.trainingcenter@gmail.com | AC16: {=SUMPRODUCT(--(M16:Q16="YES"))} -> 4 | AD16: =COUNTIF($AC$7:AC16, ">=3") -> 5
A17: 6 | B17: Computer Site Ins. Inc. | C17: 3 | D17: 1321 | E17: 1112 | F17: 0 | G17: 0 | H17: 13 | I17: =IF(D17=0,"-",E17/D17) -> 0.84178653 | J17: =IF(F17=0,"-",G17/F17) -> - | L17: No TESDA scholarship as of right now. You cannot pay for a TESDA course either. It really has to be through TESDA scholarship. If you want to be apply to pay, you would have to go through the two-year courses. To apply, you have to drop-by and fill up to the location. Facebook was last updated July 3. | M17: Yes | N17: No | O17: Yes | P17: Yes | Q17: Yes | R17: https://baldestamon2004.neocities.org/ | S17: No | T17: 2 | U17: None (Pending TESDA funding) | V17: N/A (TESDA only; paid via 2-year courses) | W17: No (No TESDA scholarship currently) | X17: Onsite (Walk-in application) | Z17: 0942 422 0165 | AA17: comsite19882000@yahoo.com | AC17: {=SUMPRODUCT(--(M17:Q17="YES"))} -> 4 | AD17: =COUNTIF($AC$7:AC17, ">=3") -> 6
A18: 209 | B18: C HEO TRAINING AND ASSESSMENT CENTER, INC. | C18: 11 | D18: 82 | E18: 53 | F18: 1306 | G18: 1064 | H18: 2 | I18: =IF(D18=0,"-",E18/D18) -> 0.64634146 | J18: =IF(F18=0,"-",G18/F18) -> 0.81470138 | K18: 1
A19: 15 | B19: LUCENA TECHNOLOGICAL INSTITUTE INCORPORATED | C19: 3 | D19: 848 | E19: 1102 | F19: 805 | G19: 788 | H19: 24 | I19: =IF(D19=0,"-",E19/D19) -> 1.2995283 | J19: =IF(F19=0,"-",G19/F19) -> 0.97888199 | L19: They do not have any budget yet, so no TESDA offered courses. Once they have a budget, they call those who registered. To register, you just have to message the page. For the phone number, it's not readily available in the Facebook page. You would have to go to the TESDA page. | M19: Yes | N19: Yes | O19: Yes | P19: Yes | Q19: No | S19: 2nd Priority | T19: 2 | U19: None (Pending TESDA funding) | V19: None (Pending TESDA funding) | W19: Yes | X19: Online (Facebook Message) | Z19: (042) 784 2334 | AA19: LucenaTech@gmail.com | AC19: {=SUMPRODUCT(--(M19:Q19="YES"))} -> 4 | AD19: =COUNTIF($AC$7:AC19, ">=3") -> 7
A20: 348 | B20: ACETAC INSTITUTE OF TECHNOLOGY INC. | C20: 10 | D20: 23 | E20: 30 | F20: 2412 | G20: 2689 | H20: 1 | I20: =IF(D20=0,"-",E20/D20) -> 1.3043478 | J20: =IF(F20=0,"-",G20/F20) -> 1.1148425 | K20: 1
A21: 416 | B21: PROVINCIAL TECHNICAL EDUCATION AND SKILLS DEVELOPMENT CENTER (PTESDC) - TAYTAY | C21: 10 | D21: 0 | E21: 0 | F21: 1055 | G21: 907 | H21: 0 | I21: =IF(D21=0,"-",E21/D21) -> - | J21: =IF(F21=0,"-",G21/F21) -> 0.85971564 | K21: 1
A22: 456 | B22: RENAISSANCE SCHOOL OF SCIENCE AND TECHNOLOGY INC. | C22: 10 | D22: 0 | E22: 0 | F22: 2588 | G22: 2486 | H22: 0 | I22: =IF(D22=0,"-",E22/D22) -> - | J22: =IF(F22=0,"-",G22/F22) -> 0.96058733 | K22: 1
A23: 458 | B23: RIZAL PROVINCIAL TECHNICAL EDUCATION AND SKILLS DEVELOPMENT CENTER - CAINTA | C23: 10 | D23: 0 | E23: 0 | F23: 810 | G23: 686 | H23: 0 | I23: =IF(D23=0,"-",E23/D23) -> - | J23: =IF(F23=0,"-",G23/F23) -> 0.84691358 | K23: 1
A24: 525 | B24: SISTERS OF MARY TECHNICAL EDUCATION INSTITUTE CAVITE, INC. - BOYSTOWN | C24: 10 | D24: 0 | E24: 0 | F24: 454 | G24: 442 | H24: 0 | I24: =IF(D24=0,"-",E24/D24) -> - | J24: =IF(F24=0,"-",G24/F24) -> 0.97356828 | K24: 1
A25: 535 | B25: BANAHAW TECHNOLOGICAL COLLEGE, INC. | C25: 10 | D25: 0 | E25: 0 | F25: 1985 | G25: 1907 | H25: 0 | I25: =IF(D25=0,"-",E25/D25) -> - | J25: =IF(F25=0,"-",G25/F25) -> 0.96070529 | K25: 1
A26: 9 | B26: DIVINE MERCY INTERNATIONAL INSTITUTE INC. | C26: 5 | D26: 1167 | E26: 1099 | F26: 0 | G26: 0 | H26: 18 | I26: =IF(D26=0,"-",E26/D26) -> 0.94173093 | J26: =IF(F26=0,"-",G26/F26) -> - | L26: The number provided in the TESDA Webpage was apparently incorrect. I will still include it for completeness, but they don't even provide an email. The Facebook page was updated last July 1. | M26: Yes | N26: Yes | O26: Yes | P26: No | Q26: No | S26: 2nd Priority | T26: 2 | Z26: (046) 512 3522 | AC26: {=SUMPRODUCT(--(M26:Q26="YES"))} -> 3 | AD26: =COUNTIF($AC$7:AC26, ">=3") -> 8
A27: 12 | B27: SYNERGY ASSESSMENT & TRAINING CENTER | C27: 4 | D27: 971 | E27: 1034 | F27: 0 | G27: 0 | H27: 15 | I27: =IF(D27=0,"-",E27/D27) -> 1.0648816 | J27: =IF(F27=0,"-",G27/F27) -> - | L27: The number provided in the TESDA Webpage was apparently incorrect. They currently have welding courses, lahat may scholarship. They only have scholarship. Umaabot pa ng 13K. To apply, get a registration form in the onsite office of the national ID, birth certificate, and the such. Once they applied and once the instituion gets the funding from TESDA for the scholarships, they will just call the scholars. | M27: Yes | N27: Yes | O27: Yes | P27: Yes | Q27: No | S27: 3rd Priority | T27: 2 | U27: None (Pending TESDA funding) | V27: Free (Scholarship), Php 13,000 (Regular) | W27: Yes | X27: Onsite (Waitlist until class is full) | Z27: 043 756 2564 | AA27: synergyassessment_trainingcenter@yahoo.com | AC27: {=SUMPRODUCT(--(M27:Q27="YES"))} -> 4 | AD27: =COUNTIF($AC$7:AC27, ">=3") -> 9
A28: 25 | B28: Regional Training Center - CALABARZON | C28: 18 | D28: 715 | E28: 871 | F28: 0 | G28: 0 | H28: 22 | I28: =IF(D28=0,"-",E28/D28) -> 1.2181818 | J28: =IF(F28=0,"-",G28/F28) -> - | L28: They are very active in their Facebook page, where they last uploaded July 3. They also have a very pretty website, which was the first result. 0917 124 6624 | M28: Yes | N28: Yes | O28: Yes | P28: Yes | Q28: Yes | R28: https://tesdartccalabarzon.com/ | S28: Yes | T28: 2 | U28: N/A | V28: N/A | W28: N/A | X28: N/A | Z28: (043) 781 9379 | AA28: rtcbatangas@tesda.gov.ph | AC28: {=SUMPRODUCT(--(M28:Q28="YES"))} -> 5 | AD28: =COUNTIF($AC$7:AC28, ">=3") -> 10
A29: 17 | B29: SP CASTRO CONSTRUCTION SERVICES | C29: 4 | D29: 825 | E29: 773 | F29: 0 | G29: 0 | H29: 9 | I29: =IF(D29=0,"-",E29/D29) -> 0.9369697 | J29: =IF(F29=0,"-",G29/F29) -> - | L29: This specializes as a construction company, so when you search it up, it shows their offices in Pasig, not the school in Quezon. The Facebook for the school was updated last May 9, 2024. The phone number does not work. | M29: No | N29: No | O29: No | P29: No | Q29: Yes | R29: https://www.spcastro.com/ | S29: 2nd Priority | T29: 2 | AC29: {=SUMPRODUCT(--(M29:Q29="YES"))} -> 1 | AD29: =COUNTIF($AC$7:AC29, ">=3") -> 10
A30: 13 | B30: ST. MARK SKILLS TRAINING INSTITUTE INC. | C30: 7 | D30: 940 | E30: 768 | F30: 986 | G30: 982 | H30: 13 | I30: =IF(D30=0,"-",E30/D30) -> 0.81702128 | J30: =IF(F30=0,"-",G30/F30) -> 0.9959432 | L30: Facebook was updated last July 3. | M30: Yes | N30: Yes | O30: Yes | P30: No | Q30: No | T30: 2 | Z30: 0948 051 1340 | AA30: st.mark.institute2022@gmail.com | AC30: {=SUMPRODUCT(--(M30:Q30="YES"))} -> 3 | AD30: =COUNTIF($AC$7:AC30, ">=3") -> 11
A31: 19 | B31: EXCELSIOR CENTER FOR EXCELLENCE INC. | C31: 3 | D31: 765 | E31: 766 | F31: 0 | G31: 0 | H31: 13 | I31: =IF(D31=0,"-",E31/D31) -> 1.0013072 | J31: =IF(F31=0,"-",G31/F31) -> - | L31: Facebook page is just a group chat. It is filled with questions if a TESDA course is now available. The latest question was from June 27. Even though the Facebook is technically updated, I don't trust it. The phone number provided in the TESDA Webpage does not work. | M31: No | N31: No | O31: Yes | P31: No | Q31: No | T31: 2 | AC31: {=SUMPRODUCT(--(M31:Q31="YES"))} -> 1 | AD31: =COUNTIF($AC$7:AC31, ">=3") -> 11
A32: 395 | B32: LYCEUM OF THE PHILIPPINES UNIVERSITY, INC. - CAVITE | C32: 9 | D32: 0 | E32: 0 | F32: 391 | G32: 391 | H32: 0 | I32: =IF(D32=0,"-",E32/D32) -> - | J32: =IF(F32=0,"-",G32/F32) -> 1
A33: 428 | B33: TESDA PROVINCIAL TRAINING CENTER - ROSARIO | C33: 9 | D33: 0 | E33: 0 | F33: 1415 | G33: 1335 | H33: 0 | I33: =IF(D33=0,"-",E33/D33) -> - | J33: =IF(F33=0,"-",G33/F33) -> 0.9434629
A34: 513 | B34: COLEGIO DE SANTO CRISTO DE BURGOS CORPORATION | C34: 9 | D34: 0 | E34: 0 | F34: 1702 | G34: 1647 | H34: 0 | I34: =IF(D34=0,"-",E34/D34) -> - | J34: =IF(F34=0,"-",G34/F34) -> 0.96768508
A35: 31 | B35: KAMELO MANPOWER SKILLS DEVELOPMENT CENTER INC. | C35: 4 | D35: 595 | E35: 737 | F35: 0 | G35: 0 | H35: 11 | I35: =IF(D35=0,"-",E35/D35) -> 1.2386555 | J35: =IF(F35=0,"-",G35/F35) -> - | L35: The Facebook page does not readily provide the institution’s contact details, such as the phone number and email. These had to be located within the posts. The page was last updated on July 6. https://www.facebook.com/photo?fbid=2250178522472942&set=a.210535573103924 At present, there are no available scholarships. For paid training, applicants must wait for the availability of a trainer. The fee for SMAW NC I is Php 35,000. To apply, applicants are required to proceed onsite and coordinate directly with the institution for further instructions. | M35: Yes | N35: Yes | O35: Yes | P35: Yes | Q35: No | S35: 3rd Priority | T35: 2 | U35: None (Waiting for trainer availability) | V35: Php 35,000 (SMAW NC I) | W35: No (No scholarship currently) | X35: Onsite (Walk-in application) | Z35: 0946 502 9079 | AA35: kamelo.batangas@gmail.com | AC35: {=SUMPRODUCT(--(M35:Q35="YES"))} -> 4 | AD35: =COUNTIF($AC$7:AC35, ">=3") -> 12
A36: 26 | B36: RUBIKS MANPOWER TRAINING CENTER INC. | C36: 5 | D36: 711 | E36: 716 | F36: 1168 | G36: 1141 | H36: 12 | I36: =IF(D36=0,"-",E36/D36) -> 1.0070323 | J36: =IF(F36=0,"-",G36/F36) -> 0.97688356 | L36: Facebook page was updated last July 3, 2014. | M36: No | N36: No | O36: Yes | P36: No | Q36: No | T36: 2 | AC36: {=SUMPRODUCT(--(M36:Q36="YES"))} -> 1 | AD36: =COUNTIF($AC$7:AC36, ">=3") -> 12
A37: 32 | B37: Skillful Training and Assessment Center Inc. | C37: 3 | D37: 594 | E37: 715 | F37: 0 | G37: 0 | H37: 7 | I37: =IF(D37=0,"-",E37/D37) -> 1.2037037 | J37: =IF(F37=0,"-",G37/F37) -> - | T37: 2 | AC37: {=SUMPRODUCT(--(M37:Q37="YES"))} -> 0 | AD37: =COUNTIF($AC$7:AC37, ">=3") -> 12
A38: 400 | B38: TOYOTA MOTOR PHILIPPINES SCHOOL OF TECHNOLOGY, INC. | C38: 8 | D38: 0 | E38: 0 | F38: 2876 | G38: 2871 | H38: 0 | I38: =IF(D38=0,"-",E38/D38) -> - | J38: =IF(F38=0,"-",G38/F38) -> 0.99826147
A39: 422 | B39: OLIVAREZ COLLEGE - TAGAYTAY, INC. | C39: 8 | D39: 0 | E39: 0 | F39: 1253 | G39: 1130 | H39: 0 | I39: =IF(D39=0,"-",E39/D39) -> - | J39: =IF(F39=0,"-",G39/F39) -> 0.90183559
A40: 436 | B40: TESDA PROVINCIAL TRAINING CENTER - PALIPARAN | C40: 8 | D40: 0 | E40: 0 | F40: 802 | G40: 794 | H40: 0 | I40: =IF(D40=0,"-",E40/D40) -> - | J40: =IF(F40=0,"-",G40/F40) -> 0.99002494
A41: 22 | B41: GOALS TRAINING AND ASSESSMENT INSTITUTE INC. | C41: 5 | D41: 741 | E41: 681 | F41: 0 | G41: 0 | H41: 11 | I41: =IF(D41=0,"-",E41/D41) -> 0.91902834 | J41: =IF(F41=0,"-",G41/F41) -> - | L41: There are two Facebook pages for the same institution. I used the phone number of the Facebook page that had the latest post, which was on November 2025. | M41: No | N41: No | O41: Yes | P41: No | Q41: No | T41: 2 | Z41: 0917 701 8481 | AA41: goalsinstitute2017@gmail.com | AC41: {=SUMPRODUCT(--(M41:Q41="YES"))} -> 1 | AD41: =COUNTIF($AC$7:AC41, ">=3") -> 12
...

Sheet Leads for NCR and 4A
A1: Record Id | B1: Is Converted | C1: Lead Owner.id | D1: Lead Owner | E1: Company | F1: First Name | G1: Last Name | H1: Title | I1: Priority Level | J1: Email | K1: Sureness | L1: Phone | M1: Mobile | N1: Website | O1: Lead Source | P1: Lead Status | Q1: Created By.id | R1: Created By | S1: Modified By.id | T1: Modified By | U1: Created Time | V1: Modified Time | W1: Lead Name | X1: City | Y1: Description | Z1: Salutation | AA1: Secondary Email | AB1: Last Activity Time | AC1: Tag | AD1: Converted Date Time | AE1: Lead Conversion Time | AF1: Unsubscribed Mode | AG1: Unsubscribed Time | AH1: Converted Account.id | AI1: Converted Account | AJ1: Converted Contact.id | AK1: Converted Contact | AL1: Converted Deal.id | AM1: Converted Deal | AN1: Change Log Time | AO1: Locked | AP1: Last Enriched Time | AQ1: Enrich Status | AR1: Partner Type | AS1: Connect with University Entrepreneurship Prgm. | AT1: Get more information about the alliance | AU1: Partner with you as a mentor | AV1: Connect with programs aimed at entrepreneurs /SB | AW1: Other | AX1: Industria o Sector | AY1: ¿Qué esperas obtener de esta masterclass? | AZ1: Retos más importantes para este año | BA1: Que le preguntarías al fundador de Rappi | BB1: ¿En qué punto se encuentra tu emprendimiento? | BC1: Interest Level | BD1: Sector. | BE1: State/Province | BF1: Country. | BG1: Web o redes del emprendimiento | BH1: Prinicipal reto | BI1: Tipo de Aliado | BJ1: Fecha de inicio de operaciones | BK1: Número de Empleados | BL1: Número de clientes que pagan | BM1: Pitch de Startup | BN1: Ventas Anuales | BO1: Tipo de fondeo recibido | BP1: Principales Canales de Ventas | BQ1: Get more information about Emplea+
E2: TESDA Women's Center | F2: Gerrelen | G2: Balbin | H2: Senior TESD Specialist, Training Management Unit Head | I2: 1st Priority | J2: gdbalbin@tesda.gov.ph | K2: Yes (Website) | O2: Cold call | P2: Sourced
E3: PSAA INTERNATIONAL ACADEMY INC. | F3: Riza | G3: Sorima-Matias | H3: Training Director | I3: 1st Priority | J3: psaamanila@hotmail.com | K3: Yes (Website)
E4: MILESTONE TECHNOLOGICAL INSTITUTE, INC. | F4: Fernando | G4: Libao | H4: Center Manager | I4: 1st Priority | J4: milestone.camanava2022@gmail.com / mti.developer.ph@gmail.com | K4: Maybe??? (Came From 2024 EGAC Dataset)
E5: CENTER FOR ASIAN CULINARY STUDIES INC. | F5: Eugenio | G5: Gonzalez | H5: Culinary Arts Director | I5: 1st Priority | J5: cacschef@gmail.com | K5: Yes (Website)
E6: MECHATRONICS TECHNOLOGIES CORP. | F6: Xerxes Gamaliel | G6: Itao | H6: Managing Director | I6: 1st Priority | J6: mechatronicstechnologiescorp@yahoo.com | K6: Yes (Website)
E7: CENTER FOR BARISTA AND TOURISM ACADEMY TRAINING AND ASSESSMENT, INC. | F7: Deejae | G7: Juanta | H7: Founder | I7: 2nd Priority | J7: qc.cenbartvimis@gmail.com / training.cfb@gmail.com | K7: Yes (Website)
E8: ACADEMY ASIA SCHOOL OF TECHNOLOGY AND THE ARTS, INC. | F8: Jamie | G8: Dolera | H8: Managing Director | I8: 1st Priority | J8: academy.asia@gmail.com | K8: Most Likely (Fact-Checked from Pre-2024 Sources)
E9: SEAMAC INTERNATIONAL TRAINING INSTITUTE, INC. | F9: Teresita | G9: Marcos | H9: Center Manager | I9: 2nd Priority | J9: ne.guarina@seamac.ph.education / seamactraining@yahoo.com | K9: Don't Trust (Came From 2024 EGAC Dataset. But contact person works now in Exact Colleges)
E10: ASIA SOURCE ICOLLEGE INC. | F10: Jethro | G10: Orejuela | H10: School Director | I10: 2nd Priority | J10: asiasource.academics@gmail.com / asic2014@asiasourceicollege.edu.ph | K10: Yes (Facebook)
E11: UNO CAREGIVER AND DOMESTIC MNGT TRAINING, INC. | F11: Mary Grace Rosalia | G11: Gulan | H11: Center Manager | I11: 1st Priority | J11: uno_training@yahoo.com / uno.training88@gmail.com | K11: Don't Trust (Came From 2024 EGAC Dataset. But contact person works now in NASTA)
E12: TECHVOC SKILLS INC. | F12: Melody | G12: Cruz | H12: School Head | I12: 1st Priority | J12: techvoc_skills.incorporated@yahoo.com | K12: Yes (Tiktok)
E13: REGIONAL TRAINING CENTER - NCR | F13: Jerry | G13: Taroy | H13: Supervising TESD Specialist, Head – Training, Research, Assessment and Extension Unit (TREAU) | I13: 1st Priority | J13: rtcncr@tesda.gov.ph | K13: Yes (Website)
E14: SMI INSTITUTE INC. | F14: Cristina | G14: Aplasca | H14: Center Manager | I14: 1st Priority | J14: smiacademicenter@gmail.com | K14: Yes (Facebook)
... E41: THE FORKS TRAINING AND ASSESSMENT SOLUTIONS INC. | F41: Carlenne Joy | G41: Benamer | H41: Center Administrator | I41: 2nd Priority | J41: theforksbatangas@yahoo.com | K41: Yes (Website)

Sheet NC Combinations
A1: Top NC Combinations for 1st Priority Institutions
A2: 174 common combinations. Ranked by absolute frequency. NOT computed live. This was just copy and pasted from the Github under 09_LEADS
A3: https://github.com/BSDSBA-JF/wadwani_intern
A5: itemset | B5: Absolute Frequency | C5: Relative Frequency
A6: ('Housekeeping NC II',) | B6: 13 | C6: 0.56521739
A7: ('Food and Beverage Services NC II',) | B7: 12 | C7: 0.52173913
A8: ('Food and Beverage Services NC II', 'Housekeeping NC II') | B8: 10 | C8: 0.43478261
A9: ('Trainers Methodology Level I',) | B9: 9 | C9: 0.39130435
A10: ('Bartending NC II', 'Food and Beverage Services NC II') | B10: 8 | C10: 0.34782609
A11: ('Cookery NC II', 'Food and Beverage Services NC II') | B11: 7 | C11: 0.30434783
A12: ('Hilot (Wellness Massage) NC II',) | B12: 7 | C12: 0.30434783
A13: ('Bartending NC II', 'Food and Beverage Services NC II', 'Housekeeping NC II') | B13: 7 | C13: 0.30434783
A14: ('Bartending NC II', 'Housekeeping NC II') | B14: 7 | C14: 0.30434783
A15: ('Cookery NC II', 'Housekeeping NC II') | B15: 6 | C15: 0.26086957
A16: ('Housekeeping NC II', 'Trainers Methodology Level I') | B16: 6 | C16: 0.26086957
A17: ('Front Office Services NC II', 'Housekeeping NC II') | B17: 5 | C17: 0.2173913
... A25: ('Mechatronics Servicing NC II',) | B25: 5 | C25: 0.2173913
A26: ('Bartending NC II', 'Cookery NC II') | B26: 5 | C26: 0.2173913 | E26: `
A27: ('Cookery NC II', 'Food and Beverage Services NC II', 'Housekeeping NC II') | B27: 5 | C27: 0.2173913
A28: ('Food and Beverage Services NC II', 'Housekeeping NC II', 'Trainers Methodology Level I') | B28: 5 | C28: 0.2173913
A29: ('Food and Beverage Services NC II', 'Trainers Methodology Level I') | B29: 5 | C29: 0.2173913
A30: ('Bartending NC II', 'Cookery NC II', 'Food and Beverage Services NC II') | B30: 5 | C30: 0.2173913
A31: ('Barista NC II', 'Bartending NC II') | B31: 4 | C31: 0.17391304
A32: ('Shielded Metal Arc Welding (SMAW) NC I', 'Shielded Metal Arc Welding (SMAW) NC II') | B32: 4 | C32: 0.17391304
A33: ('Bookkeeping NC III', 'Food and Beverage Services NC II') | B33: 4 | C33: 0.17391304
A34: ('Bookkeeping NC III', 'Trainers Methodology Level I') | B34: 4 | C34: 0.17391304
A35: ('Barista NC II', 'Food and Beverage Services NC II', 'Housekeeping NC II') | B35: 4 | C35: 0.17391304
A36: ('Barista NC II', 'Housekeeping NC II') | B36: 4 | C36: 0.17391304
A37: ('Driving NC II', 'Electronic Products Assembly and Servicing NC II', 'Trainers Methodology Level I') | B37: 4 | C37: 0.17391304
A38: ('Shielded Metal Arc Welding (SMAW) NC I', 'Trainers Methodology Level I') | B38: 4 | C38: 0.17391304
... A179: ('Bookkeeping NC III', 'Food and Beverage Services NC II', 'Front Office Services NC II') | B179: 3 | C179: 0.13043478

Sheet Sectors
A1: Top Sectors for 1st Priority Institutions
A2: 24 First Priority Institutions.
A3: https://github.com/BSDSBA-JF/wadwani_intern
A5: Institution | B5: Qualifications | C5: Sectors | D5: Specialized Sector | E5: Graduates
A6: TESDA Women's Center | B6: {'Housekeeping NC II', 'Bookkeeping NC III', 'Trainers Methodology Level I', 'Shielded Metal Arc Welding (SMAW) NC I', 'Driving NC II', 'Bartending NC II', 'Gas Metal Arc Welding (GMAW) NC II', 'Shielded Metal Arc Welding (SMAW) NC II', 'Electronic Products Assembly and Servicing NC II', 'Barista NC II', 'Bread and Pastry Production NC II', 'Cookery NC II', 'Plumbing NC I', 'Plumbing NC II', 'Dressmaking NC II', 'Electrical Installation and Maintenance NC II', 'Food and Beverage Services NC II', 'Automotive Servicing NC I'} | C6: ['TOURISM SECTOR', 'HEALTH, SOCIAL, AND OTHER COMMUNITY DEVELOPMENT SERVICES SECTOR', 'TVET SECTOR', 'METALS AND ENGINEERING SECTOR', 'AUTOMOTIVE AND LAND TRANSPORT SECTOR', 'TOURISM SECTOR', 'METALS AND ENGINEERING SECTOR', 'METALS AND ENGINEERING SECTOR', 'ELECTRICAL & ELECTRONICS SECTOR', 'TOURISM SECTOR', 'TOURISM SECTOR', 'TOURISM SECTOR', 'CONSTRUCTION SECTOR', 'CONSTRUCTION SECTOR', 'GARMENTS SECTOR', 'ELECTRICAL & ELECTRONICS SECTOR', 'TOURISM SECTOR', 'AUTOMOTIVE AND LAND TRANSPORT SECTOR'] | D6: TOURISM SECTOR | E6: {=IFERROR( _xlfn.XLOOKUP(TRUE, EXACT(Table4[[#This Row],[Institution]], 'Top Centers - NCR'!B:B), 'Top Centers - NCR'!E:E ), _xlfn.XLOOKUP(TRUE, EXACT(Table4[[#This Row],[Institution]], 'Top Centers - 4A'!B:B), 'Top Centers - 4A'!E:E ) )} -> 2491
A7: TECHVOC SKILLS INC. | B7: {'Contact Center Services NC II', 'Plumbing NC II', 'Hilot (Wellness Massage) NC II', 'Tile Setting NC II'} | C7: ['INFORMATION AND COMMUNICATION TECHNOLOGY (ICT) SECTOR', 'CONSTRUCTION SECTOR', 'HEALTH, SOCIAL, AND OTHER COMMUNITY DEVELOPMENT SERVICES SECTOR', 'CONSTRUCTION SECTOR'] | D7: CONSTRUCTION SECTOR | E7: {=IFERROR( _xlfn.XLOOKUP(TRUE, EXACT(Table4[[#This Row],[Institution]], 'Top Centers - NCR'!B:B), 'Top Centers - NCR'!E:E ), _xlfn.XLOOKUP(TRUE, EXACT(Table4[[#This Row],[Institution]], 'Top Centers - 4A'!B:B), 'Top Centers - 4A'!E:E ) )} -> 1917
A8: UNO CAREGIVER AND DOMESTIC MNGT TRAINING, INC. | B8: {'Housekeeping NC II', 'Trainers Methodology Level I', 'Domestic Work NC II', 'Events Management Services NC III', 'Bartending NC II', 'Barista NC II', 'Bread and Pastry Production NC II', 'Health Care Services NC II', 'Housekeeping NC III', 'Caregiving NC II', 'Caregiving (Elderly) NC II', 'Food and Beverage Services NC II', 'Food and Beverage Services NC III'} | C8: ['TOURISM SECTOR', 'TVET SECTOR', 'HEALTH, SOCIAL, AND OTHER COMMUNITY DEVELOPMENT SERVICES SECTOR', 'TOURISM SECTOR', 'TOURISM SECTOR', 'TOURISM SECTOR', 'TOURISM SECTOR', 'HEALTH, SOCIAL, AND OTHER COMMUNITY DEVELOPMENT SERVICES SECTOR', 'TOURISM SECTOR', 'HEALTH, SOCIAL, AND OTHER COMMUNITY DEVELOPMENT SERVICES SECTOR', 'HEALTH, SOCIAL, AND OTHER COMMUNITY DEVELOPMENT SERVICES SECTOR', 'TOURISM SECTOR', 'TOURISM SECTOR'] | D8: TOURISM SECTOR | E8: {=IFERROR( _xlfn.XLOOKUP(TRUE, EXACT(Table4[[#This Row],[Institution]], 'Top Centers - NCR'!B:B), 'Top Centers - NCR'!E:E ), _xlfn.XLOOKUP(TRUE, EXACT(Table4[[#This Row],[Institution]], 'Top Centers - 4A'!B:B), 'Top Centers - 4A'!E:E ) )} -> 1703
A9: REGIONAL TRAINING CENTER - NCR | B9: {'Mechatronics Servicing NC II', 'Visual Graphic Design NC III', 'Trainers Methodology Level I', 'PV Systems Installation NC II', 'Shielded Metal Arc Welding (SMAW) NC I', 'Shielded Metal Arc Welding (SMAW) NC II', 'RAC Servicing (DomRAC) NC II', "Ship's Catering Services NC I", 'Commercial Air-conditioning Installation and Servicing NC III', 'Trainers Methodology Level II', 'Shielded Metal Arc Welding (SMAW) NC III', 'Mechatronics Servicing NC III'} | C9: ['ELECTRICAL & ELECTRONICS SECTOR', 'INFORMATION AND COMMUNICATION TECHNOLOGY (ICT) SECTOR', 'TVET SECTOR', 'CONSTRUCTION SECTOR', 'METALS AND ENGINEERING SECTOR', 'METALS AND ENGINEERING SECTOR', 'HEATING, VENTILATION, AIR CONDITIONING AND REFRIGERATION', 'MARITIME SECTOR', 'HEATING, VENTILATION, AIR CONDITIONING AND REFRIGERATION', 'TVET SECTOR', 'METALS AND ENGINEERING SECTOR', 'ELECTRICAL & ELECTRONICS SECTOR'] | D9: METALS AND ENGINEERING SECTOR | E9: {=IFERROR( _xlfn.XLOOKUP(TRUE, EXACT(Table4[[#This Row],[Institution]], 'Top Centers - NCR'!B:B), 'Top Centers - NCR'!E:E ), _xlfn.XLOOKUP(TRUE, EXACT(Table4[[#This Row],[Institution]], 'Top Centers - 4A'!B:B), 'Top Centers - 4A'!E:E ) )} -> 1438
A10: Colegio de Santo Cristo De Burgos Corporation | B10: {'Housekeeping NC II', 'Trainers Methodology Level I', 'Driving NC II', 'Bread and Pastry Production NC II', 'Food and Beverage Services NC II'} | C10: ['TOURISM SECTOR', 'TVET SECTOR', 'AUTOMOTIVE AND LAND TRANSPORT SECTOR', 'TOURISM SECTOR', 'TOURISM SECTOR'] | D10: TOURISM SECTOR | E10: {=IFERROR( _xlfn.XLOOKUP(TRUE, EXACT(Table4[[#This Row],[Institution]], 'Top Centers - NCR'!B:B), 'Top Centers - NCR'!E:E ), _xlfn.XLOOKUP(TRUE, EXACT(Table4[[#This Row],[Institution]], 'Top Centers - 4A'!B:B), 'Top Centers - 4A'!E:E ) )} -> 1187
A11: PSAA INTERNATIONAL ACADEMY INC. | B11: {'Housekeeping NC II', 'Trainers Methodology Level I', 'Bookkeeping NC III', 'Domestic Work NC II', 'Events Management Services NC III', 'Bartending NC II', 'Cookery NC II', 'Bread and Pastry Production NC II', 'Barista NC II', 'Health Care Services NC II', 'Front Office Services NC II', 'Caregiving NC II', 'Tourism Promotion Services NC II', 'Caregiving (Elderly) NC II', 'Travel Services NC II', 'Food and Beverage Services NC II'} | C11: ['TOURISM SECTOR', 'TVET SECTOR', 'HEALTH, SOCIAL, AND OTHER COMMUNITY DEVELOPMENT SERVICES SECTOR', 'HEALTH, SOCIAL, AND OTHER COMMUNITY DEVELOPMENT SERVICES SECTOR', 'TOURISM SECTOR', 'TOURISM SECTOR', 'TOURISM SECTOR', 'TOURISM SECTOR', 'TOURISM SECTOR', 'HEALTH, SOCIAL, AND OTHER COMMUNITY DEVELOPMENT SERVICES SECTOR', 'TOURISM SECTOR', 'HEALTH, SOCIAL, AND OTHER COMMUNITY DEVELOPMENT SERVICES SECTOR', 'TOURISM SECTOR', 'HEALTH, SOCIAL, AND OTHER COMMUNITY DEVELOPMENT SERVICES SECTOR', 'TOURISM SECTOR', 'TOURISM SECTOR'] | D11: TOURISM SECTOR | E11: {=IFERROR( _xlfn.XLOOKUP(TRUE, EXACT(Table4[[#This Row],[Institution]], 'Top Centers - NCR'!B:B), 'Top Centers - NCR'!E:E ), _xlfn.XLOOKUP(TRUE, EXACT(Table4[[#This Row],[Institution]], 'Top Centers - 4A'!B:B), 'Top Centers - 4A'!E:E ) )} -> 1169
A12: MILESTONE TECHNOLOGICAL INSTITUTE, INC. | B12: {'Mechatronics Servicing NC II', 'Events Management Services NC III', 'Programming (Java) NC III', 'Bread and Pastry Production NC II', 'Hilot (Wellness Massage) NC II'} | C12: ['ELECTRICAL & ELECTRONICS SECTOR', 'TOURISM SECTOR', 'INFORMATION AND COMMUNICATION TECHNOLOGY (ICT) SECTOR', 'TOURISM SECTOR', 'HEALTH, SOCIAL, AND OTHER COMMUNITY DEVELOPMENT SERVICES SECTOR'] | D12: TOURISM SECTOR | E12: {=IFERROR( _xlfn.XLOOKUP(TRUE, EXACT(Table4[[#This Row],[Institution]], 'Top Centers - NCR'!B:B), 'Top Centers - NCR'!E:E ), _xlfn.XLOOKUP(TRUE, EXACT(Table4[[#This Row],[Institution]], 'Top Centers - 4A'!B:B), 'Top Centers - 4A'!E:E ) )} -> 970
A13: MECHATRONICS TECHNOLOGIES CORP. | B13: {'Mechatronics Servicing NC II', 'Electrical Installation and Maintenance NC IV', 'PV Systems Installation NC II', 'Instrumentation and Control Servicing NC II', 'RAC Servicing (DomRAC) NC II', 'Electrical Installation and Maintenance NC III', 'Mechatronics Servicing NC III', 'Mechatronics Servicing NC IV', 'Electrical Installation and Maintenance NC II'} | C13: ['ELECTRICAL & ELECTRONICS SECTOR', 'ELECTRICAL & ELECTRONICS SECTOR', 'CONSTRUCTION SECTOR', 'ELECTRICAL & ELECTRONICS SECTOR', 'HEATING, VENTILATION, AIR CONDITIONING AND REFRIGERATION', 'ELECTRICAL & ELECTRONICS SECTOR', 'ELECTRICAL & ELECTRONICS SECTOR', 'ELECTRICAL & ELECTRONICS SECTOR', 'ELECTRICAL & ELECTRONICS SECTOR'] | D13: ELECTRICAL & ELECTRONICS SECTOR | E13: {=IFERROR( _xlfn.XLOOKUP(TRUE, EXACT(Table4[[#This Row],[Institution]], 'Top Centers - NCR'!B:B), 'Top Centers - NCR'!E:E ), _xlfn.XLOOKUP(TRUE, EXACT(Table4[[#This Row],[Institution]], 'Top Centers - 4A'!B:B), 'Top Centers - 4A'!E:E ) )} -> 957
